Workbook
Name ___INDEX_SHEET___ASAP_Utilities: #REF!
Name ___INDEX_SHEET___ASAP_Utilities: #REF!

Sheet 香港市场目标
A1: 分类 | B1: KOL | C1: 备注 | D1: 2月例子数 | E1: 2月日均例子数 | F1: 截至5.20例子数 | G1: 截至5.20日均例子数 | H1: 6月-实际日均 | I1: 6月实际-合计 | J1: 46174 | K1: 46175 | L1: 46176 | M1: 46177 | N1: 46178 | O1: 46179 | P1: 46180 | Q1: 46181 | R1: 46182 | S1: 46183 | T1: 46184 | U1: 46185 | V1: 46186 | W1: 46187 | X1: 46188 | Y1: 46189 | Z1: 46190 | AA1: 46191 | AB1: 46192 | AC1: 46193 | AD1: 46194 | AE1: 46195 | AF1: 46196 | AG1: 46197 | AH1: 46198 | AI1: 46199 | AJ1: 46200 | AK1: 46201 | AL1: 46202 | AM1: 46203 | AN1: MTD例子目标 | AO1: 实际例子达成 | AP1: 例子gap | AQ1: MTD约课例子目标 | AR1: 实际约课达成 | AS1: 约课例子gap | AT1: 约课成本
A2: KOL | B2: 钟嘉欣图片 | F2: 202 | G2: =F2/20 | H2: =I2/30 | I2: =SUM(J2:AM2) | J2: 9 | K2: 9 | L2: 10 | M2: 10 | N2: 10 | O2: 11 | P2: 11 | Q2: 9 | R2: 9 | S2: 10 | T2: 10 | U2: 10 | V2: 11 | W2: 11 | X2: 9 | Y2: 9 | Z2: 10 | AA2: 10 | AB2: 10 | AC2: 11 | AD2: 11 | AE2: 9 | AF2: 9 | AG2: 10 | AH2: 10 | AI2: 10 | AJ2: 11 | AK2: 11 | AL2: 10 | AM2: 10 | AN2: =J2+K2+L2+M2+N2+O2+P2 | AO2: 88 | AP2: 74 | AQ2: =AN2*55% | AR2: =VLOOKUP(B2,[4]Sheet3!$B:$M,12,0) | AS2: 45 | AT2: =VLOOKUP(B2,[4]Sheet3!$B:$O,14,0) | AU2: 1040.1138
B3: 钟嘉欣视频1 | C3: 模型目标225（通过测试新素材提升至目标） | F3: 96 | G3: =F3/20 | H3: =I3/30 | I3: =SUM(J3:AM3) | J3: 4 | K3: 5 | L3: 5 | M3: 5 | N3: 5 | O3: 5 | P3: 5 | Q3: 4 | R3: 5 | S3: 5 | T3: 5 | U3: 5 | V3: 5 | W3: 5 | X3: 4 | Y3: 5 | Z3: 5 | AA3: 5 | AB3: 5 | AC3: 5 | AD3: 5 | AE3: 4 | AF3: 5 | AG3: 5 | AH3: 5 | AI3: 5 | AJ3: 5 | AK3: 5 | AL3: 4 | AM3: 5 | AN3: =J3+K3+L3+M3+N3+O3+P3 | AO3: 43 | AP3: 62 | AQ3: =AN3*55% | AR3: =VLOOKUP(B3,[4]Sheet3!$B:$M,12,0) | AS3: 18 | AT3: =VLOOKUP(B3,[4]Sheet3!$B:$O,14,0) | AU3: 1787.2923
B4: 钟嘉欣视频 | C4: 预估每天4条 | H4: =I4/30 | I4: =SUM(J4:AM4) | J4: 4 | K4: 4 | L4: 4 | M4: 4 | N4: 4 | O4: 4 | P4: 4 | Q4: 4 | R4: 4 | S4: 4 | T4: 4 | U4: 4 | V4: 4 | W4: 4 | X4: 4 | Y4: 4 | Z4: 4 | AA4: 4 | AB4: 4 | AC4: 4 | AD4: 4 | AE4: 4 | AF4: 4 | AG4: 4 | AH4: 4 | AI4: 4 | AJ4: 4 | AK4: 4 | AL4: 4 | AM4: 4 | AN4: =J4+K4+L4+M4+N4+O4+P4 | AO4: 36 | AP4: 55 | AQ4: =AN4*55% | AR4: =VLOOKUP(B4,[4]Sheet3!$B:$M,12,0) | AS4: 20 | AT4: =VLOOKUP(B4,[4]Sheet3!$B:$O,14,0) | AU4: 1074.0415
B5: 其他汇总 | F5: 27 | G5: =F5/20 | H5: =I5/30 | I5: =SUM(J5:AM5) | J5: 1 | K5: 1 | L5: 1 | M5: 1 | N5: 1 | O5: 1 | P5: 1 | Q5: 1 | R5: 1 | S5: 1 | T5: 1 | U5: 1 | V5: 1 | W5: 1 | X5: 1 | Y5: 1 | Z5: 1 | AA5: 1 | AB5: 1 | AC5: 1 | AD5: 1 | AE5: 1 | AF5: 1 | AG5: 1 | AH5: 1 | AI5: 1 | AJ5: 1 | AK5: 1 | AL5: 1 | AM5: 1 | AN5: =J5+K5+L5+M5+N5+O5+P5 | AO5: 9 | AP5: 9 | AQ5: =AN5*55% | AR5: 4 | AS5: 5 | AU5: 1079.9642
B6: KOL-汇总 | F6: =SUM(F2:F5) | G6: =F6/20 | H6: =I6/30 | I6: =SUM(J6:AM6) | J6: =SUM(J2:J5) | K6: =SUM(K2:K5) | L6: =SUM(L2:L5) | M6: =SUM(M2:M5) | N6: =SUM(N2:N5) | O6: =SUM(O2:O5) | P6: =SUM(P2:P5) | Q6: =SUM(Q2:Q5) | ... AO6: =SUM(AO2:AO5) | AP6: 200 | AQ6: =AN6*0.55 | AR6: =SUM(AR2:AR5) | AS6: 88 | AT6: 1236.9605 | AU6: 1202.9208
A7: 独立站HK | B7: 出席礼品测试 | C7: 参考51talk，预估一个月30条 | H7: =I7/30 | I7: =SUM(J7:AM7) | P7: 1 | Q7: 1 | R7: 1 | S7: 1 | T7: 2 | U7: 2 | V7: 1 | W7: 1 | X7: 1 | Y7: 1 | Z7: 1 | AA7: 2 | AB7: 2 | AC7: 1 | AD7: 1 | AE7: 1 | AF7: 1 | AG7: 1 | AH7: 2 | AI7: 2 | AJ7: 1 | AK7: 1 | AL7: 1 | AM7: 1 | AN7: =J7+K7+L7+M7+N7+O7+P7 | AO7: 3 | AP7: 4 | AQ7: =AN7*0.6 | AR7: 2 | AS7: 2 | AU7: 432.97561
B8: edm | C8: 正在走流程，预估月底上线 | I8: =SUM(J8:AM8) | AD8: 1 | AE8: 1 | AF8: 1 | AG8: 1 | AH8: 1 | AI8: 1 | AJ8: 1 | AK8: 1 | AL8: 1 | AM8: 1 | AN8: =J8+K8+L8+M8+N8+O8+P8 | AO8: 0 | AP8: 0 | AQ8: =AN8*0.6 | AS8: 0
A9: 商超&社群 | B9: 代理商场 | C9: 代理商场（预计8+1，合计9） | I9: =SUM(J9:AM9) | N9: 10 | O9: 50 | P9: 50 | U9: 20 | V9: 40 | W9: 40 | X9: 20 | AA9: 20 | AB9: 40 | AC9: 40 | AD9: 20 | AE9: 20 | AH9: 20 | AI9: 20 | AJ9: 40 | AK9: 20 | AN9: =J9+K9+L9+M9+N9+O9+P9 | AO9: 110 | AP9: 103 | AQ9: =AN9*0.78 | AR9: 64 | AS9: 73 | AU9: 304.28219
B10: 澳門展会 | I10: =SUM(J10:AM10) | U10: 20 | V10: 40 | W10: 40 | AN10: =J10+K10+L10+M10+N10+O10+P10 | AO10: 0 | AP10: 0 | AQ10: =AN10*0.78 | AS10: 0
B11: 代理人汇总 | F11: 20 | G11: =F11/20 | H11: =I11/31 | I11: =SUM(J11:AM11) | J11: 1 | K11: 1 | L11: 1 | M11: 1 | N11: 1 | O11: 1 | P11: 1 | Q11: 1 | R11: 1 | S11: 1 | T11: 1 | U11: 1 | V11: 1 | W11: 1 | X11: 1 | Y11: 1 | Z11: 1 | AA11: 1 | AB11: 1 | AC11: 1 | AD11: 1 | AE11: 1 | AF11: 1 | AG11: 1 | AH11: 1 | AI11: 1 | AJ11: 1 | AK11: 1 | AL11: 1 | AM11: 1 | AN11: =J11+K11+L11+M11+N11+O11+P11 | AO11: 9 | AP11: 3 | AQ11: =AN11*0.6 | AR11: 1 | AS11: 1 | AU11: 0
B12: 合计 | I12: =SUM(I9:I11) | J12: =SUM(J9:J11) | K12: =SUM(K9:K11) | L12: =SUM(L9:L11) | M12: =SUM(M9:M11) | N12: =SUM(N9:N11) | O12: =SUM(O9:O11) | P12: =SUM(P9:P11) | ... AM12: =SUM(AM9:AM11) | AN12: =SUM(AN7:AN11) | AO12: =SUM(AO7:AO11) | AP12: 106 | AQ12: =SUM(AQ7:AQ11) | AR12: =SUM(AR7:AR11) | AS12: 74 | AU12: 300.17027
B13: 合计 | I13: =I12+I6+I7+I8 | J13: =J12+J6 | K13: =K12+K6 | L13: =L12+L6 | M13: =M12+M6 | N13: =N12+N6 | O13: =O12+O6 | P13: =P12+P6 | Q13: =Q12+Q6 | ... AO13: =AO12+AO6 | AP13: 310 | AQ13: =AQ12+AQ6 | AR13: =AR12+AR6 | AS13: 164 | AU13: 786.19258
AQ15: =AO13/AN13
B16: KOL历史 | C16: 3月 | D16: 4月 | E16: 5月 | F16: 6月 | G16: 7月 | H16: 8月 | I16: 9月 | J16: 10月 | K16: 11月 | L16: 12月 | M16: 1月 | N16: 2月 | O16: 3月 | P16: 4月 | Q16: 46162
B17: 累计例子 | C17: 727 | D17: 565 | E17: 1080 | F17: 1123 | G17: 665 | H17: 973 | I17: 1530 | J17: 1847 | K17: 1112 | L17: 796 | M17: 787 | N17: 360 | O17: 677 | P17: 468 | Q17: 325 | AV17: =AO6/AN6 | AW17: =AR6/AQ6
B18: 平均成本 | C18: 431 | D18: 571 | E18: 673 | F18: 763 | G18: 969 | H18: 644 | I18: =I19/I17 | J18: =J19/J17 | K18: =K19/K17 | L18: =L19/L17 | M18: =M19/M17 | N18: =N19/N17 | O18: =O19/O17 | P18: =P19/P17 | Q18: =Q19/Q17 | AQ18: =AO9/AN9 | AV18: =AO9/AN9
I19: 807722 | J19: 895008 | K19: 1134508 | L19: 935636 | M19: 615368.77 | N19: 306862 | O19: 465727 | P19: 342428 | Q19: 201491 | AV19: =AO13/AN13
B20: 日均例子 | C20: =C17/31 | D20: =D17/30 | E20: =E17/31 | F20: =F17/30 | G20: =G17/31 | H20: =H17/31 | I20: =I17/30 | J20: =J17/31 | K20: =K17/30 | L20: =L17/31 | M20: =M17/31 | N20: =N17/28 | O20: =O17/31 | P20: =P17/31 | Q20: =Q17/20 | AO20: =#REF!/#REF!
AW21: =AR13/AQ13
B23: 6月目标预计 | C23: 例子数 | D23: 成本 | E23: 消耗 | AT23: 陈琪
A24: KOLHK | B24: KOL | C24: =I6 | D24: 650 | E24: =C24*D24 | M24: . | AT24: Bob林盛斌
A25: 线下HK | B25: 展会 | C25: =I10 | D25: =P37 | E25: =D25*C25 | P25: 420840 | AT25: 钟嘉欣图片
A26: 社群HK | B26: 代理人 | C26: =I11 | D26: 300 | E26: =C26*D26 | P26: 420 | AQ26: =#REF!/#REF!
A27: 线下HK | B27: 商超 | C27: =I9 | D27: 250 | E27: =C27*D27 | P27: 1030 | AT27: 钟嘉欣视频1
B28: 其他汇总 | C28: =I7+I8 | D28: 200 | E28: =C28*D28
B29: 合计 | C29: =C24+C25+C27+C26+C28 | D29: =E29/C29 | E29: =E24+E25+E27+E26+E28 | P29: =P25/P27*P26 | AT29: 蔡雪莹
AT30: 陈琪直播
AO31: 15填 | AT31: 陳展鵬
AT32: 專家鄧明儀
B33: 展会 | C33: 2月BB展 | D33: 5月课外活动展 | E33: 5月儿童展 | F33: 7月书展 | G33: 8月展会 | H33: 9月展会 | I33: 10月创意文化展 | J33: 10月兒童書展 | K33: 12月儿童书展 | L33: 12月澳门展 | M33: 2月BB展 | N33: 5月课外活动展 | O33: 5月儿童书展 | P33: 6月澳门展 | AT33: 陳凱琳
B34: 累计例子 | C34: 235 | D34: 303 | E34: 301 | F34: 587 | G34: 270 | H34: 150 | I34: 200 | J34: 400 | K34: =展会数据测算!U24 | L34: =展会数据测算!W24 | M34: =展会数据测算!Y24 | N34: =展会数据测算!AC24 | O34: =展会数据测算!AE24 | P34: 100 | AT34: 麥雅緻直播
B35: 平均成本 | C35: =C36/C34 | D35: 177 | E35: 228 | F35: 236 | G35: 140 | H35: 145 | I35: 146 | J35: 121 | K35: =展会数据测算!U26 | L35: =展会数据测算!W26 | M35: =展会数据测算!Y26 | AT35: 呂慧儀直播
B36: 总消耗 | C36: 41427 | D36: 53609 | E36: 68721 | F36: 138753 | G36: 52080 | I36: 34009.26 | J36: 57839.73 | K36: =K34*K35 | L36: =L34*L35 | M36: =展会数据测算!Y22 | N36: =展会数据测算!AC22 | O36: =展会数据测算!AE22 | P36: =展会数据测算!AG30 | AT36: 嘉欣购物团
B37: 平均成本（含差旅CPS） | C37: 232 | D37: 236 | E37: 288 | F37: 301 | G37: 234 | H37: 171 | I37: 205 | J37: 176 | K37: =K36/K34 | L37: =L36/L34 | M37: =M36/M34 | N37: =展会数据测算!AC27 | O37: =展会数据测算!AE27 | P37: =展会数据测算!AG31 | AT37: 其他汇总
N38: 2TMK+4CC | O38: 2TMK+2CC | P38: 2CC+2TMK
B40: 线下HK历史达成数据 | C40: 总目标 | D40: 实际总达成 | E40: 书展目标 | F40: 书展达成 | G40: 商超目标 | H40: 商超达成 | I40: 总目标达成率 | J40: 书展达成率 | K40: 商超达成率
B41: 45931 | C41: =E41+G41 | D41: =F41+H41 | E41: 650 | F41: 375 | G41: 210 | H41: 222 | I41: =D41/C41 | J41: =F41/E41 | K41: =H41/G41
B42: 45962 | C42: =E42+G42 | D42: =F42+H42 | G42: 400 | H42: 319 | I42: =D42/C42 | K42: =H42/G42
B43: 45992 | C43: =E43+G43 | D43: =F43+H43 | E43: 600 | F43: 634 | G43: 500 | H43: 422 | I43: =D43/C43 | J43: =F43/E43 | K43: =H43/G43
...

Sheet 嘉欣购物团（暂定）
A1: 麦雅致 | B1: 例子占比 | C1: 总例子数 | D1: 成本 | E1: 加权 | F1: 实际投放时间 | G1: 投放时间1个半月
A2: 汇总 | B2: 1 | C2: 100 | D2: 700 | E2: =SUMPRODUCT(C3:C4,D3:D4)/C2 | F2: 30 | I2: 以项目或周期为单位 | J2: 前端投放参数-预估 | K2: 益智 | L2: 美术
A3: 11月 | B3: =C3/$C$2 | C3: 30 | D3: 700 | F3: 10 | I3: 主投 | J3: 注册例子数 | K3: 100 | N3: 其他参数（海外调整） | O3: 益智 | P3: 美术
A4: 12月 | B4: =C4/$C$2 | C4: 70 | D4: 700 | F4: 20 | I4: 主投 | J4: 分发例子数 | N4: 销售人均承接例子数 | O4: 93.8 | P4: 103
I5: 主投 | J5: 单例子成本（CPA） | K5: 700 | N5: 销售人均固定人工成本 | O5: 10622 | P5: 11145.017
I6: 主投 | J6: 单到课例子成本（CPA） | N6: 销售提成比例 | O6: 0.079 | P6: 0.077
I7: 主投 | J7: 渠道佣金（CPS） | K7: 0.25 | N7: 礼品及其他费用比例 | O7: 0.017 | P7: 0.022
I8: 主投 | J8: 投放费用（CPT) | K8: 4000 | N8: 出席试听课费用 | O8: 86.4 | P8: 82
I9: 辅投 | J9: 注册例子数 | N9: 单例子渠道运营人工成本及其他 | O9: 33.49 | P9: 75
I10: 辅投 | J10: 分发例子数 | N10: 是否过TMK | O10: 是 | P10: 是
I11: 辅投 | J11: 单例子成本（CPA） | N11: TMK人均承担例子量 | O11: 1055 | P11: 1233
I12: 辅投 | J12: 单到课例子成本（CPA） | N12: TMK人均成本 | O12: 11181 | P12: 11486.424
I13: 辅投 | J13: 渠道佣金（CPS） | N13: 备注：绿色填充部分可调整，没有对应的参数可留空
I14: 辅投 | J14: 投放费用（CPT) | O14: =O5/O4 | P14: =P5/P4
O15: =O12/O11
J16: 过程指标-预估
J17: 注册分发率 | K17: 0.5
I18: 主投 | J18: 滚动注册出席率 | K18: 0.38
I19: 主投 | J19: 滚动出席转化率 | K19: 0.35
I20: 主投 | J20: 滚动注册转化率 | K20: 0.18
I21: 主投 | J21: 正价课ASP | K21: 5000
I22: 辅投 | J22: 注册分发率
I23: 辅投 | J23: 滚动注册出席率
I24: 辅投 | J24: 滚动出席转化率
I25: 辅投 | J25: 滚动注册转化率
I26: 辅投 | J26: 正价课ASP
J28: ROI 1相关指标-自动计算
I29: 主投 | J29: 到课学员数量 | K29: =K18*K3 | L29: =L18*L3 | N29: 例子数*注册出席率
I30: 主投 | J30: 正价课学员数量 | K30: =K3*K20 | L30: =L3*L20 | N30: 例子数*注册转化率
I31: 主投 | J31: 正价课GMV | K31: =K30*K21 | L31: =L30*L21 | N31: ASP*学员人数
I32: 主投 | J32: 前端投放总成本 | K32: =K5*K3+K7*K31+K8+K29*K6+K3*O9 | L32: =L5*L3+L7*L31+L8+L29*L6+L3*P9 | N32: 例子数*单例子成本+GMV*CPS佣金比例+投放费用+单到课例子成本*出席人数+例子数*单例子运营人工成本
I33: 辅投 | J33: 到课学员数量 | K33: =K23*K9 | L33: =L23*L9
I34: 辅投 | J34: 正价课学员数量 | K34: =K9*K25 | L34: =L9*L25
I35: 辅投 | J35: 正价课GMV | K35: =K26*K34 | L35: =L26*L34
I36: 辅投 | J36: 前端投放总成本 | K36: =K9*K11+K13*K35+K14+K12*K33+K9*P9 | L36: =L9*L11+L13*L35+L14+L12*L33+L9*O9 | N36: 例子数*单例子成本+GMV*CPS佣金比例+投放费用+单到课例子成本*出席人数+例子数*单例子运营人工成本
I37: 主投+辅投 | J37: 每单获客成本1 | K37: =(K32+K36)/(K30+K34) | L37: =(L32+L36)/(L30+L34) | N37: 前端投放总成本/学员人数
J38: ROI 1 | K38: =(K31+K35)/(K32+K36) | L38: =(L31+L35)/(L32+L36) | N38: GMV/前端投放总成本
J40: ROI 2相关指标-自动计算
I41: 主投 | J41: 试听课费用 | K41: =K29*O8 | L41: =L29*P8 | N41: 单课时试听课费用*出席人数
I42: 主投 | J42: TMK费用 | K42: =IF(O10="是",K3/O11*O12,0) | L42: =IF(P10="是",L3/P11*P12,0) | N42: 例子数/TMK人均承担例子量*TMK人均成本=TMK人数*TMK人均成本
...

Sheet 钟嘉欣新视频
A1: 钟嘉欣新视频 | B1: 例子占比 | C1: 总例子数 | D1: 成本 | E1: 加权 | F1: 实际投放时间 | G1: 投放时间4个半月
A2: 汇总 | B2: 1 | C2: 900 | D2: 650 | E2: {=SUMPRODUCT(C3:C7,D3:D7)/C2} | F2: =SUM(F3:F7) | I2: 以项目或周期为单位 | J2: 前端投放参数-预估 | K2: 益智 | L2: 美术
A3: 3月（13天，预计3.19投放） | B3: 0.15 | C3: =B3*C2 | D3: 550 | F3: 13 | I3: 主投 | J3: 注册例子数 | K3: 900 | N3: 其他参数（海外调整） | O3: 益智 | P3: 美术
A4: 4月 | B4: 0.3 | C4: =B4*C2 | D4: 600 | F4: 30 | I4: 主投 | J4: 分发例子数 | N4: 销售人均承接例子数 | O4: 93.8 | P4: 103
A5: 5月 | B5: 0.25 | C5: =B5*C2 | D5: 650 | F5: 31 | I5: 主投 | J5: 单例子成本（CPA） | K5: 650 | N5: 销售人均固定人工成本 | O5: 10622 | P5: 11145.017
A6: 6月 | B6: 0.15 | C6: =B6*C2 | D6: 700 | F6: 30 | I6: 主投 | J6: 单到课例子成本（CPA） | N6: 销售提成比例 | O6: 0.079 | P6: 0.077
A7: 7月 | B7: 0.15 | C7: =B7*C2 | D7: 700 | F7: 31 | I7: 主投 | J7: 渠道佣金（CPS） | N7: 礼品及其他费用比例 | O7: 0.017 | P7: 0.022
I8: 主投 | J8: 投放费用（CPT) | K8: =160000*0.91 | N8: 出席试听课费用 | O8: 86.4 | P8: 82
I9: 辅投 | J9: 注册例子数 | N9: 单例子渠道运营人工成本及其他 | O9: 33.49 | P9: 75
I10: 辅投 | J10: 分发例子数 | N10: 是否过TMK | O10: 是 | P10: 是
I11: 辅投 | J11: 单例子成本（CPA） | N11: TMK人均承担例子量 | O11: 1055 | P11: 1233
I12: 辅投 | J12: 单到课例子成本（CPA） | N12: TMK人均成本 | O12: 11181 | P12: 11486.424
I13: 辅投 | J13: 渠道佣金（CPS） | N13: 备注：绿色填充部分可调整，没有对应的参数可留空
I14: 辅投 | J14: 投放费用（CPT) | O14: =O5/O4 | P14: =P5/P4
O15: =O12/O11
J16: 过程指标-预估
J17: 注册分发率 | K17: 0.5
I18: 主投 | J18: 滚动注册出席率 | K18: 0.38
I19: 主投 | J19: 滚动出席转化率 | K19: 0.35
I20: 主投 | J20: 滚动注册转化率 | K20: 0.165
I21: 主投 | J21: 正价课ASP | K21: 5000
I22: 辅投 | J22: 注册分发率
I23: 辅投 | J23: 滚动注册出席率
I24: 辅投 | J24: 滚动出席转化率
I25: 辅投 | J25: 滚动注册转化率
I26: 辅投 | J26: 正价课ASP
J28: ROI 1相关指标-自动计算
I29: 主投 | J29: 到课学员数量 | K29: =K18*K3 | L29: =L18*L3 | N29: 例子数*注册出席率
I30: 主投 | J30: 正价课学员数量 | K30: =K3*K20 | L30: =L3*L20 | N30: 例子数*注册转化率
I31: 主投 | J31: 正价课GMV | K31: =K30*K21 | L31: =L30*L21 | N31: ASP*学员人数
I32: 主投 | J32: 前端投放总成本 | K32: =K5*K3+K7*K31+K8+K29*K6+K3*O9 | L32: =L5*L3+L7*L31+L8+L29*L6+L3*P9 | N32: 例子数*单例子成本+GMV*CPS佣金比例+投放费用+单到课例子成本*出席人数+例子数*单例子运营人工成本
I33: 辅投 | J33: 到课学员数量 | K33: =K23*K9 | L33: =L23*L9
I34: 辅投 | J34: 正价课学员数量 | K34: =K9*K25 | L34: =L9*L25
I35: 辅投 | J35: 正价课GMV | K35: =K26*K34 | L35: =L26*L34
I36: 辅投 | J36: 前端投放总成本 | K36: =K9*K11+K13*K35+K14+K12*K33+K9*P9 | L36: =L9*L11+L13*L35+L14+L12*L33+L9*O9 | N36: 例子数*单例子成本+GMV*CPS佣金比例+投放费用+单到课例子成本*出席人数+例子数*单例子运营人工成本
I37: 主投+辅投 | J37: 每单获客成本1 | K37: =(K32+K36)/(K30+K34) | L37: =(L32+L36)/(L30+L34) | N37: 前端投放总成本/学员人数
J38: ROI 1 | K38: =(K31+K35)/(K32+K36) | L38: =(L31+L35)/(L32+L36) | N38: GMV/前端投放总成本
J40: ROI 2相关指标-自动计算
I41: 主投 | J41: 试听课费用 | K41: =K29*O8 | L41: =L29*P8 | N41: 单课时试听课费用*出席人数
I42: 主投 | J42: TMK费用 | K42: =IF(O10="是",K3/O11*O12,0) | L42: =IF(P10="是",L3/P11*P12,0) | N42: 例子数/TMK人均承担例子量*TMK人均成本=TMK人数*TMK人均成本
...

Sheet 周家蔚
A1: 吕慧仪 | B1: 例子占比 | C1: 总例子数 | D1: 成本 | E1: 加权 | F1: 实际投放天数 | G1: 预计上线时间11.15
A2: 汇总 | B2: 1 | C2: 420 | D2: 700 | E2: {=SUMPRODUCT(C3:C6,D3:D6)/C2} | I2: 以项目或周期为单位 | J2: 前端投放参数-预估 | K2: 益智 | L2: 美术
A3: 2月 | B3: 0.1 | C3: =C$2*B3 | D3: 600 | F3: 15 | I3: 主投 | J3: 注册例子数 | K3: 420 | N3: 其他参数（海外调整） | O3: 益智 | P3: 美术
A4: 3月 | B4: 0.4 | C4: =C$2*B4 | D4: 650 | F4: 31 | I4: 主投 | J4: 分发例子数 | N4: 销售人均承接例子数 | O4: 93.8 | P4: 103
A5: 4月 | B5: 0.3 | C5: =C$2*B5 | D5: 735 | F5: 31 | I5: 主投 | J5: 单例子成本（CPA） | K5: 700 | N5: 销售人均固定人工成本 | O5: 10622 | P5: 11145.017
A6: 5月 | B6: 0.2 | C6: =C$2*B6 | D6: 795 | F6: 13 | I6: 主投 | J6: 单到课例子成本（CPA） | N6: 销售提成比例 | O6: 0.079 | P6: 0.077
I7: 主投 | J7: 渠道佣金（CPS） | N7: 礼品及其他费用比例 | O7: 0.017 | P7: 0.022
I8: 主投 | J8: 投放费用（CPT) | K8: 84500 | N8: 出席试听课费用 | O8: 86.4 | P8: 82
I9: 辅投 | J9: 注册例子数 | N9: 单例子渠道运营人工成本及其他 | O9: 33.49 | P9: 75
I10: 辅投 | J10: 分发例子数 | N10: 是否过TMK | O10: 是 | P10: 是
I11: 辅投 | J11: 单例子成本（CPA） | N11: TMK人均承担例子量 | O11: 1055 | P11: 1233
I12: 辅投 | J12: 单到课例子成本（CPA） | N12: TMK人均成本 | O12: 11181 | P12: 11486.424
I13: 辅投 | J13: 渠道佣金（CPS） | N13: 备注：绿色填充部分可调整，没有对应的参数可留空
I14: 辅投 | J14: 投放费用（CPT) | O14: =O5/O4 | P14: =P5/P4
O15: =O12/O11
J16: 过程指标-预估
J17: 注册分发率 | K17: 0.5
I18: 主投 | J18: 滚动注册出席率 | K18: 0.38
I19: 主投 | J19: 滚动出席转化率 | K19: 0.35
I20: 主投 | J20: 滚动注册转化率 | K20: 0.18
I21: 主投 | J21: 正价课ASP | K21: 5000
I22: 辅投 | J22: 注册分发率
I23: 辅投 | J23: 滚动注册出席率
I24: 辅投 | J24: 滚动出席转化率
I25: 辅投 | J25: 滚动注册转化率
I26: 辅投 | J26: 正价课ASP
J28: ROI 1相关指标-自动计算
I29: 主投 | J29: 到课学员数量 | K29: =K18*K3 | L29: =L18*L3 | N29: 例子数*注册出席率
I30: 主投 | J30: 正价课学员数量 | K30: =K3*K20 | L30: =L3*L20 | N30: 例子数*注册转化率
I31: 主投 | J31: 正价课GMV | K31: =K30*K21 | L31: =L30*L21 | N31: ASP*学员人数
I32: 主投 | J32: 前端投放总成本 | K32: =K5*K3+K7*K31+K8+K29*K6+K3*O9 | L32: =L5*L3+L7*L31+L8+L29*L6+L3*P9 | N32: 例子数*单例子成本+GMV*CPS佣金比例+投放费用+单到课例子成本*出席人数+例子数*单例子运营人工成本
I33: 辅投 | J33: 到课学员数量 | K33: =K23*K9 | L33: =L23*L9
I34: 辅投 | J34: 正价课学员数量 | K34: =K9*K25 | L34: =L9*L25
I35: 辅投 | J35: 正价课GMV | K35: =K26*K34 | L35: =L26*L34
I36: 辅投 | J36: 前端投放总成本 | K36: =K9*K11+K13*K35+K14+K12*K33+K9*P9 | L36: =L9*L11+L13*L35+L14+L12*L33+L9*O9 | N36: 例子数*单例子成本+GMV*CPS佣金比例+投放费用+单到课例子成本*出席人数+例子数*单例子运营人工成本
I37: 主投+辅投 | J37: 每单获客成本1 | K37: =(K32+K36)/(K30+K34) | L37: =(L32+L36)/(L30+L34) | N37: 前端投放总成本/学员人数
J38: ROI 1 | K38: =(K31+K35)/(K32+K36) | L38: =(L31+L35)/(L32+L36) | N38: GMV/前端投放总成本
J40: ROI 2相关指标-自动计算
I41: 主投 | J41: 试听课费用 | K41: =K29*O8 | L41: =L29*P8 | N41: 单课时试听课费用*出席人数
I42: 主投 | J42: TMK费用 | K42: =IF(O10="是",K3/O11*O12,0) | L42: =IF(P10="是",L3/P11*P12,0) | N42: 例子数/TMK人均承担例子量*TMK人均成本=TMK人数*TMK人均成本
...

Sheet 邓明仪直播
A1: 邓明仪直播 | B1: 例子占比 | C1: 总例子数 | D1: 成本 | E1: 加权 | F1: 实际投放时间 | G1: 投放时间1个半月
A2: 汇总 | B2: 1 | C2: 180 | D2: 680 | E2: {=SUMPRODUCT(C3:C6,D3:D6)/C2} | F2: 90 | I2: 以项目或周期为单位 | J2: 前端投放参数-预估 | K2: 益智 | L2: 美术
A3: 12月 | B3: 0.5 | C3: =B3*C2 | D3: 600 | F3: 23 | I3: 主投 | J3: 注册例子数 | K3: 180 | N3: 其他参数（海外调整） | O3: 益智 | P3: 美术
A4: 1月 | B4: 0.25 | C4: =B4*C2 | D4: 700 | F4: 31 | I4: 主投 | J4: 分发例子数 | N4: 销售人均承接例子数 | O4: 93.8 | P4: 103
A5: 2月 | B5: 0.2 | C5: =B5*C2 | D5: 750 | F5: 28 | I5: 主投 | J5: 单例子成本（CPA） | K5: 700 | N5: 销售人均固定人工成本 | O5: 10622 | P5: 11145.017
A6: 3月 | B6: 0.05 | C6: =B6*C2 | D6: 800 | F6: 8 | I6: 主投 | J6: 单到课例子成本（CPA） | N6: 销售提成比例 | O6: 0.079 | P6: 0.077
I7: 主投 | J7: 渠道佣金（CPS） | N7: 礼品及其他费用比例 | O7: 0.017 | P7: 0.022
I8: 主投 | J8: 投放费用（CPT) | K8: 30000 | N8: 出席试听课费用 | O8: 86.4 | P8: 82
I9: 辅投 | J9: 注册例子数 | N9: 单例子渠道运营人工成本及其他 | O9: 33.49 | P9: 75
I10: 辅投 | J10: 分发例子数 | N10: 是否过TMK | O10: 是 | P10: 是
I11: 辅投 | J11: 单例子成本（CPA） | N11: TMK人均承担例子量 | O11: 1055 | P11: 1233
I12: 辅投 | J12: 单到课例子成本（CPA） | N12: TMK人均成本 | O12: 11181 | P12: 11486.424
I13: 辅投 | J13: 渠道佣金（CPS） | N13: 备注：绿色填充部分可调整，没有对应的参数可留空
I14: 辅投 | J14: 投放费用（CPT) | O14: =O5/O4 | P14: =P5/P4
O15: =O12/O11
J16: 过程指标-预估
J17: 注册分发率 | K17: 0.5
I18: 主投 | J18: 滚动注册出席率 | K18: 0.38
I19: 主投 | J19: 滚动出席转化率 | K19: 0.35
I20: 主投 | J20: 滚动注册转化率 | K20: 0.165
I21: 主投 | J21: 正价课ASP | K21: 5000
I22: 辅投 | J22: 注册分发率
I23: 辅投 | J23: 滚动注册出席率
I24: 辅投 | J24: 滚动出席转化率
I25: 辅投 | J25: 滚动注册转化率
I26: 辅投 | J26: 正价课ASP
J28: ROI 1相关指标-自动计算
I29: 主投 | J29: 到课学员数量 | K29: =K18*K3 | L29: =L18*L3 | N29: 例子数*注册出席率
I30: 主投 | J30: 正价课学员数量 | K30: =K3*K20 | L30: =L3*L20 | N30: 例子数*注册转化率
I31: 主投 | J31: 正价课GMV | K31: =K30*K21 | L31: =L30*L21 | N31: ASP*学员人数
I32: 主投 | J32: 前端投放总成本 | K32: =K5*K3+K7*K31+K8+K29*K6+K3*O9 | L32: =L5*L3+L7*L31+L8+L29*L6+L3*P9 | N32: 例子数*单例子成本+GMV*CPS佣金比例+投放费用+单到课例子成本*出席人数+例子数*单例子运营人工成本
I33: 辅投 | J33: 到课学员数量 | K33: =K23*K9 | L33: =L23*L9
I34: 辅投 | J34: 正价课学员数量 | K34: =K9*K25 | L34: =L9*L25
I35: 辅投 | J35: 正价课GMV | K35: =K26*K34 | L35: =L26*L34
I36: 辅投 | J36: 前端投放总成本 | K36: =K9*K11+K13*K35+K14+K12*K33+K9*P9 | L36: =L9*L11+L13*L35+L14+L12*L33+L9*O9 | N36: 例子数*单例子成本+GMV*CPS佣金比例+投放费用+单到课例子成本*出席人数+例子数*单例子运营人工成本
I37: 主投+辅投 | J37: 每单获客成本1 | K37: =(K32+K36)/(K30+K34) | L37: =(L32+L36)/(L30+L34) | N37: 前端投放总成本/学员人数
J38: ROI 1 | K38: =(K31+K35)/(K32+K36) | L38: =(L31+L35)/(L32+L36) | N38: GMV/前端投放总成本
J40: ROI 2相关指标-自动计算
I41: 主投 | J41: 试听课费用 | K41: =K29*O8 | L41: =L29*P8 | N41: 单课时试听课费用*出席人数
I42: 主投 | J42: TMK费用 | K42: =IF(O10="是",K3/O11*O12,0) | L42: =IF(P10="是",L3/P11*P12,0) | N42: 例子数/TMK人均承担例子量*TMK人均成本=TMK人数*TMK人均成本
...

Sheet 麦雅致
A1: 麦雅致 | B1: 例子占比 | C1: 总例子数 | D1: 成本 | E1: 加权 | F1: 实际投放时间 | G1: 投放时间1个半月
A2: 汇总 | B2: 1 | C2: 280 | D2: 700 | E2: =SUMPRODUCT(C3:C4,D3:D4)/C2 | F2: 45 | J2: 以项目或周期为单位 | K2: 前端投放参数-预估 | L2: 益智 | M2: 美术
A3: 11月 | B3: =C3/$C$2 | C3: 180 | D3: 700 | F3: 25 | J3: 主投 | K3: 注册例子数 | L3: 280 | O3: 其他参数（海外调整） | P3: 益智 | Q3: 美术
A4: 12月 | B4: =C4/$C$2 | C4: 100 | D4: 800 | F4: 20 | J4: 主投 | K4: 分发例子数 | O4: 销售人均承接例子数 | P4: 93.8 | Q4: 103
J5: 主投 | K5: 单例子成本（CPA） | L5: 700 | O5: 销售人均固定人工成本 | P5: 10622 | Q5: 11145.017
J6: 主投 | K6: 单到课例子成本（CPA） | O6: 销售提成比例 | P6: 0.079 | Q6: 0.077
J7: 主投 | K7: 渠道佣金（CPS） | O7: 礼品及其他费用比例 | P7: 0.017 | Q7: 0.022
J8: 主投 | K8: 投放费用（CPT) | L8: 75000 | O8: 出席试听课费用 | P8: 86.4 | Q8: 82
J9: 辅投 | K9: 注册例子数 | O9: 单例子渠道运营人工成本及其他 | P9: 33.49 | Q9: 75
J10: 辅投 | K10: 分发例子数 | O10: 是否过TMK | P10: 是 | Q10: 是
J11: 辅投 | K11: 单例子成本（CPA） | O11: TMK人均承担例子量 | P11: 1055 | Q11: 1233
J12: 辅投 | K12: 单到课例子成本（CPA） | O12: TMK人均成本 | P12: 11181 | Q12: 11486.424
J13: 辅投 | K13: 渠道佣金（CPS） | O13: 备注：绿色填充部分可调整，没有对应的参数可留空
J14: 辅投 | K14: 投放费用（CPT) | P14: =P5/P4 | Q14: =Q5/Q4
P15: =P12/P11
K16: 过程指标-预估
K17: 注册分发率 | L17: 0.5
J18: 主投 | K18: 滚动注册出席率 | L18: 0.38
J19: 主投 | K19: 滚动出席转化率 | L19: 0.35
J20: 主投 | K20: 滚动注册转化率 | L20: 0.18
J21: 主投 | K21: 正价课ASP | L21: 5000
J22: 辅投 | K22: 注册分发率
J23: 辅投 | K23: 滚动注册出席率
J24: 辅投 | K24: 滚动出席转化率
J25: 辅投 | K25: 滚动注册转化率
J26: 辅投 | K26: 正价课ASP
K28: ROI 1相关指标-自动计算
J29: 主投 | K29: 到课学员数量 | L29: =L18*L3 | M29: =M18*M3 | O29: 例子数*注册出席率
J30: 主投 | K30: 正价课学员数量 | L30: =L3*L20 | M30: =M3*M20 | O30: 例子数*注册转化率
J31: 主投 | K31: 正价课GMV | L31: =L30*L21 | M31: =M30*M21 | O31: ASP*学员人数
J32: 主投 | K32: 前端投放总成本 | L32: =L5*L3+L7*L31+L8+L29*L6+L3*P9 | M32: =M5*M3+M7*M31+M8+M29*M6+M3*Q9 | O32: 例子数*单例子成本+GMV*CPS佣金比例+投放费用+单到课例子成本*出席人数+例子数*单例子运营人工成本
J33: 辅投 | K33: 到课学员数量 | L33: =L23*L9 | M33: =M23*M9
J34: 辅投 | K34: 正价课学员数量 | L34: =L9*L25 | M34: =M9*M25
J35: 辅投 | K35: 正价课GMV | L35: =L26*L34 | M35: =M26*M34
J36: 辅投 | K36: 前端投放总成本 | L36: =L9*L11+L13*L35+L14+L12*L33+L9*Q9 | M36: =M9*M11+M13*M35+M14+M12*M33+M9*P9 | O36: 例子数*单例子成本+GMV*CPS佣金比例+投放费用+单到课例子成本*出席人数+例子数*单例子运营人工成本
J37: 主投+辅投 | K37: 每单获客成本1 | L37: =(L32+L36)/(L30+L34) | M37: =(M32+M36)/(M30+M34) | O37: 前端投放总成本/学员人数
K38: ROI 1 | L38: =(L31+L35)/(L32+L36) | M38: =(M31+M35)/(M32+M36) | O38: GMV/前端投放总成本
K40: ROI 2相关指标-自动计算
J41: 主投 | K41: 试听课费用 | L41: =L29*P8 | M41: =M29*Q8 | O41: 单课时试听课费用*出席人数
J42: 主投 | K42: TMK费用 | L42: =IF(P10="是",L3/P11*P12,0) | M42: =IF(Q10="是",M3/Q11*Q12,0) | O42: 例子数/TMK人均承担例子量*TMK人均成本=TMK人数*TMK人均成本
...

Sheet 吕慧仪
A1: 吕慧仪 | B1: 例子占比 | C1: 总例子数 | D1: 成本 | E1: 加权 | F1: 实际投放天数 | G1: 预计上线时间11.15
A2: 汇总 | B2: 1 | C2: 230 | D2: 700 | E2: {=SUMPRODUCT(C3:C6,D3:D6)/C2} | I2: 以项目或周期为单位 | J2: 前端投放参数-预估 | K2: 益智 | L2: 美术
A3: 11月 | B3: =C3/$C$2 | C3: 100 | D3: 600 | F3: 15 | I3: 主投 | J3: 注册例子数 | K3: 230 | N3: 其他参数（海外调整） | O3: 益智 | P3: 美术
A4: 12月 | B4: =C4/$C$2 | C4: 70 | D4: 650 | F4: 31 | I4: 主投 | J4: 分发例子数 | N4: 销售人均承接例子数 | O4: 93.8 | P4: 103
A5: 1月 | B5: =C5/$C$2 | C5: 40 | D5: 800 | F5: 31 | I5: 主投 | J5: 单例子成本（CPA） | K5: 700 | N5: 销售人均固定人工成本 | O5: 10622 | P5: 11145.017
A6: 2月 | B6: =C6/$C$2 | C6: 20 | D6: 900 | F6: 13 | I6: 主投 | J6: 单到课例子成本（CPA） | N6: 销售提成比例 | O6: 0.079 | P6: 0.077
I7: 主投 | J7: 渠道佣金（CPS） | N7: 礼品及其他费用比例 | O7: 0.017 | P7: 0.022
I8: 主投 | J8: 投放费用（CPT) | K8: 60000 | N8: 出席试听课费用 | O8: 86.4 | P8: 82
I9: 辅投 | J9: 注册例子数 | N9: 单例子渠道运营人工成本及其他 | O9: 33.49 | P9: 75
I10: 辅投 | J10: 分发例子数 | N10: 是否过TMK | O10: 是 | P10: 是
I11: 辅投 | J11: 单例子成本（CPA） | N11: TMK人均承担例子量 | O11: 1055 | P11: 1233
I12: 辅投 | J12: 单到课例子成本（CPA） | N12: TMK人均成本 | O12: 11181 | P12: 11486.424
I13: 辅投 | J13: 渠道佣金（CPS） | N13: 备注：绿色填充部分可调整，没有对应的参数可留空
I14: 辅投 | J14: 投放费用（CPT) | O14: =O5/O4 | P14: =P5/P4
O15: =O12/O11
J16: 过程指标-预估
J17: 注册分发率 | K17: 0.5
I18: 主投 | J18: 滚动注册出席率 | K18: 0.38
I19: 主投 | J19: 滚动出席转化率 | K19: 0.35
I20: 主投 | J20: 滚动注册转化率 | K20: 0.18
I21: 主投 | J21: 正价课ASP | K21: 5000
I22: 辅投 | J22: 注册分发率
I23: 辅投 | J23: 滚动注册出席率
I24: 辅投 | J24: 滚动出席转化率
I25: 辅投 | J25: 滚动注册转化率
I26: 辅投 | J26: 正价课ASP
J28: ROI 1相关指标-自动计算
I29: 主投 | J29: 到课学员数量 | K29: =K18*K3 | L29: =L18*L3 | N29: 例子数*注册出席率
I30: 主投 | J30: 正价课学员数量 | K30: =K3*K20 | L30: =L3*L20 | N30: 例子数*注册转化率
I31: 主投 | J31: 正价课GMV | K31: =K30*K21 | L31: =L30*L21 | N31: ASP*学员人数
I32: 主投 | J32: 前端投放总成本 | K32: =K5*K3+K7*K31+K8+K29*K6+K3*O9 | L32: =L5*L3+L7*L31+L8+L29*L6+L3*P9 | N32: 例子数*单例子成本+GMV*CPS佣金比例+投放费用+单到课例子成本*出席人数+例子数*单例子运营人工成本
I33: 辅投 | J33: 到课学员数量 | K33: =K23*K9 | L33: =L23*L9
I34: 辅投 | J34: 正价课学员数量 | K34: =K9*K25 | L34: =L9*L25
I35: 辅投 | J35: 正价课GMV | K35: =K26*K34 | L35: =L26*L34
I36: 辅投 | J36: 前端投放总成本 | K36: =K9*K11+K13*K35+K14+K12*K33+K9*P9 | L36: =L9*L11+L13*L35+L14+L12*L33+L9*O9 | N36: 例子数*单例子成本+GMV*CPS佣金比例+投放费用+单到课例子成本*出席人数+例子数*单例子运营人工成本
I37: 主投+辅投 | J37: 每单获客成本1 | K37: =(K32+K36)/(K30+K34) | L37: =(L32+L36)/(L30+L34) | N37: 前端投放总成本/学员人数
J38: ROI 1 | K38: =(K31+K35)/(K32+K36) | L38: =(L31+L35)/(L32+L36) | N38: GMV/前端投放总成本
J40: ROI 2相关指标-自动计算
I41: 主投 | J41: 试听课费用 | K41: =K29*O8 | L41: =L29*P8 | N41: 单课时试听课费用*出席人数
I42: 主投 | J42: TMK费用 | K42: =IF(O10="是",K3/O11*O12,0) | L42: =IF(P10="是",L3/P11*P12,0) | N42: 例子数/TMK人均承担例子量*TMK人均成本=TMK人数*TMK人均成本
...

Sheet 專家鄧明儀
A1: 專家鄧明儀 | B1: 例子占比 | C1: 总例子数 | D1: 成本 | E1: 加权
A2: 汇总 | B2: 1 | C2: 65 | D2: 720 | E2: =SUMPRODUCT(C3:C5,D3:D5)/C2 | H2: 以项目或周期为单位 | I2: 前端投放参数-预估 | J2: 益智 | K2: 美术
A3: 10月 | B3: =C3/$C$2 | C3: 40 | D3: 600 | H3: 主投 | I3: 注册例子数 | J3: 65 | M3: 其他参数（海外调整） | N3: 益智 | O3: 美术
A4: 11月 | B4: =C4/$C$2 | C4: 20 | D4: 750 | H4: 主投 | I4: 分发例子数 | M4: 销售人均承接例子数 | N4: 93.8 | O4: 103
A5: 12月 | B5: =C5/$C$2 | C5: 5 | D5: 900 | H5: 主投 | I5: 单例子成本（CPA） | J5: 700 | M5: 销售人均固定人工成本 | N5: 10622 | O5: 11145.017
H6: 主投 | I6: 单到课例子成本（CPA） | M6: 销售提成比例 | N6: 0.079 | O6: 0.077
H7: 主投 | I7: 渠道佣金（CPS） | M7: 礼品及其他费用比例 | N7: 0.017 | O7: 0.022
H8: 主投 | I8: 投放费用（CPT) | J8: 16740 | M8: 出席试听课费用 | N8: 86.4 | O8: 82
H9: 辅投 | I9: 注册例子数 | M9: 单例子渠道运营人工成本及其他 | N9: 33.49 | O9: 75
H10: 辅投 | I10: 分发例子数 | M10: 是否过TMK | N10: 是 | O10: 是
H11: 辅投 | I11: 单例子成本（CPA） | M11: TMK人均承担例子量 | N11: 1055 | O11: 1233
H12: 辅投 | I12: 单到课例子成本（CPA） | M12: TMK人均成本 | N12: 11181 | O12: 11486.424
H13: 辅投 | I13: 渠道佣金（CPS） | M13: 备注：绿色填充部分可调整，没有对应的参数可留空
H14: 辅投 | I14: 投放费用（CPT) | N14: =N5/N4 | O14: =O5/O4
N15: =N12/N11
I16: 过程指标-预估
I17: 注册分发率 | J17: 0.5
H18: 主投 | I18: 滚动注册出席率 | J18: 0.38
H19: 主投 | I19: 滚动出席转化率 | J19: 0.35
H20: 主投 | I20: 滚动注册转化率 | J20: 0.18
H21: 主投 | I21: 正价课ASP | J21: 5000
H22: 辅投 | I22: 注册分发率
H23: 辅投 | I23: 滚动注册出席率
H24: 辅投 | I24: 滚动出席转化率
H25: 辅投 | I25: 滚动注册转化率
H26: 辅投 | I26: 正价课ASP
I28: ROI 1相关指标-自动计算
H29: 主投 | I29: 到课学员数量 | J29: =J18*J3 | K29: =K18*K3 | M29: 例子数*注册出席率
H30: 主投 | I30: 正价课学员数量 | J30: =J3*J20 | K30: =K3*K20 | M30: 例子数*注册转化率
H31: 主投 | I31: 正价课GMV | J31: =J30*J21 | K31: =K30*K21 | M31: ASP*学员人数
H32: 主投 | I32: 前端投放总成本 | J32: =J5*J3+J7*J31+J8+J29*J6+J3*N9 | K32: =K5*K3+K7*K31+K8+K29*K6+K3*O9 | M32: 例子数*单例子成本+GMV*CPS佣金比例+投放费用+单到课例子成本*出席人数+例子数*单例子运营人工成本
H33: 辅投 | I33: 到课学员数量 | J33: =J23*J9 | K33: =K23*K9
H34: 辅投 | I34: 正价课学员数量 | J34: =J9*J25 | K34: =K9*K25
H35: 辅投 | I35: 正价课GMV | J35: =J26*J34 | K35: =K26*K34
H36: 辅投 | I36: 前端投放总成本 | J36: =J9*J11+J13*J35+J14+J12*J33+J9*O9 | K36: =K9*K11+K13*K35+K14+K12*K33+K9*N9 | M36: 例子数*单例子成本+GMV*CPS佣金比例+投放费用+单到课例子成本*出席人数+例子数*单例子运营人工成本
H37: 主投+辅投 | I37: 每单获客成本1 | J37: =(J32+J36)/(J30+J34) | K37: =(K32+K36)/(K30+K34) | M37: 前端投放总成本/学员人数
I38: ROI 1 | J38: =(J31+J35)/(J32+J36) | K38: =(K31+K35)/(K32+K36) | M38: GMV/前端投放总成本
I40: ROI 2相关指标-自动计算
H41: 主投 | I41: 试听课费用 | J41: =J29*N8 | K41: =K29*O8 | M41: 单课时试听课费用*出席人数
H42: 主投 | I42: TMK费用 | J42: =IF(N10="是",J3/N11*N12,0) | K42: =IF(O10="是",K3/O11*O12,0) | M42: 例子数/TMK人均承担例子量*TMK人均成本=TMK人数*TMK人均成本
...

Sheet 陳凱琳
A1: 陳凱琳 | B1: 例子占比 | C1: 总例子数 | D1: 成本 | E1: 加权
A2: 汇总 | B2: 1 | C2: 700 | D2: 720 | E2: {=SUMPRODUCT(C3:C6,D3:D6)/C2}
A3: 10月 | B3: =C3/$C$2 | C3: 140 | D3: 550
A4: 11月 | B4: =C4/$C$2 | C4: 300 | D4: 640 | G4: =230/30*20+170/30*10
A5: 12月 | B5: =C5/$C$2 | C5: 190 | D5: 750
A6: 1月 | B6: =C6/$C$2 | C6: 70 | D6: 900

Sheet 陈展鹏
A1: 陈展鹏 | B1: 例子占比 | C1: 总例子数 | D1: 成本 | E1: 加权
A2: 汇总 | B2: 1 | C2: 380 | D2: 720 | E2: =SUMPRODUCT(C3:C6,D3:D6)/C2
A3: 9月 | B3: =C3/$C$2 | C3: 170 | D3: 550
A4: 10月 | B4: =C4/$C$2 | C4: 120 | D4: 800
A5: 11月 | B5: =C5/$C$2 | C5: 70 | D5: 900
A6: 12月 | B6: =C6/$C$2 | C6: 20 | D6: 1000

Sheet 陈琪
A1: 陈展鹏 | B1: 例子占比 | C1: 总例子数 | D1: 成本 | E1: 加权
A2: 汇总 | B2: 1 | C2: 320 | D2: 720 | E2: =SUMPRODUCT(C3:C8,D3:D8)/450
A3: 9月 | B3: =C3/$C$2 | C3: 200 | D3: 550
A4: 10月 | B4: =C4/$C$2 | C4: 100 | D4: 800
A5: 11月 | B5: =C5/$C$2 | C5: 60 | D5: 900
A6: 12月 | B6: =C6/$C$2 | C6: 40 | D6: 1000
A7: 1月 | B7: =C7/$C$2 | C7: 30 | D7: 1000
A8: 2月 | B8: =C8/$C$2 | C8: 20 | D8: 1000

Sheet 展会数据测算
A1: 汇率 | B1: 0.93 | D1: 0.93 | F1: 0.93 | I1: 0.92 | K1: 0.93 | M1: 0.93 | O1: 0.91 | Q1: 0.93 | AB1: 0.93 | AD1: 0.93
A2: 展会 | B2: 2025年2月BB展 | D2: 2025年5月课外活动展 | F2: 2025年5月儿童书展 | H2: 2025年7月大湾区 | I2: 2025年7月儿童书展 | K2: 8月bb展 | M2: 9月澳门展 | O2: 10月创意文化展（预估） | Q2: 10月兒童書展（预估） | S2: 12月兒童書展（预估） | U2: 8個展位(以此为准） | V2: 12月澳门展 | X2: 2026年BB展開支 | Z2: 26年4月月澳门展 | AB2: 2025年5月课外活动展 | AD2: 2025年5月儿童书展 | AF2: 6月澳门展
A3: 项目 | B3: 费用-HKD | C3: 费用-RMB | D3: 费用-HKD | E3: 费用-RMB | F3: 费用-HKD | G3: 费用-RMB | H3: 费用-RMB | I3: 费用-HKD | J3: 费用-RMB | K3: 费用-HKD | L3: 费用-RMB | M3: 费用-HKD | N3: 费用-RMB | O3: 费用-HKD | P3: 费用-RMB | Q3: 费用-HKD | R3: 费用-RMB | S3: 费用-HKD | T3: 费用-RMB | U3: 费用-RMB | V3: 费用-HKD | W3: 费用-RMB | X3: 费用-HKD | Y3: 费用-RMB | Z3: 费用-HKD | AA3: 费用-RMB | AB3: 费用-HKD | AC3: 费用-RMB | AD3: 费用-HKD | AE3: 费用-RMB | AF3: 费用-HKD | AG3: 费用-RMB
A4: 展位费 | B4: 30000 | C4: =B4*$B$1 | D4: 42960 | E4: =D4*$D$1 | F4: 50000 | G4: =F4*$F$1 | H4: 0 | I4: 112392 | J4: =I4*$I$1 | K4: 29000 | L4: =K4*$K$1 | M4: 13000 | N4: =M4*$K$1 | O4: 21924 | P4: =O4*$O$1 | Q4: 29800 | R4: =Q4*$K$1 | S4: 29800 | T4: 27714 | U4: 49885.2 | V4: 15000 | W4: =V4*$Q$1 | X4: 18000 | Y4: 16380 | Z4: 13000 | AA4: =Z4*$K$1 | AB4: 28000 | AC4: =AB4*$D$1 | AD4: 29800 | AE4: =AD4*$F$1 | AF4: 12000 | AG4: =AF4*$K$1
A5: 搭建费 | B5: 3700 | C5: =B5*$B$1 | D5: 5066 | E5: =D5*$D$1 | F5: 9486 | G5: =F5*$F$1 | H5: 0 | I5: 7324 | J5: =I5*$I$1 | K5: 2841 | L5: =K5*$K$1 | M5: 3750 | N5: =M5*$K$1 | O5: 2103 | P5: =O5*$O$1 | Q5: 9486 | R5: =Q5*$K$1 | S5: 9486 | T5: 8822 | U5: 12408.9 | V5: 3915 | W5: =V5*$Q$1 | X5: 2400 | Y5: 2184 | Z5: 3750 | AA5: =Z5*$K$1 | AB5: 5066 | AC5: =AB5*$D$1 | AD5: =9486/2 | AE5: =AD5*$F$1 | AF5: 3000 | AG5: =AF5*$K$1
A6: 礼品-馬克筆 | B6: 3526.88 | C6: =B6*$B$1 | D6: 5454 | E6: =D6*$D$1 | F6: 7741.94 | G6: =F6*$F$1 | H6: 0 | I6: 14464.29 | J6: =I6*$I$1 | K6: 2948.03 | L6: =K6*$K$1 | M6: 2000 | N6: =M6*$K$1 | O6: 5030 | P6: =O6*$O$1 | Q6: 6290.32 | R6: =Q6*$K$1 | S6: 6290.32 | T6: 5850 | U6: 8775 | V6: =12.5*98/0.93 | W6: =V6*$Q$1 | X6: 5413.4615 | Y6: 4926.25 | Z6: 2000 | AA6: =Z6*$K$1 | AB6: =12.5*280 | AC6: =AB6*$D$1 | AD6: =12.5*370 | AE6: =AD6*$F$1 | AF6: =12.5*120 | AG6: =AF6*$K$1
A7: 禮品物流費
A8: POP制作/打印等 | B8: 1140 | C8: =B8*$B$1 | I8: 540 | J8: =I8*$I$1
A9: WIFI 蛋租赁 | B9: 580 | C9: =B9*$B$1 | D9: 580 | E9: =D9*$D$1 | F9: 515 | G9: =F9*$F$1 | H9: 0 | I9: 990 | J9: =I9*$I$1 | K9: 580 | L9: =K9*$K$1 | M9: 580 | N9: =M9*$K$1 | O9: 499 | P9: =O9*$O$1 | Q9: 515 | R9: =Q9*$K$1 | S9: 515 | T9: 479 | U9: 445.4 | V9: 500 | W9: =V9*$Q$1 | Z9: 580 | AA9: =Z9*$K$1 | AB9: 580 | AC9: =AB9*$D$1 | AD9: 515 | AE9: =AD9*$F$1
A10: 文具 | B10: 77 | C10: =B10*$B$1
A11: 电费 | K11: 1420 | L11: =K11*$K$1
A12: 礼品-氣球 | E12: 3174 | G12: =F12*$F$1 | I12: 1219.78 | J12: =I12*$I$1
A13: pad充電線*8 | E13: 160
A14: 香港物流費 | B14: 1580 | C14: =B14*$B$1 | D14: 1600 | E14: ¥1,488.0 | F14: 1600 | G14: =F14*$F$1 | H14: 0 | I14: 2350 | J14: =I14*$I$1 | K14: 1600 | L14: =K14*$K$1 | M14: 2000 | N14: =M14*$K$1 | O14: 830 | P14: =O14*$O$1 | Q14: 1600 | R14: =Q14*$K$1 | S14: 1600 | T14: 2976 | U14: 2767.7 | V14: 1500 | W14: =V14*$Q$1 | X14: 1900 | Y14: 1729 | Z14: 2000 | AA14: =Z14*$K$1 | AB14: 1600 | AC14: ¥1,488.0 | AD14: 1600 | AE14: =AD14*$F$1 | AF14: 2000 | AG14: =AF14*$K$1
A15: 餐費 | B15: 3942.2 | C15: =B15*$B$1 | D15: 3387.1 | E15: ¥3,150.0 | F15: 4351.4 | G15: =F15*$F$1 | H15: 0 | I15: 11538.46 | J15: =I15*$I$1 | K15: 2628.13 | L15: =K15*$K$1 | M15: 2000 | N15: =M15*$K$1 | O15: 1800 | P15: =O15*$O$1 | Q15: 4351.4 | R15: =Q15*$K$1 | S15: 4351.4 | T15: 4046.8 | U15: 4046.8 | V15: 2250 | W15: =V15*$Q$1 | Z15: 2000 | AA15: =Z15*$K$1 | AB15: 3387.1 | AC15: ¥3,150.0 | AD15: 4351.4 | AE15: =AD15*$F$1 | AF15: 2000 | AG15: =AF15*$K$1
A16: 工衣洗衣 | F16: 200 | G16: =F16*$F$1
A17: 代理CPS费（预估） | H17: =60000*35% | J17: =122*9%*4500*35% | L17: =(270-140)*9%*4500*30% | P17: =50*9%*4500*35% | R17: =90*9%*4500*35% | X17: =Y17/0.91 | Y17: =85692.541*0.35
A18: 差旅（住宿）（预估） | C18: =800*4*3 | E18: =1200*4*3 | G18: =1200*4*3 | H18: 0 | J18: =1100*4*7 | L18: =1000*3+2000*2 | N18: =700*4 | P18: =750*4 | R18: =750*8 | U18: =750*8 | W18: =750*4 | AC18: =1200*6*3 | AE18: =1200*4*3 | AG18: =700*4
A19: 差率（车票）（预估） | C19: =8*430 | E19: =8*430 | G19: =8*430 | H19: 0 | J19: =16*430 | L19: =5*430 | N19: =200*6 | P19: =430*4 | R19: =430*8 | U19: =430*8 | W19: =430*4 | AC19: =12*430 | AE19: =8*430 | AG19: =200*6
A21: 總開支 | B21: =SUM(B4:B16) | C21: =SUM(C4:C16) | D21: =SUM(D4:D16) | E21: =SUM(E4:E16) | F21: =SUM(F4:F16) | G21: =SUM(G4:G16) | I21: =SUM(I4:I16) | J21: =SUM(J4:J16) | K21: =SUM(K4:K16) | L21: =SUM(L4:L16) | M21: =SUM(M4:M16) | N21: =SUM(N4:N16) | O21: =SUM(O4:O16) | P21: =SUM(P4:P16) | ... R21: =SUM(R4:R16) | U21: =SUM(U4:U16) | W21: =SUM(W4:W16) | Y21: =SUM(Y4:Y17) | Z21: =SUM(Z4:Z16) | AA21: =SUM(AA4:AA16) | AB21: =SUM(AB4:AB16) | AC21: =SUM(AC4:AC16) | AD21: =SUM(AD4:AD16) | AE21: =SUM(AE4:AE16) | AF21: =SUM(AF4:AF16) | AG21: =SUM(AG4:AG16)
A22: 总开支（含差旅） | C22: =C21+C18+C19 | E22: =E21+E18+E19 | G22: =G21+G18+G19 | H22: =H21+H18+H19+H17 | J22: =J21+J18+J19+J17 | L22: =L21+L18+L19+L17 | N22: =N21+N18+N19+N17 | P22: =P21+P18+P19+P17 | R22: =R21+R18+R19+R17 | U22: =U21+U18+U19+U17 | W22: =W21+W18+W19+W17 | Y22: =Y21 | AA22: =AA21+AA18+AA19+AA17 | AC22: =AC21+AC18+AC19 | AE22: =AE21+AE18+AE19 | AG22: =AG21+AG18+AG19+AG17
A24: 总例子数 | C24: 235 | E24: 303 | G24: 301 | H24: 155 | J24: 587 | L24: 270 | N24: 150 | P24: 200 | R24: 400 | U24: 450 | W24: 150 | Y24: 282 | AA24: 110 | AC24: 260 | AE24: 350 | AG24: 100
A26: 平均例子成本（总，不含差旅合CPS） | C26: =C21/C24 | E26: =E21/E24 | G26: =G21/G24 | J26: =J21/J24 | L26: =(L21)/L24 | N26: =(N21)/N24 | P26: =(P21)/P24 | R26: =(R21)/R24 | U26: =(U21)/U24 | W26: =(W21)/W24 | Y26: =(Y21)/Y24 | AA26: =(AA21)/AA24 | AC26: =AC21/AC24 | AE26: =AE21/AE24 | AG26: =(AG21)/AG24
A27: 平均例子成本（总，含差旅CPS） | C27: =C22/C24 | E27: =E22/E24 | G27: =G22/G24 | H27: =H22/H24 | J27: =J22/J24 | L27: =L22/L24 | N27: =N22/N24 | P27: =P22/P24 | R27: =R22/R24 | U27: =U22/U24 | W27: =W22/W24 | Y27: =Y22/Y24 | AA27: =AA22/AA24 | AC27: =AC22/AC24 | AE27: =AE22/AE24 | AG27: =AG22/AG24
A30: 成本（展位搭建礼品物流餐费） | C30: =C4+C5+C6+C14+C15 | D30: =D4+D5+D6+D14+D15 | E30: 53374.3 | G30: =G4+G5+G6+G14+G15 | J30: =J4+J5+J6+J14+J15 | L30: =L4+L5+L6+L14+L15 | N30: =N4+N5+N6+N14+N15 | P30: =P4+P5+P6+P14+P15 | R30: =R4+R5+R6+R14+R15 | U30: =U4+U5+U6+U14+U15 | AA30: =AA4+AA5+AA6+AA14+AA15 | AG30: =AG4+AG5+AG6+AG14+AG15
A31: 平均例子成本（展位搭建礼品物流餐费） | C31: =C30/C24 | E31: =E30/E24 | G31: =G30/G24 | J31: =J30/J24 | L31: =L30/L24 | N31: =N30/N24 | P31: =P30/P24 | R31: =R30/R24 | U31: =U30/U24 | AA31: =AA30/AA24 | AG31: =AG30/AG24
K34: 代理CPS费用 | L34: =(270-140)*9%*4500*30%

Sheet BB展ROI测算数据
F2: 主投思维 | I2: 2025/2/14-16日 | K2: 2025年5月3-5日 | L2: 2025年5月23-25日 | M2: 45689 | N2: 45870 | O2: 2026年2月6-8日 | P2: 2026年2月6-8日
B3: 参数：8月初 | C3: 益智 | D3: 美术 | H3: 9月兒童書展 | I3: 12月兒童書展 | J3: 2月BB展 | K3: 課外活動展 | L3: 5月兒童展 | M3: 2月BB展 | N3: 8月BB展 | O3: 3月BB展 | P3: 3月BB展
B4: 单例子销售固定人工成本 | C4: 89.09 | D4: 83.45 | F4: 链路合计 | G4: ROI 2 | H4: =H5/H6 | I4: =I5/I6 | J4: =J5/J6 | K4: =K5/K6 | L4: =L5/L6 | M4: =M5/M6 | N4: =N5/N6 | O4: =O5/O6 | P4: =P5/P6
B5: 单例子TMK人工成本 | C5: 8.99 | D5: 8.99 | F5: 链路合计 | G5: GMV | H5: =H17+H35 | I5: =I17+I35 | J5: =J17+J35 | K5: =K17+K35 | L5: =L17+L35 | M5: =M17+M35 | N5: =N17+N35 | O5: =O17+O35 | P5: =P17+P35
B6: 销售提成比例 | C6: 0.0894 | D6: 0.0839 | F6: 链路合计 | G6: ROI 2成本项 | H6: =H36+H18 | I6: =I36+I18 | J6: =J36+J18 | K6: =K36+K18 | L6: =L36+L18 | M6: =M36+M18 | N6: =N36+N18 | O6: =O36+O18 | P6: =P36+P18
B7: 礼品及其他费用比例 | C7: 0.0132 | D7: 0.0155 | F7: 链路合计 | G7: 渠道预算 | H7: 97616 | I7: 145759.8 | J7: 41427.9 | K7: 51452.7 | L7: 60000 | M7: =[1]開支總表!C15 | N7: =M7 | O7: =[1]開支總表!E15 | P7: =[1]開支總表!F15
B8: 试听课单课时成本 | C8: 83.03 | D8: 74.31 | F8: 入場人數 | H8: 300000 | I8: 380000 | J8: 150000 | K8: 150000 | L8: 300000 | M8: 50000 | N8: 50000 | O8: 50000 | P8: 50000
B9: 单例子市场运营人工及日常成本 | C9: 100 | D9: 100 | F9: 主投 | G9: 例子数 | H9: 420 | I9: 360 | J9: 235 | K9: 303 | L9: 301 | M9: 235 | N9: 328 | O9: =(M9+N9)/2 | P9: =O9
F10: 主投 | G10: 例子分发率 | H10: =H14/H9 | I10: =H10 | J10: =H10 | K10: =I10 | L10: =K10 | M10: =K10 | N10: =L10 | O10: =M10 | P10: =N10
F11: 主投 | G11: 例子到课率 | H11: =H15/H9 | I11: 0.517 | J11: 0.51 | K11: =82.8%*86.9% | L11: =77.7%*77.8% | M11: 0.535 | N11: 0.52 | O11: =(M11+N11)/2 | P11: =O11
F12: 主投 | G12: 滚动转化率 | H12: =H16/H9 | I12: 0.094 | J12: 0.085 | K12: 0.139 | L12: 0.09 | M12: 0.085 | N12: 0.052 | O12: =(M12+N12)/2 | P12: =O12
F13: 主投 | G13: ASP | H13: =H17/H16 | I13: 3943 | J13: 4444 | K13: 4220 | L13: 4898 | M13: 4444 | N13: 4329 | O13: 4444 | P13: 4444
F14: 主投 | G14: 分发数 | H14: 416 | I14: =I$9*I10 | J14: =J$9*J10 | K14: =K$9*K10 | L14: =L$9*L10 | M14: =M$9*M10 | N14: =N$9*N10 | O14: =O$9*O10 | P14: =P$9*P10
F15: 主投 | G15: 到课数 | H15: 281 | I15: =I$9*I11 | J15: =J$9*J11 | K15: =K$9*K11 | L15: =L$9*L11 | M15: =M$9*M11 | N15: =N$9*N11 | O15: =O$9*O11 | P15: =P$9*P11
F16: 主投 | G16: 转化数 | H16: 43 | I16: =I$9*I12 | J16: =J$9*J12 | K16: =K$9*K12 | L16: =L$9*L12 | M16: =M$9*M12 | N16: =N$9*N12 | O16: =O$9*O12 | P16: =P$9*P12
F17: 主投 | G17: GMV | H17: 181744 | I17: =I13*I16 | J17: =J13*J16 | K17: =K13*K16 | L17: =L13*L16 | M17: =M13*M16 | N17: =N13*N16 | O17: =O13*O16 | P17: =P13*P16
F18: 主投 | G18: ROI 2成本项 | H18: =SUM(H19:H23)+H7 | I18: =SUM(I19:I23)+I7 | J18: =SUM(J19:J23)+J7 | K18: =SUM(K19:K23)+K7 | L18: =SUM(L19:L23)+L7 | M18: =SUM(M19:M23)+M7 | N18: =SUM(N19:N23)+N7 | O18: =SUM(O19:O23)+O7 | P18: =SUM(P19:P23)+P7
F19: 主投 | G19: 销售固定成本 | H19: =H14*$C$4 | I19: =I14*$C$4 | J19: =J14*$C$4 | K19: =K14*$C$4 | L19: =L14*$C$4 | M19: =M14*$C$4 | N19: =N14*$C$4 | O19: =O14*$C$4 | P19: =P14*$C$4
F20: 主投 | G20: 销售变动成本 | H20: =H17*($C$6+$C$7) | I20: =I17*($C$6+$C$7) | J20: =J17*($C$6+$C$7) | K20: =K17*($C$6+$C$7) | L20: =L17*($C$6+$C$7) | M20: =M17*($C$6+$C$7) | N20: =N17*($C$6+$C$7) | O20: =O17*($C$6+$C$7) | P20: =P17*($C$6+$C$7)
F21: 主投 | G21: TMK费用 | H21: =H9*$C$5 | I21: =I9*$C$5 | J21: =J9*$C$5 | K21: =K9*$C$5 | L21: =L9*$C$5 | M21: =M9*$C$5 | N21: =N9*$C$5 | O21: =O9*$C$5 | P21: =P9*$C$5
F22: 主投 | G22: DEMO费用 | H22: =H14*$C$8 | I22: =I15*$C$8 | J22: =J15*$C$8 | K22: =K15*$C$8 | L22: =L15*$C$8 | M22: =M15*$C$8 | N22: =N15*$C$8 | O22: =O15*$C$8 | P22: =P15*$C$8
F23: 主投 | G23: 运营人工成本 | H23: =H9*$C$9/2 | I23: =I9*$C$9/2 | J23: =J9*$C$9/2 | K23: =K9*$C$9/2 | L23: =L9*$C$9/2 | M23: =M9*$C$9/2 | N23: =N9*$C$9/2 | O23: =O9*$C$9/2 | P23: =P9*$C$9/2
F24: 主投 | G24: ROI 2 | H24: =H17/H18 | I24: =I17/I18 | J24: =J17/J18 | K24: =K17/K18 | L24: =L17/L18 | M24: =M17/M18 | N24: =N17/N18 | O24: =O17/O18 | P24: =P17/P18
F26: 辅投 | G26: 联投率 | H26: =H27/H9 | I26: 0.85 | J26: 0.85 | K26: 0.85 | L26: 0.85
F27: 辅投 | G27: 例子数 | H27: 419 | I27: =I9*I26 | J27: =J9*J26 | K27: =K9*K26 | L27: =L9*L26
F28: 辅投 | G28: 例子分发率 | H28: =H32/H27 | I28: 0.39 | J28: 0.5 | K28: 0.5 | L28: 0.47
F29: 辅投 | G29: 例子到课率 | H29: =H33/H27 | I29: 0.28 | J29: 0.29 | K29: 0.44 | L29: 0.34
F30: 辅投 | G30: 滚动转化率 | H30: =H34/H27 | I30: =H30 | J30: 0.043 | K30: 0.032 | L30: 0.016
F31: 辅投 | G31: ASP | H31: =H35/H34 | I31: 3045 | J31: 2837 | K31: 3588 | L31: 4568
F32: 辅投 | G32: 分发数 | H32: 418 | I32: =I$27*I28 | J32: =J$27*J28 | K32: =K$27*K28 | L32: =L$27*L28 | M32: =M$27*M28 | N32: =N$27*N28 | O32: =O$27*O28 | P32: =P$27*P28
F33: 辅投 | G33: 到课数 | H33: 161 | I33: =I$27*I29 | J33: =J$27*J29 | K33: =K$27*K29 | L33: =L$27*L29 | M33: =M$27*M29 | N33: =N$27*N29 | O33: =O$27*O29 | P33: =P$27*P29
F34: 辅投 | G34: 转化数 | H34: 12 | I34: =I$27*I30 | J34: =J$27*J30 | K34: =K$27*K30 | L34: =L$27*L30 | M34: =M$27*M30 | N34: =N$27*N30 | O34: =O$27*O30 | P34: =P$27*P30
F35: 辅投 | G35: GMV | H35: 37457 | I35: =I31*I34 | J35: =J31*J34 | K35: =K31*K34 | L35: =L31*L34 | M35: =M31*M34 | N35: =N31*N34 | O35: =O31*O34 | P35: =P31*P34
F36: 辅投 | G36: ROI 2成本项 | H36: =SUM(H37:H41) | I36: =SUM(I37:I41) | J36: =SUM(J37:J41) | K36: =SUM(K37:K41) | L36: =SUM(L37:L41) | M36: =SUM(M37:M41) | N36: =SUM(N37:N41) | O36: =SUM(O37:O41) | P36: =SUM(P37:P41)
F37: 辅投 | G37: 销售固定成本 | H37: =H32*$D$4 | I37: =I32*$D$4 | J37: =J32*$D$4 | K37: =K32*$D$4 | L37: =L32*$D$4 | M37: =M32*$D$4 | N37: =N32*$D$4 | O37: =O32*$D$4 | P37: =P32*$D$4
F38: 辅投 | G38: 销售变动成本 | H38: =H35*($D$6+$D$7) | I38: =I35*($D$6+$D$7) | J38: =J35*($D$6+$D$7) | K38: =K35*($D$6+$D$7) | L38: =L35*($D$6+$D$7) | M38: =M35*($D$6+$D$7) | N38: =N35*($D$6+$D$7) | O38: =O35*($D$6+$D$7) | P38: =P35*($D$6+$D$7)
F39: 辅投 | G39: TMK费用 | H39: =H27*$D$5 | I39: =I27*$D$5 | J39: =J27*$D$5 | K39: =K27*$D$5 | L39: =L27*$D$5 | M39: =M27*$D$5 | N39: =N27*$D$5 | O39: =O27*$D$5 | P39: =P27*$D$5
F40: 辅投 | G40: DEMO费用 | H40: =H32*$D$8 | I40: =I33*$D$8 | J40: =J33*$D$8 | K40: =K33*$D$8 | L40: =L33*$D$8 | M40: =M33*$D$8 | N40: =N33*$D$8 | O40: =O33*$D$8 | P40: =P33*$D$8
F41: 辅投 | G41: 运营人工成本 | H41: =H27*$D$9/2 | I41: =I27*$D$9/2 | J41: =J27*$D$9/2 | K41: =K27*$D$9/2 | L41: =L27*$D$9/2 | M41: =M27*$D$9/2 | N41: =N27*$D$9/2 | O41: =O27*$D$9/2 | P41: =P27*$D$9/2
F42: 辅投 | G42: ROI 2 | H42: =H35/H36 | I42: =I35/I36 | J42: =J35/J36 | K42: =K35/K36 | L42: =L35/L36 | M42: =M35/M36 | N42: =N35/N36 | O42: =O35/O36 | P42: =P35/P36

Sheet BB展ROI测算数据 (2)
F2: 主投思维
B3: 参数：8月初 | C3: 益智 | D3: 美术 | H3: 4月澳門展
B4: 单例子销售固定人工成本 | C4: 89.09 | D4: 83.45 | F4: 链路合计 | G4: ROI 2 | H4: =H5/H6
B5: 单例子TMK人工成本 | C5: 8.99 | D5: 8.99 | F5: 链路合计 | G5: GMV | H5: =H19+H37
B6: 销售提成比例 | C6: 0.0894 | D6: 0.0839 | F6: 链路合计 | G6: ROI 2成本项 | H6: =H38+H20
B7: 礼品及其他费用比例 | C7: 0.0132 | D7: 0.0155 | F7: 链路合计 | G7: 渠道预算 | H7: 21696.9
B8: 试听课单课时成本 | C8: 83.03 | D8: 74.31 | F8: 入場人數 | H8: 300000
B9: 单例子市场运营人工及日常成本 | C9: 100 | D9: 100 | F9: 主投 | G9: 例子数 | H9: 110
F10: 主投 | G10: 例子分发率 | H10: =H15/H9
F11: 主投 | G11: 例子约课率 | H11: 0.75
F12: 主投 | G12: 例子到课率 | H12: =H17/H9
F13: 主投 | G13: 滚动转化率 | H13: =H18/H9
F14: 主投 | G14: ASP | H14: =H19/H18
F15: 主投 | G15: 分发数 | H15: 110
F16: 主投 | G16: 约课数 | H16: =H9*H11
F17: 主投 | G17: 到课数 | H17: =H16*0.8
F18: 主投 | G18: 转化数 | H18: =H9*10%
F19: 主投 | G19: GMV | H19: =H18*4500
F20: 主投 | G20: ROI 2成本项 | H20: =SUM(H21:H25)+H7
F21: 主投 | G21: 销售固定成本 | H21: =H15*$C$4
F22: 主投 | G22: 销售变动成本 | H22: =H19*($C$6+$C$7)
F23: 主投 | G23: TMK费用 | H23: =H9*$C$5
F24: 主投 | G24: DEMO费用 | H24: =H15*$C$8
F25: 主投 | G25: 运营人工成本 | H25: =H9*$C$9/2
F26: 主投 | G26: ROI 2 | H26: =H19/H20

Sheet 回本预测
A1: 当前消耗月份数 | B1: KOL | C1: 目前总cpt+投放消耗 | D1: 剩余cpt | E1: 全额CPT+投放消耗 | F1: 投放消耗 | G1: 其他截至目前成本 | H1: 全额CPT+投放消耗总成本 | I1: 投放消耗+其他成本 | J1: 总GMV | K1: ROI2 | L1: ROI2 | M1: ROI1 | N1: 成本Gap | O1: CPT成本/天 | P1: 历史单例子成本 | Q1: 单例子成本/个 | R1: 历史约课率 | S1: 约课率预设 | T1: 历史出席率 | U1: 出席率预设 | V1: 历史滚转 | W1: 滚转预设 | X1: 历史ASP | Y1: ASP预设 | Z1: 单例子链路成本 | AA1: 历史ROI2 | AB1: 目标ROI2 | AC1: 最低ROI2 | AD1: 单例子利润 | AE1: 例子缺口
K2: （全额CPT+投放消耗+其他成本） | L2: （投放消耗+其他成本） | M2: （仅投放消耗）
A3: 92天 | B3: 陈琪-汇总 | C3: 821009 | D3: 8184 | E3: 829193 | F3: 761853 | G3: 463124 | H3: 1292317 | I3: 1224977 | J3: 1447546 | K3: 1.12 | L3: 1.18 | M3: 1.9
A4: 90天 | B4: 孙慧雪-汇总 | C4: 430793 | D4: 0 | E4: 430793 | F4: 365693 | G4: 168630 | H4: 599423 | I4: 534323 | J4: 550196 | K4: 0.92 | L4: 1.03 | M4: 1.5
B5: 陈倩扬-汇总 | C5: 215431 | D5: 0 | E5: 215431 | F5: 170791 | G5: 90137 | H5: 305568 | I5: 260928 | J5: 292684 | K5: 0.96 | L5: 1.12 | M5: 1.71
A6: 90天 | B6: Bob-汇总 | C6: 363482 | D6: 0 | E6: 363482 | F6: 293732 | G6: 140020 | H6: 503503 | I6: 433753 | J6: 442780 | K6: 0.88 | L6: 1.02 | M6: 1.51
A7: 110天 | B7: 陈山聪-汇总 | C7: 372628 | D7: 4883 | E7: 377510 | F7: 318920 | G7: 128442 | H7: 505952 | I7: 447362 | J7: 417480 | K7: 0.83 | L7: 0.93 | M7: 1.31
A8: 90天 | B8: 陈敏之-汇总 | C8: 385930 | D8: 0 | E8: 385930 | F8: 318040 | G8: 138038 | H8: 523968 | I8: 456078 | J8: 449736 | K8: 0.86 | L8: 0.99 | M8: 1.41
A9: 90天 | B9: 林子善-汇总 | C9: 228248 | D9: 0 | E9: 228248 | F9: 186398 | G9: 70148 | H9: 298396 | I9: 256546 | J9: 197777 | K9: 0.66 | L9: 0.77 | M9: 1.06 | N9: =(J9-H9)*AC9 | O9: =(E9-F9)/90 | P9: 741 | Q9: 700 | R9: 0.474 | S9: 0.5 | T9: 0.367 | U9: 0.38 | V9: 0.1364 | W9: 0.18 | X9: 4709 | Y9: 5000 | Z9: 535 | AA9: 0.65 | AB9: 1.04 | AC9: 0.8 | AD9: =W9*Y9*(AB9-AC9) | AE9: =N9/AD9
A10: 80天 | B10: mamidaily-汇总 | C10: 117328 | D10: 6148 | E10: 123476 | F10: 68141 | G10: 22947 | H10: 146422 | I10: 91087 | J10: 79620 | K10: 0.54 | L10: 0.87 | M10: 1.17 | N10: =(J10-H10)*AC10 | O10: =(E10-F10)/90 | P10: 1333 | Q10: 700 | R10: 0.568 | S10: 0.55 | T10: 0.488 | U10: 0.45 | V10: 0.1705 | W10: 0.2 | X10: 5308 | Y10: 5000 | Z10: 632 | AA10: 0.56 | AB10: 1.06 | AC10: 0.8 | AD10: =W10*Y10*(AB10-AC10) | AE10: =N10/AD10
A11: 62天 | B11: 吴若希-汇总 | C11: 107349 | D11: 19675 | E11: 127023 | F11: 63783 | G11: 16145 | H11: 143168 | I11: 79928 | J11: 30116 | K11: 0.21 | L11: 0.38 | M11: 0.47 | N11: =(J11-H11)*AC11 | O11: =(E11-F11)/90 | P11: 1278 | Q11: 700 | R11: 0.4643 | S11: 0.5 | T11: 0.369 | U11: 0.38 | V11: 0.0833 | W11: 0.15 | X11: 4302 | Y11: 4500 | Z11: 535 | AA11: 0.24 | AB11: 0.65 | AC11: 0.8 | AD11: =W11*Y11*(AB11-AC11) | AE11: 无限，回不了
A12: 40天 | B12: 张美妮-汇总 | C12: 35855 | D12: 13950 | E12: 49805 | F12: 24695 | G12: 5368 | H12: 55173 | I12: 30063 | J12: 3588 | K12: 0.07 | L12: 0.12 | M12: 0.15 | N12: =(J12-H12)*AC12 | O12: =(E12-F12)/90 | P12: 1019 | Q12: 700 | R12: 0.3143 | S12: 0.45 | T12: 0.379 | U12: 0.38 | V12: 0.0286 | W12: 0.15 | X12: 3588 | Y12: 4500 | Z12: 632 | AA12: 0.22 | AB12: 0.76 | AC12: 0.8 | AD12: =W12*Y12*(AB12-AC12) | AE12: 无限，回不了
A13: 31天 | B13: 钟嘉欣-汇总 | C13: 193227 | D13: 341000 | E13: 534227 | F13: 162227 | G13: 79003 | H13: 613230 | I13: 241230 | J13: 168804 | K13: 0.28 | L13: 0.70 | M13: 1.04
A14: 10天 | B14: 蔡雪莹-汇总 | C14: 12336 | D14: 23147 | E14: 35482 | F14: 9442 | G14: 5909 | H14: 41391 | I14: 15351 | J14: 0 | K14: 0 | L14: 0.00 | M14: 0
B15: 汇总 | C15: 3413150 | D15: 416986 | E15: 3830136 | F15: 2822101 | G15: 1353477 | H15: 5183613 | I15: 4175578 | J15: 4136648 | K15: 0.8 | L15: 0.99 | M15: 1.47
P16: 本月分摊 | AF16: 定标
A17: 180天 | B17: 陈琪（直播） | D17: =70000*0.93 | N17: =0-D17 | P17: =N17*0.5 | Q17: 600 | S17: 0.5 | U17: 0.38 | W17: 0.18 | Y17: 5000 | AB17: 0.97 | AC17: 0.8 | AD17: =W17*Y17*(AB17-AC17) | AE17: =P17/AD17 | AF17: 240
A18: 90天 | B18: 陈展鹏 | D18: =100000*0.93 | N18: =0-D18 | P18: =N18*0.5*0.5 | Q18: 600 | S18: 0.5 | U18: 0.38 | W18: 0.18 | Y18: 5000 | AB18: 0.98 | AC18: 0.8 | AD18: =W18*Y18*(AB18-AC18) | AE18: =P18/AD18 | AF18: 170
A19: 90天 | B19: 鄧明儀 | D19: =18000*0.93 | N19: =0-D19 | P19: =N19*0.5*0.5 | Q19: 600 | S19: 0.5 | U19: 0.38 | W19: 0.18 | Y19: 5000 | AB19: 0.98 | AC19: 0.8 | AD19: =W19*Y19*(AB19-AC19) | AE19: =P19/AD19 | AF19: 35
A20: 90天 | B20: 陳凱琳 | D20: =200000*0.93 | N20: =0-D20 | P20: =N20*0.5*0.5 | Q20: 600 | S20: 0.5 | U20: 0.38 | W20: 0.18 | Y20: 5000 | AB20: 0.98 | AC20: 0.8 | AD20: =W20*Y20*(AB20-AC20) | AE20: =P20/AD20 | AF20: 300

Sheet 历史KOL数据
J1: 主投 | AP1: 辅投 | BR1: 汇总
B2: 渠道组 | C2: 供应商 | D2: 渠道名称 | E2: 主投 | F2: 辅投 | G2: 结算方式 | H2: 当月CPT金额 | I2: 滚动消耗 | J2: 滚动消耗(不含赠课成本) | K2: 单例子成本 | L2: 例子数 | M2: 分发数 | N2: 剔除毛例子 分发数 | O2: 约课数 | P2: 到课数 | Q2: 滚动到课数 | R2: 当月成交数 | S2: 滚动成交数 | T2: 当月GMV | U2: 滚动GMV | V2: 海外GMV占比 | W2: 滚动ASP | X2: 例子分发率 | Y2: 分发约课率 | Z2: 例子约课率 | AA2: 约课到课率 | AB2: 滚动应到课率 | AC2: 到课转化率 | AD2: 注册转化率 | AE2: 滚动转化率 | AF2: 滚动ROI2总成本 | AG2: 滚动ROI2 | AH2: 滚动应到课人数 | AI2: 滚动到课人数 | AJ2: 滚动到课人次 | AK2: 运营成本 | AL2: 销售固定成本 | AM2: 销售变动成本 | AN2: TMK费用 | AO2: DEMO费用 | AP2: 例子数 | AQ2: 分发数 | AR2: 剔除毛例子分发数 | AS2: 约课数 | AT2: 到课数 | AU2: 滚动到课数 | AV2: 当月成交 | AW2: 滚动成交数 | AX2: 当月GMV | AY2: 滚动GMV | AZ2: 海外GMV占比 | BA2: 滚动ASP | BB2: 例子分发率 | BC2: 分发约课率 | BD2: 例子约课率 | BE2: 约课到课率 | BF2: 滚动应到课率 | BG2: 到课转化率 | BH2: 注册转化率 | BI2: 滚动转化率 | BJ2: 滚动应到课人数 | BK2: 滚动到课人数 | BL2: 滚动到课人次 | BM2: 运营成本 | BN2: 销售固定成本 | BO2: 销售变动成本 | BP2: TMK费用 | BQ2: DEMO费用 | BR2: 当月GMV | BS2: 滚动GMV | BT2: 海外GMV占比 | BU2: 滚动其他成本 | BV2: 同源其他成本 | BW2: 运营成本 | BX2: 滚动消耗 | BY2: 同源消耗 | BZ2: 当月ROI2总成本 | CA2: 当月ROI2 | CB2: 滚动赠课成本 | CC2: 滚动ROI2总成本 | CD2: 滚动ROI2 | CE2: O-ROI总成本 | CF2: O-ROI
A3: 2024年-12月陈琪 | C3: 陈琪 | D3: KOLHK-香港-陈琪-Shukei-思维&美术 | E3: 思维 | F3: 美术 | G3: CPT | I3: 33739 | J3: 33739 | K3: 177 | L3: 191 | M3: 138 | N3: 139 | O3: 91 | P3: 63 | Q3: 63 | R3: 15 | S3: 15 | T3: 59520 | U3: 59520 | V3: 1 | W3: 3968 | X3: 0.723 | Y3: 0.659 | Z3: 0.476 | AA3: 0.692 | AB3: 0.955 | AC3: 0.238 | AD3: 0.079 | AE3: 0.079 | AF3: 50678 | AG3: 1.17 | AH3: 66 | AI3: 63 | AJ3: 69 | AK3: 11247 | AL3: 16717 | AM3: 6655 | AN3: 1781 | AO3: 5844 | AP3: 190 | AQ3: 26 | AR3: 26 | AS3: 31 | AT3: 23 | AU3: 23 | AV3: 3 | AW3: 3 | AX3: 12498 | AY3: 12498 | AZ3: 1 | BA3: 4166 | BB3: 0.137 | BC3: 1.192 | BD3: 0.163 | BE3: 0.742 | BF3: 0.767 | BG3: 0.13 | BH3: 0.016 | BI3: 0.016 | BJ3: 30 | BK3: 23 | BL3: 23 | BM3: 8938 | BN3: 4012 | BO3: 1313 | BP3: 1853 | BQ3: 1980 | BR3: 72018 | BS3: 72018 | BT3: 1 | BU3: 40155 | BV3: 40035 | BW3: 20185 | BX3: 33739 | BY3: 33739 | BZ3: 93959 | CA3: 0.77 | CC3: 94080 | CD3: 0.77 | CE3: 77472 | CF3: 0.93
A4: 2025年-1月陈琪 | C4: 陈琪 | D4: KOLHK-香港-陈琪-Shukei-思维&美术 | E4: 思维 | F4: 美术 | G4: CPT | I4: 40592 | J4: 40592 | K4: 344 | L4: 118 | M4: 45 | N4: 48 | O4: 48 | P4: 40 | Q4: 51 | R4: 14 | S4: 15 | T4: 69532 | U4: 73220 | V4: 1 | W4: 4881 | X4: 0.381 | Y4: 1.067 | Z4: 0.407 | AA4: 0.833 | AB4: 0.962 | AC4: 0.35 | AD4: 0.119 | AE4: 0.127 | AF4: 73894 | AG4: 0.99 | AH4: 53 | AI4: 51 | AJ4: 57 | AK4: 14458 | AL4: 6862 | AM4: 6046 | AN4: 1311 | AO4: 4627 | AP4: 118 | AQ4: 30 | AR4: 36 | AS4: 29 | AT4: 17 | AU4: 19 | AV4: 2 | AW4: 2 | AX4: 6529 | AY4: 6529 | AZ4: 1 | BA4: 3265 | BB4: 0.254 | BC4: 0.967 | BD4: 0.246 | BE4: 0.586 | BF4: 0.559 | BG4: 0.118 | BH4: 0.017 | BI4: 0.017 | BJ4: 34 | BK4: 19 | BL4: 20 | BM4: 13720 | BN4: 3869 | BO4: 610 | BP4: 1311 | BQ4: 1631 | BR4: 76061 | BS4: 79749 | BT4: 1 | BU4: 26266 | BV4: 23751 | BW4: 28178 | BX4: 40592 | BY4: 40592 | BZ4: 92520 | CA4: 0.82 | CC4: 95035 | CD4: 0.84 | CE4: 84558 | CF4: 0.94
A5: 2025年-2月陈琪 | C5: 陈琪 | D5: KOLHK-香港-陈琪-Shukei-思维&美术 | E5: 思维 | F5: 美术 | G5: CPT | I5: 48635 | J5: 48635 | K5: 269 | L5: 181 | M5: 85 | N5: 86 | O5: 90 | P5: 64 | Q5: 72 | R5: 23 | S5: 27 | T5: 118186 | U5: 138838 | V5: 1 | W5: 5142 | X5: 0.47 | Y5: 1.059 | Z5: 0.497 | AA5: 0.711 | AB5: 0.947 | AC5: 0.359 | AD5: 0.127 | AE5: 0.149 | AF5: 93017 | AG5: 1.49 | AH5: 76 | AI5: 72 | AJ5: 78 | AK5: 12472 | AL5: 11124 | AM5: 12886 | AN5: 1250 | AO5: 6649 | AP5: 164 | AQ5: 46 | AR5: 49 | AS5: 52 | AT5: 21 | AU5: 24 | AV5: 2 | AW5: 2 | AX5: 7176 | AY5: 7176 | AZ5: 1 | BA5: 3588 | BB5: 0.28 | BC5: 1.13 | BD5: 0.317 | BE5: 0.404 | BF5: 0.453 | BG5: 0.095 | BH5: 0.012 | BI5: 0.012 | BJ5: 53 | BK5: 24 | BL5: 25 | BM5: 10654 | BN5: 4401 | BO5: 691 | BP5: 1198 | BQ5: 1847 | BR5: 125362 | BS5: 146014 | BT5: 1 | BU5: 40047 | BV5: 36743 | BW5: 23126 | BX5: 48635 | BY5: 48635 | BZ5: 108503 | CA5: 1.16 | CC5: 111808 | CD5: 1.31 | CE5: 114557 | CF5: 1.27
A6: 2025年-3月陈琪 | C6: 陈琪 | D6: KOLHK-香港-陈琪-Shukei-思维&美术 | E6: 思维 | F6: 美术 | G6: CPT | I6: 113250 | J6: 113250 | K6: 380 | L6: 298 | M6: 142 | N6: 146 | O6: 152 | P6: 117 | Q6: 132 | R6: 47 | S6: 55 | T6: 243836 | U6: 275640 | V6: 1 | W6: 5012 | X6: 0.477 | Y6: 1.07 | Z6: 0.51 | AA6: 0.77 | AB6: 0.95 | AC6: 0.402 | AD6: 0.158 | AE6: 0.185 | AF6: 193915 | AG6: 1.42 | AH6: 139 | AI6: 132 | AJ6: 138 | AK6: 26636 | AL6: 14433 | AM6: 26387 | AN6: 2005 | AO6: 11202 | AP6: 18 | AQ6: 17 | AR6: 25 | AS6: 17 | AT6: 10 | AU6: 13 | AV6: 2 | AW6: 2 | AX6: 7735 | AY6: 7735 | AZ6: 1 | BA6: 3868 | BB6: 0.944 | BC6: 1 | BD6: 0.944 | BE6: 0.588 | BF6: 0.542 | BG6: 0.2 | BH6: 0.111 | BI6: 0.111 | BJ6: 24 | BK6: 13 | BL6: 14 | BM6: 1471 | BN6: 2100 | BO6: 760 | BP6: 121 | BQ6: 1142 | BR6: 251571 | BS6: 283375 | BT6: 1 | BU6: 58151 | BV6: 52577 | BW6: 28107 | BX6: 113250 | BY6: 113250 | BZ6: 193935 | CA6: 1.3 | CC6: 199509 | CD6: 1.42 | CE6: 195102 | CF6: 1.45
A7: 2025年-4月陈琪 | C7: 陈琪 | D7: KOLHK-香港-陈琪-Shukei-思维&美术 | E7: 思维 | F7: 美术 | G7: CPT | I7: 131732 | J7: 131732 | K7: 540 | L7: 244 | M7: 122 | N7: 128 | O7: 127 | P7: 100 | Q7: 124 | R7: 41 | S7: 48 | T7: 180708 | U7: 211424 | V7: 1 | W7: 4405 | X7: 0.5 | Y7: 1.041 | Z7: 0.52 | AA7: 0.787 | AB7: 0.984 | AC7: 0.41 | AD7: 0.168 | AE7: 0.197 | AF7: 210353 | AG7: 1.01 | AH7: 126 | AI7: 124 | AJ7: 134 | AK7: 27025 | AL7: 18959 | AM7: 18955 | AN7: 2412 | AO7: 11270 | AP7: 20 | AQ7: 18 | AR7: 20 | AS7: 18 | AT7: 11 | AU7: 13 | AV7: 0 | AW7: 0 | AX7: 0 | AY7: 0 | BB7: 0.9 | BC7: 1 | BD7: 0.9 | BE7: 0.611 | BF7: 0.65 | BG7: 0 | BH7: 0 | BI7: 0 | BJ7: 20 | BK7: 13 | BL7: 14 | BM7: 2093 | BN7: 2050 | BO7: 0 | BP7: 198 | BQ7: 1114 | BR7: 180708 | BS7: 211424 | BT7: 1 | BU7: 54958 | BV7: 48849 | BW7: 29118 | BX7: 131732 | BY7: 131732 | BZ7: 209699 | CA7: 0.86 | CC7: 215808 | CD7: 0.98 | CE7: 206490 | CF7: 1.02
A8: 2025年-5月陈琪 | I8: 163228 | J8: 163228 | K8: 633 | L8: 258 | M8: 119 | N8: 124 | O8: 116 | P8: 84 | Q8: 106 | R8: 34 | S8: 45 | T8: 171724 | U8: 222292 | V8: 1 | W8: 4940 | X8: 0.461 | Y8: 0.975 | Z8: 0.45 | AA8: 0.724 | AB8: 0.955 | AC8: 0.405 | AD8: 0.132 | AE8: 0.174 | AF8: 226867 | AG8: 0.98 | AH8: 111 | AI8: 106 | AJ8: 116 | AK8: 14628 | AL8: 15218 | AM8: 21318 | AN8: 2399 | AO8: 10076 | AP8: 6 | AQ8: 5 | AR8: 6 | AS8: 5 | AT8: 3 | AU8: 6 | AV8: 0 | AW8: 0 | AX8: 0 | AY8: 0 | BB8: 0.833 | BC8: 1 | BD8: 0.833 | BE8: 0.6 | BF8: 0.75 | BG8: 0 | BH8: 0 | BI8: 0 | BJ8: 8 | BK8: 6 | BL8: 6 | BM8: 281 | BN8: 656 | BO8: 0 | BP8: 56 | BQ8: 466 | BR8: 171724 | BS8: 222292 | BT8: 1 | BU8: 50189 | BV8: 42212 | BW8: 14909 | BX8: 163228 | BY8: 163228 | BZ8: 220349 | CA8: 0.78 | CC8: 228326 | CD8: 0.97 | CE8: 233217 | CF8: 0.95
A9: 2025年-6月陈琪 | I9: 154847 | J9: 145314 | K9: 759 | L9: 204 | M9: 114 | N9: 124 | O9: 116 | P9: 96 | Q9: 130 | R9: 43 | S9: 53 | T9: 209284 | U9: 255664 | V9: 1 | W9: 4824 | X9: 0.559 | Y9: 1.018 | Z9: 0.569 | AA9: 0.828 | AB9: 0.929 | AC9: 0.448 | AD9: 0.211 | AE9: 0.26 | AF9: 220689 | AG9: 1.16 | AH9: 140 | AI9: 130 | AJ9: 150 | AK9: 12724 | AL9: 13936 | AM9: 24680 | AN9: 1647 | AO9: 12953 | AP9: 99 | AQ9: 30 | AR9: 30 | AS9: 29 | AT9: 17 | AU9: 20 | AV9: 1 | AW9: 1 | AX9: 3588 | AY9: 3588 | AZ9: 1 | BA9: 3588 | BB9: 0.303 | BC9: 0.967 | BD9: 0.293 | BE9: 0.586 | BF9: 0.625 | BG9: 0.059 | BH9: 0.01 | BI9: 0.01 | BJ9: 32 | BK9: 20 | BL9: 20 | BM9: 5542 | BN9: 2699 | BO9: 373 | BP9: 800 | BQ9: 1579 | BR9: 212872 | BS9: 259252 | BT9: 1 | BU9: 58844 | BV9: 48947 | BW9: 18322 | BX9: 154847 | BY9: 153067 | BZ9: 220336 | CA9: 0.97 | CB9: 9533 | CC9: 232013 | CD9: 1.12 | CE9: 236491 | CF9: 1.1
A10: 2025年-7月陈琪 | I10: 120482 | J10: 114209 | K10: 813 | L10: 148 | M10: 62 | N10: 69 | O10: 64 | P10: 52 | Q10: 77 | R10: 24 | S10: 35 | T10: 121912 | U10: 163880 | V10: 1 | W10: 4682 | X10: 0.419 | Y10: 1.032 | Z10: 0.432 | AA10: 0.813 | AB10: 0.963 | AC10: 0.462 | AD10: 0.162 | AE10: 0.236 | AF10: 160110 | AG10: 1.02 | AH10: 80 | AI10: 77 | AJ10: 87 | AK10: 6513 | AL10: 7240 | AM10: 16781 | AN10: 1523 | AO10: 7668 | AP10: 4 | AQ10: 3 | AR10: 4 | AS10: 4 | AT10: 2 | AU10: 2 | AV10: 0 | AW10: 1 | AX10: 0 | AY10: 1880 | AZ10: 1 | BA10: 1880 | BB10: 0.75 | BC10: 1.333 | BD10: 1 | BE10: 0.5 | BF10: 0.5 | BG10: 0 | BH10: 0 | BI10: 0.25 | BJ10: 4 | BK10: 2 | BL10: 2 | BM10: 0 | BN10: 379 | BO10: 197 | BP10: 41 | BQ10: 164 | BR10: 121912 | BS10: 165760 | BT10: 1 | BU10: 33996 | BV10: 26115 | BW10: 6513 | BX10: 120482 | BY10: 118443 | BZ10: 151071 | CA10: 0.81 | CB10: 6273 | CC10: 160991 | CD10: 1.03 | CE10: 165878 | CF10: 1
A11: 2025年-8月陈琪 | I11: 38341 | J11: 35866 | K11: 834 | L11: 46 | M11: 21 | N11: 25 | O11: 21 | P11: 16 | Q11: 36 | R11: 6 | S11: 14 | T11: 24028 | U11: 57832 | V11: 1 | W11: 4131 | X11: 0.457 | Y11: 1 | Z11: 0.457 | AA11: 0.762 | AB11: 1 | AC11: 0.375 | AD11: 0.13 | AE11: 0.304 | AF11: 55313 | AG11: 1.05 | AH11: 36 | AI11: 36 | AJ11: 38 | AK11: 4153 | AL11: 3088 | AM11: 5922 | AN11: 460 | AO11: 3349 | AP11: 0 | AQ11: 0 | AR11: 0 | AS11: 0 | AT11: 0 | AU11: 0 | AV11: 0 | AW11: 0 | AX11: 0 | AY11: 0 | BJ11: 0 | BK11: 0 | BL11: 0 | BM11: 0 | BN11: 0 | BO11: 0 | BP11: 0 | BQ11: 0 | BR11: 24028 | BS11: 57832 | BT11: 1 | BU11: 12819 | BV11: 7101 | BW11: 4153 | BX11: 38341 | BY11: 36927 | BZ11: 48180 | CA11: 0.5 | CB11: 2475 | CC11: 55313 | CD11: 1.05 | CE11: 54610 | CF11: 1.06
A12: 2025年-9月陈琪 | H12: 651 | I12: 23292 | J12: 22220 | K12: 597 | L12: 39 | M12: 18 | N12: 20 | O12: 19 | P12: 11 | Q12: 21 | R12: 3 | S12: 6 | T12: 11564 | U12: 22328 | V12: 1 | W12: 3721 | X12: 0.462 | Y12: 1.056 | Z12: 0.487 | AA12: 0.579 | AB12: 1 | AC12: 0.273 | AD12: 0.077 | AE12: 0.154 | AF12: 33904 | AG12: 0.66 | AH12: 21 | AI12: 21 | AJ12: 22 | AK12: 2955 | AL12: 2892 | AM12: 2507 | AN12: 390 | AO12: 1868 | AP12: 0 | AQ12: 0 | AR12: 1 | AS12: 0 | AT12: 0 | AU12: 0 | AV12: 0 | AW12: 0 | AX12: 0 | AY12: 0 | BJ12: 0 | BK12: 0 | BL12: 0 | BM12: 0 | BN12: 95 | BO12: 0 | BP12: 0 | BQ12: 0 | BR12: 11564 | BS12: 22328 | BT12: 1 | BU12: 7752 | BV12: 5225 | BW12: 2955 | BX12: 23292 | BY12: 22756 | BZ12: 30936 | CA12: 0.37 | CB12: 1072 | CC12: 33999 | CD12: 0.66 | CE12: 33969 | CF12: 0.66
A13: 2025年-10月陈琪 | H13: 651 | I13: 17360 | J13: 16109 | K13: 620 | L13: 28 | M13: 11 | N13: 12 | O13: 10 | P13: 9 | Q13: 12 | R13: 3 | S13: 7 | T13: 16464 | U13: 38447 | V13: 1 | W13: 5492 | X13: 0.393 | Y13: 0.909 | Z13: 0.357 | AA13: 0.9 | AB13: 1 | AC13: 0.333 | AD13: 0.107 | AE13: 0.25 | AF13: 26597 | AG13: 1.45 | AH13: 12 | AI13: 12 | AJ13: 15 | AK13: 1750 | AL13: 1707 | AM13: 4229 | AN13: 280 | AO13: 1271 | AP13: 0 | AQ13: 0 | AR13: 0 | AS13: 0 | AT13: 0 | AU13: 0 | AV13: 0 | AW13: 0 | AX13: 0 | AY13: 0 | BJ13: 0 | BK13: 0 | BL13: 0 | BM13: 0 | BN13: 0 | BO13: 0 | BP13: 0 | BQ13: 0 | BR13: 16464 | BS13: 38447 | BT13: 1 | BU13: 7488 | BV13: 4503 | BW13: 1750 | BX13: 17360 | BY13: 16645 | BZ13: 22898 | CA13: 0.72 | CB13: 1250 | CC13: 26597 | CD13: 1.45 | CE13: 26947 | CF13: 1.43
A14: 2025年-11月陈琪 | I14: 15316 | J14: 14780 | K14: 729 | L14: 21 | M14: 8 | N14: 9 | O14: 8 | P14: 6 | Q14: 8 | R14: 2 | S14: 3 | T14: 11318 | U14: 14817 | V14: 1 | W14: 4939 | X14: 0.381 | Y14: 1 | Z14: 0.381 | AA14: 0.75 | AB14: 1 | AC14: 0.333 | AD14: 0.095 | AE14: 0.143 | AF14: 20264 | AG14: 0.73 | AH14: 8 | AI14: 8 | AJ14: 8 | AK14: 1367 | AL14: 1063 | AM14: 1630 | AN14: 210 | AO14: 678 | AP14: 0 | AQ14: 0 | AR14: 0 | AS14: 0 | AT14: 0 | AU14: 0 | AV14: 0 | AW14: 0 | AX14: 0 | AY14: 0 | BJ14: 0 | BK14: 0 | BL14: 0 | BM14: 0 | BN14: 0 | BO14: 0 | BP14: 0 | BQ14: 0 | BR14: 11318 | BS14: 14817 | BT14: 1 | BU14: 3581 | BV14: 2908 | BW14: 1367 | BX14: 15316 | BY14: 15138 | BZ14: 19413 | CA14: 0.58 | CB14: 536 | CC14: 20264 | CD14: 0.73 | CE14: 20472 | CF14: 0.72
A15: 陈琪-汇总 | I15: 900815 | J15: 879674 | K15: 495 | L15: 1776 | M15: 885 | N15: 930 | O15: 862 | P15: 658 | Q15: 832 | R15: 255 | S15: 323 | T15: 1238076 | U15: 1533902 | W15: 4749 | X15: 0.4983 | Y15: 0.974 | Z15: 0.4854 | AA15: 0.7633 | AB15: 0.9703 | AC15: 0.3875 | AD15: 0.1436 | AE15: 0.1819 | AF15: 1365601 | AG15: 1.12 | AH15: 868 | AI15: 832 | AJ15: 912 | AK15: 135927 | AL15: 113240 | AM15: 147997 | AN15: 15669 | AO15: 77457 | AP15: 619 | AQ15: 175 | AR15: 197 | AS15: 185 | AT15: 104 | AU15: 120 | AV15: 10 | AW15: 11 | AX15: 37527 | AY15: 39407 | BA15: 3582 | BB15: 0.2827 | BC15: 1.0571 | BD15: 0.2989 | BE15: 0.5622 | BF15: 0.6056 | BG15: 0.0962 | BH15: 0.0162 | BI15: 0.0178 | BJ15: 205 | BK15: 120 | BL15: 124 | BM15: 42699 | BN15: 20262 | BO15: 3945 | BP15: 5577 | BQ15: 9922 | BR15: 1275603 | BS15: 1573309 | BU15: 394246 | BV15: 338966 | BW15: 178682 | BX15: 900815 | BY15: 894152 | BZ15: 1411800 | CA15: 0.9 | CB15: 21141 | CC15: 1473743 | CD15: 1.07 | CE15: 1449764 | CF15: 1.09
A16: 2025年-9月陈琪直播 | H16: 12912 | I16: 128084 | J16: 123440 | K16: 577 | L16: 222 | M16: 91 | N16: 91 | O16: 90 | P16: 69 | Q16: 69 | R16: 26 | S16: 26 | T16: 151688 | U16: 151688 | V16: 1 | W16: 5834 | X16: 0.41 | Y16: 0.989 | Z16: 0.405 | AA16: 0.767 | AB16: 0.972 | AC16: 0.377 | AD16: 0.117 | AE16: 0.117 | AF16: 183768 | AG16: 0.83 | AH16: 71 | AI16: 69 | AJ16: 76 | AK16: 16821 | AL16: 13158 | AM16: 17031 | AN16: 2220 | AO16: 6455 | AP16: 0 | AQ16: 0 | AR16: 0 | AS16: 0 | AT16: 0 | AU16: 0 | AV16: 0 | AW16: 0 | AX16: 0 | AY16: 0 | BJ16: 0 | BK16: 0 | BL16: 0 | BM16: 0 | BN16: 0 | BO16: 0 | BP16: 0 | BQ16: 0 | BR16: 151688 | BS16: 151688 | BT16: 1 | BU16: 38863 | BV16: 38863 | BW16: 16821 | BX16: 128084 | BY16: 128084 | BZ16: 183768 | CA16: 0.83 | CB16: 4645 | CC16: 183768 | CD16: 0.83 | CE16: 183598 | CF16: 0.83
