Workbook

Sheet 陈琪
I1: 主投 | AR1: 辅投 | BW1: 汇总
B2: 渠道组 | C2: 供应商 | D2: 渠道名称 | E2: 主投 | F2: 辅投 | G2: 结算方式 | I2: 滚动消耗 | J2: 单例子成本 | K2: 例子数 | L2: 分发数 | M2: 剔除毛例子 分发数 | N2: 约课数 | Q2: 到课数 | R2: 滚动到课数 | S2: 当月成交数 | T2: 滚动成交数 | U2: 当月GMV | V2: 滚动GMV | W2: 海外GMV占比 | X2: 滚动ASP | Y2: 例子分发率 | Z2: 分发约课率 | AA2: 例子约课率 | AB2: 约课到课率 | AD2: 滚动应到课率 | AE2: 到课转化率 | AF2: 注册转化率 | AG2: 滚动转化率 | AH2: 滚动ROI2总成本 | AI2: 滚动ROI2 | AJ2: 滚动应到课人数 | AK2: 滚动到课人数 | AL2: 滚动到课人次 | AM2: 滚动其他成本 | AN2: 同源其他成本 | AO2: 运营成本 | AP2: 同源消耗 | AR2: 例子数 | AS2: 分发数 | AT2: 剔除毛例子 分发数 | AU2: 约课数 | AX2: 到课数 | AY2: 滚动到课数 | AZ2: 当月成交 | BA2: 滚动成交数 | BB2: 当月GMV | BC2: 滚动GMV | BD2: 海外GMV占比 | BE2: 滚动ASP | BF2: 例子分发率 | BG2: 分发约课率 | BH2: 例子约课率 | BI2: 约课到课率 | BK2: 滚动应到课率 | BL2: 到课转化率 | BM2: 注册转化率 | BN2: 滚动转化率 | BO2: 滚动应到课人数 | BP2: 滚动到课人数 | BQ2: 到课人次 | BR2: 滚动其他成本 | BS2: 同源其他成本 | BT2: 运营成本 | BU2: 滚动消耗 | BV2: 同源消耗 | BW2: 当月GMV | BX2: 滚动GMV | BY2: 海外GMV占比 | BZ2: 滚动其他成本 | CA2: 同源其他成本 | CB2: 运营成本 | CC2: 滚动消耗 | CD2: 同源消耗 | CE2: 当月ROI2总成本 | CF2: 当月ROI2 | CH2: 滚动ROI2总成本 | CI2: 滚动ROI2 | CJ2: O-ROI总成本 | CK2: O-ROI
A3: 45627 | C3: 陈琪 | D3: KOLHK-香港-陈琪-Shukei-思维&美术 | E3: 思维 | F3: 美术 | G3: CPT | I3: =8433.33333333333+25306 | J3: =I3/K3 | K3: 191 | L3: 163 | M3: 139 | N3: 91 | Q3: 63 | R3: 63 | S3: 15 | T3: 15 | U3: 59520 | V3: 59520 | W3: 1 | X3: 3968 | Y3: 0.85340314 | Z3: 0.55828221 | AA3: 0.47643979 | AB3: 0.69230769 | AD3: 0.95454545 | AE3: 0.23809524 | AF3: 0.078534031 | AG3: 0.078534031 | AH3: =AM3+AO3+AP3 | AI3: 1.2898729 | AJ3: 66 | AK3: 63 | AL3: 69 | AM3: 30997.944 | AN3: 33376.19 | AO3: 6712.8027 | AP3: 33739.333 | AR3: 190 | AS3: 28 | AT3: 28 | AU3: 31 | AX3: 23 | AY3: 23 | AZ3: 3 | BA3: 3 | BB3: 12498.4 | BC3: 12498.4 | BD3: 1 | BE3: 4166.1333 | BF3: 0.14736842 | BG3: 1.1071429 | BH3: 0.16315789 | BI3: 0.74193548 | BK3: 0.79310345 | BL3: 0.13043478 | BM3: 0.015789474 | BN3: 0.015789474 | BO3: 29 | BP3: 23 | BQ3: 23 | BR3: 9466.1202 | BS3: 9466.1202 | BT3: 5723.5105 | BU3: 0 | BV3: 0 | BW3: 72018.4 | BX3: 72018.4 | BY3: 1 | BZ3: 40464.065 | CA3: 42842.31 | CB3: 12436.313 | CC3: 33739.333 | CD3: 33739.333 | CE3: =CA3+CB3+CD3 | CF3: =BW3/CE3 | CH3: =BZ3+CB3+CC3 | CI3: =BX3/CH3 | CJ3: 77472.398 | CK3: 0.92960076
A4: 45658 | C4: 陈琪 | D4: KOLHK-香港-陈琪-Shukei-思维&美术 | E4: 思维 | F4: 美术 | G4: CPT | I4: 40591.523 | J4: 343.99596 | K4: 118 | L4: 83 | M4: 48 | N4: 48 | Q4: 40 | R4: 51 | S4: 14 | T4: 15 | U4: 69532 | V4: 73220 | W4: 1 | X4: 4881.3333 | Y4: 0.70338983 | Z4: 0.57831325 | AA4: 0.40677966 | AB4: 0.83333333 | AD4: 0.82258065 | AE4: 0.35 | AF4: 0.11864407 | AG4: 0.12711864 | AH4: 70880.038 | AI4: 1.033013 | AJ4: 62 | AK4: 51 | AL4: 57 | AM4: 18845.028 | AN4: 22163.958 | AO4: 11443.487 | AP4: 40591.523 | AR4: 118 | AS4: 31 | AT4: 36 | AU4: 29 | AX4: 17 | AY4: 19 | AZ4: 2 | BA4: 2 | BB4: 6529.2 | BC4: 6529.2 | BD4: 1 | BE4: 3264.6 | BF4: 0.26271186 | BG4: 0.93548387 | BH4: 0.24576271 | BI4: 0.5862069 | BK4: 0.55882353 | BL4: 0.11764706 | BM4: 0.016949153 | BN4: 0.016949153 | BO4: 34 | BP4: 19 | BQ4: 20 | BR4: 7421.2655 | BS4: 6639.2255 | BT4: 11443.487 | BU4: 0 | BV4: 0 | BW4: 76061.2 | BX4: 79749.2 | BY4: 1 | BZ4: 26266.293 | CA4: 28803.184 | CB4: 22886.974 | CC4: 40591.523 | CD4: 40591.523 | CE4: 92281.681 | CF4: 0.82422859 | CH4: 89744.79 | CI4: 0.88862206 | CJ4: 84557.816 | CK4: 0.94313221
A5: 45690 | C5: 陈琪 | D5: KOLHK-香港-陈琪-Shukei-思维&美术 | E5: 思维 | F5: 美术 | G5: CPT | I5: 48635.086 | J5: 268.70213 | K5: 181 | L5: 122 | M5: 86 | N5: 90 | Q5: 64 | R5: 72 | S5: 23 | T5: 27 | U5: 118186.4 | V5: 138838.4 | W5: 1 | X5: 5142.163 | Y5: 0.67403315 | Z5: 0.73770492 | AA5: 0.49723757 | AB5: 0.71111111 | AD5: 0.77419355 | AE5: 0.359375 | AF5: 0.12707182 | AG5: 0.14917127 | AH5: 90105.691 | AI5: 1.5408394 | AJ5: 93 | AK5: 72 | AL5: 78 | AM5: 31707.907 | AN5: 32950.219 | AO5: 9762.6975 | AP5: 48635.086 | AR5: 164 | AS5: 46 | AT5: 49 | AU5: 52 | AX5: 21 | AY5: 24 | AZ5: 2 | BA5: 2 | BB5: 7176 | BC5: 7176 | BD5: 1 | BE5: 3588 | BF5: 0.2804878 | BG5: 1.1304348 | BH5: 0.31707317 | BI5: 0.40384615 | BK5: 0.45283019 | BL5: 0.095238095 | BM5: 0.012195122 | BN5: 0.012195122 | BO5: 53 | BP5: 24 | BQ5: 25 | BR5: 8064.9318 | BS5: 7487.9811 | BT5: 8845.7591 | BU5: 0 | BV5: 0 | BW5: 125362.4 | BX5: 146014.4 | BY5: 1 | BZ5: 39772.839 | CA5: 40438.2 | CB5: 18608.457 | CC5: 48635.086 | CD5: 48635.086 | CE5: 107681.74 | CF5: 1.1641936 | CH5: 107016.38 | CI5: 1.3644117 | CJ5: 114282.93 | CK5: 1.2776572
A6: 45718 | C6: 陈琪 | D6: KOLHK-香港-陈琪-Shukei-思维&美术 | E6: 思维 | F6: 美术 | G6: CPT | I6: 110033.47 | J6: 374.26351 | K6: 294 | L6: 140 | M6: 144 | N6: 150 | Q6: 114 | R6: 129 | S6: 41 | T6: 49 | U6: 213308 | V6: 245112 | W6: 1 | X6: 5002.2857 | Y6: 0.47619048 | Z6: 1.0714286 | AA6: 0.51020408 | AB6: 0.76 | AD6: 0.94160584 | AE6: 0.35964912 | AF6: 0.13945578 | AG6: 0.16666667 | AH6: 215177.03 | AI6: 1.1391179 | AJ6: 137 | AK6: 129 | AL6: 133 | AM6: 50828.352 | AN6: 16883.591 | AO6: 23897.061 | AP6: 2738.6332 | AQ6: 10795.924 | AR6: 16 | AS6: 16 | AT6: 24 | AU6: 16 | AX6: 10 | AY6: 13 | AZ6: 2 | BA6: 2 | BB6: 7735.2 | BC6: 7735.2 | BD6: 1 | BE6: 3867.6 | BF6: 1 | BG6: 1 | BH6: 1 | BI6: 0.625 | BK6: 0.54166667 | BL6: 0.2 | BM6: 0.125 | BN6: 0.125 | BO6: 24 | BP6: 13 | BQ6: 14 | BR6: 2631.4887 | BS6: 2476.231 | BT6: 764.50317 | BU6: 149.04126 | BV6: 1141.7321 | BW6: 221043.2 | BX6: 252847.2 | BY6: 1 | BZ6: 58846.717 | CA6: 52989.362 | CB6: 53459.841 | CC6: 110033.47 | CD6: 110033.47 | CE6: 216482.67 | CF6: 1.0210665 | CH6: 222340.03 | CI6: 1.1372095 | CJ6: 192130.19 | CK6: 1.3160202
A8: 陈琪-汇总 | I8: =SUM(I3:I6) | J8: =I8/K8 | K8: =SUM(K3:K6) | L8: =SUM(L3:L6) | M8: =SUM(M3:M6) | N8: =SUM(N3:N6) | Q8: =SUM(Q3:Q6) | R8: =SUM(R3:R6) | S8: =SUM(S3:S6) | T8: =SUM(T3:T6) | U8: =SUM(U3:U6) | V8: =SUM(V3:V6) | X8: =V8/T8 | Y8: =L8/K8 | Z8: =N8/L8 | AA8: =N8/K8 | AB8: =Q8/N8 | AD8: =AVERAGE(AD3:AD6) | AE8: =S8/Q8 | AF8: =S8/K8 | AG8: =T8/K8 | AH8: =SUM(AH3:AH6) | AI8: =V8/AH8 | AJ8: =SUM(AJ3:AJ6) | AK8: =SUM(AK3:AK6) | AL8: =SUM(AL3:AL6) | AM8: =SUM(AM3:AM6) | AN8: =SUM(AN3:AN6) | AO8: =SUM(AO3:AO6) | AP8: =SUM(AP3:AP6) | AR8: =SUM(AR3:AR6) | AS8: =SUM(AS3:AS6) | AU8: =SUM(AU3:AU6) | AX8: =SUM(AX3:AX6) | AY8: =SUM(AY3:AY6) | AZ8: =SUM(AZ3:AZ6) | BA8: =SUM(BA3:BA6) | BB8: =SUM(BB3:BB6) | BC8: =SUM(BC3:BC6) | BE8: =BC8/BA8 | BF8: =AS8/AR8 | BG8: =AU8/AS8 | BH8: =AU8/AR8 | BI8: =AX8/AU8 | BK8: =AVERAGE(BK3:BK6) | BL8: =AZ8/AX8 | BM8: =AZ8/AR8 | BN8: =BA8/AR8 | BO8: =SUM(BO3:BO6) | BP8: =SUM(BP3:BP6) | BQ8: =SUM(BQ3:BQ6) | BR8: =SUM(BR3:BR6) | BS8: =SUM(BS3:BS6) | BT8: =SUM(BT3:BT6) | BU8: =SUM(BU3:BU6) | BV8: =SUM(BV3:BV6) | ... BX8: =SUM(BX3:BX6) | BZ8: =SUM(BZ3:BZ6) | CA8: =SUM(CA3:CA6) | CB8: =SUM(CB3:CB6) | CC8: =SUM(CC3:CC6) | CD8: =SUM(CD3:CD6) | CE8: =SUM(CE3:CE6) | CF8: =BW8/CE8 | CH8: =SUM(CH3:CH6) | CI8: =BX8/CH8 | CJ8: =SUM(CJ3:CJ6) | CK8: =BX8/CJ8
I11: 主投 | AR11: 辅投 | BW11: 汇总
B12: 渠道组 | C12: 供应商 | D12: 渠道名称 | E12: 主投 | F12: 辅投 | G12: 结算方式 | H12: 滚动消耗 | I12: 滚动消耗(不含赠课成本) | J12: 单例子成本 | K12: 例子数 | L12: 分发数 | M12: 剔除毛例子 分发数 | N12: 约课数 | O12: 应到课数 | P12: 滚动应到课数 | Q12: 到课数 | R12: 滚动到课数 | S12: 当月成交数 | T12: 滚动成交数 | U12: 当月GMV | V12: 滚动GMV | W12: 海外GMV占比 | X12: 滚动ASP | Y12: 例子分发率 | Z12: 分发约课率 | AA12: 例子约课率 | AB12: 约课到课率 | AC12: 应到课率 | AD12: 滚动应到课率 | AE12: 到课转化率 | AF12: 注册转化率 | AG12: 滚动转化率 | AH12: 滚动ROI2总成本 | AI12: 滚动ROI2 | AJ12: 滚动应到课人数 | AK12: 滚动到课人数 | AL12: 滚动到课人次 | AM12: 运营成本 | AN12: 销售固定成本 | AO12: 销售变动成本 | AP12: TMK费用 | AQ12: DEMO费用 | AR12: 例子数 | AS12: 分发数 | AT12: 剔除毛例子分发数 | AU12: 约课数 | AV12: 应到课数 | AW12: 滚动应到课数 | AX12: 到课数 | AY12: 滚动到课数 | AZ12: 当月成交 | BA12: 滚动成交数 | BB12: 当月GMV | BC12: 滚动GMV | BD12: 海外GMV占比 | BE12: 滚动ASP | BF12: 例子分发率 | BG12: 分发约课率 | BH12: 例子约课率 | BI12: 约课到课率 | BJ12: 应到课率 | BK12: 滚动应到课率 | BL12: 到课转化率 | BM12: 注册转化率 | BN12: 滚动转化率 | BO12: 滚动应到课人数 | BP12: 滚动到课人数 | BQ12: 滚动到课人次 | BR12: 运营成本 | BS12: 销售固定成本 | BT12: 销售变动成本 | BU12: TMK费用 | BV12: DEMO费用 | BW12: 当月GMV | BX12: 滚动GMV | BY12: 海外GMV占比 | BZ12: 滚动其他成本 | CA12: 同源其他成本 | CB12: 运营成本 | CC12: 滚动消耗 | CD12: 同源消耗 | CE12: 当月ROI2总成本 | CF12: 当月ROI2 | CG12: 滚动赠课成本 | CH12: 滚动ROI2总成本 | CI12: 滚动ROI2 | CJ12: O-ROI总成本 | CK12: O-ROI
A13: 45627 | D13: 总计 | E13: - | F13: - | G13: - | H13: =I13 | I13: =8433.33333333333+25306 | J13: =I13/K13 | K13: 191 | L13: 138 | M13: 139 | N13: 91 | Q13: 63 | R13: 63 | S13: 15 | T13: 15 | U13: 59520 | V13: 59520 | W13: 1 | X13: 3968 | Y13: 0.72251309 | Z13: 0.65942029 | AA13: 0.47643979 | AB13: 0.69230769 | AD13: 0.95454545 | AE13: 0.23809524 | AF13: 0.078534031 | AG13: 0.078534031 | AH13: 50677.94 | AI13: 1.1744755 | AJ13: 66 | AK13: 63 | AL13: 69 | AM13: 11246.663 | AN13: 16717.383 | AO13: 6655.1707 | AP13: 1780.9884 | AQ13: 5844.4024 | AR13: 190 | AS13: 26 | AT13: 26 | AU13: 31 | AX13: 23 | AY13: 23 | AZ13: 3 | BA13: 3 | BB13: 12498.4 | BC13: 12498.4 | BD13: 1 | BE13: 4166.1333 | BF13: 0.13684211 | BG13: 1.1923077 | BH13: 0.16315789 | BI13: 0.74193548 | BK13: 0.76666667 | BL13: 0.13043478 | BM13: 0.015789474 | BN13: 0.015789474 | BO13: 30 | BP13: 23 | BQ13: 23 | BR13: 8938.1178 | BS13: 4012.0066 | BT13: 1313.2814 | BU13: 1852.5288 | BV13: 1979.6875 | BW13: 72018.4 | BX13: 72018.4 | BY13: 1 | BZ13: 40155.449 | CA13: 40035.18 | CB13: 20184.781 | CC13: 33739.333 | CD13: 33739.333 | CE13: =CA13+CB13+CD13 | CF13: =BW13/CE13 | CH13: =BZ13+CB13+CC13 | CI13: =BX13/CH13 | CJ13: 77472.398 | CK13: 0.92960076
A14: 45658 | D14: 总计 | E14: - | F14: - | G14: - | H14: =I14 | I14: 40591.523 | J14: =I14/K14 | K14: 118 | L14: 45 | M14: 48 | N14: 48 | Q14: 40 | R14: 51 | S14: 14 | T14: 15 | U14: 69532 | V14: 73220 | W14: 1 | X14: 4881.3333 | Y14: 0.38135593 | Z14: 1.0666667 | AA14: 0.40677966 | AB14: 0.83333333 | AD14: 0.96226415 | AE14: 0.35 | AF14: 0.11864407 | AG14: 0.12711864 | AH14: 73894.233 | AI14: 0.99087571 | AJ14: 53 | AK14: 51 | AL14: 57 | AM14: 14457.682 | AN14: 6861.7592 | AO14: 6045.5177 | AP14: 1310.926 | AQ14: 4626.8247 | AR14: 118 | AS14: 30 | AT14: 36 | AU14: 29 | AX14: 17 | AY14: 19 | AZ14: 2 | BA14: 2 | BB14: 6529.2 | BC14: 6529.2 | BD14: 1 | BE14: 3264.6 | BF14: 0.25423729 | BG14: 0.96666667 | BH14: 0.24576271 | BI14: 0.5862069 | BK14: 0.55882353 | BL14: 0.11764706 | BM14: 0.016949153 | BN14: 0.016949153 | BO14: 34 | BP14: 19 | BQ14: 20 | BR14: 13719.917 | BS14: 3869.1587 | BT14: 610.13502 | BU14: 1310.926 | BV14: 1631.0459 | BW14: 76061.2 | BX14: 79749.2 | BY14: 1 | BZ14: 26266.293 | CA14: 23750.895 | CB14: 28177.598 | CC14: 40591.523 | CD14: 40591.523 | CE14: 92520.017 | CF14: 0.82210534 | CH14: 95035.415 | CI14: 0.83915244 | CJ14: 84557.816 | CK14: 0.94313221
A15: 45690 | D15: 总计 | E15: - | F15: - | G15: - | H15: =I15 | I15: 48635.086 | J15: =I15/K15 | K15: 181 | L15: 85 | M15: 86 | N15: 90 | Q15: 64 | R15: 72 | S15: 23 | T15: 27 | U15: 118186.4 | V15: 138838.4 | W15: 1 | X15: 5142.163 | Y15: 0.46961326 | Z15: 1.0588235 | AA15: 0.49723757 | AB15: 0.71111111 | AD15: 0.94736842 | AE15: 0.359375 | AF15: 0.12707182 | AG15: 0.14917127 | AH15: 93016.863 | AI15: 1.4926154 | AJ15: 76 | AK15: 72 | AL15: 78 | AM15: 12471.987 | AN15: 11124.357 | AO15: 12886.159 | AP15: 1250.3664 | AQ15: 6648.908 | AR15: 164 | AS15: 46 | AT15: 49 | AU15: 52 | AX15: 21 | AY15: 24 | AZ15: 2 | BA15: 2 | BB15: 7176 | BC15: 7176 | BD15: 1 | BE15: 3588 | BF15: 0.2804878 | BG15: 1.1304348 | BH15: 0.31707317 | BI15: 0.40384615 | BK15: 0.45283019 | BL15: 0.095238095 | BM15: 0.012195122 | BN15: 0.012195122 | BO15: 53 | BP15: 24 | BQ15: 25 | BR15: 10653.537 | BS15: 4401.1099 | BT15: 691.26004 | BU15: 1198.424 | BV15: 1846.5914 | BW15: 125362.4 | BX15: 146014.4 | BY15: 1 | BZ15: 40047.176 | CA15: 36742.798 | CB15: 23125.524 | CC15: 48635.086 | CD15: 48635.086 | CE15: 108503.41 | CF15: 1.1553775 | CH15: 111807.79 | CI15: 1.3059413 | CJ15: 114557.26 | CK15: 1.2745975
A16: 45718 | D16: 总计 | E16: - | F16: - | G16: - | H16: =I16 | I16: 113250.48 | J16: 380.03515 | K16: 298 | L16: 142 | M16: 146 | N16: 152 | Q16: 117 | R16: 132 | S16: 47 | T16: 55 | U16: 243836 | V16: 275640 | W16: 1 | X16: 5011.6364 | Y16: 0.47651007 | Z16: 1.0704225 | AA16: 0.51006711 | AB16: 0.76973684 | AD16: 0.94964029 | AE16: 0.4017094 | AF16: 0.15771812 | AG16: 0.18456376 | AH16: 193914.57 | AI16: 1.4214507 | AJ16: 139 | AK16: 132 | AL16: 138 | AM16: 26635.972 | AN16: 14433.456 | AO16: 26387.439 | AP16: 2005.4387 | AQ16: 11201.786 | AR16: 18 | AS16: 17 | AT16: 25 | AU16: 17 | AX16: 10 | AY16: 13 | AZ16: 2 | BA16: 2 | BB16: 7735.2 | BC16: 7735.2 | BD16: 1 | BE16: 3867.6 | BF16: 0.94444444 | BG16: 1 | BH16: 0.94444444 | BI16: 0.58823529 | BK16: 0.54166667 | BL16: 0.2 | BM16: 0.11111111 | BN16: 0.11111111 | BO16: 24 | BP16: 13 | BQ16: 14 | BR16: 1471.4819 | BS16: 2100.202 | BT16: 760.24777 | BU16: 121.13388 | BV16: 1141.7321 | BW16: 251571.2 | BX16: 283375.2 | BY16: 1 | BZ16: 58151.435 | CA16: 52577.046 | CB16: 28107.454 | CC16: 113250.48 | CD16: 113250.48 | CE16: 193934.98 | CF16: 1.2971936 | CH16: 199509.37 | CI16: 1.4203604 | CJ16: 195101.91 | CK16: 1.4524471
A17: 45749 | H17: =I17 | I17: 131731.98 | J17: 539.88517 | K17: 244 | L17: 122 | M17: 128 | N17: 127 | Q17: 100 | R17: 124 | S17: 41 | T17: 48 | U17: 180708 | V17: 211424 | W17: 1 | X17: 4404.6667 | Y17: 0.5 | Z17: 1.0409836 | AA17: 0.5204918 | AB17: 0.78740157 | AD17: 0.98412698 | AE17: 0.41 | AF17: 0.16803279 | AG17: 0.19672131 | AH17: 210352.89 | AI17: 1.005092 | AJ17: 126 | AK17: 124 | AL17: 134 | AM17: 27025.104 | AN17: 18959.254 | AO17: 18955.011 | AP17: 2411.5963 | AQ17: 11269.939 | AR17: 20 | AS17: 18 | AT17: 20 | AU17: 18 | AX17: 11 | AY17: 13 | AZ17: 0 | BA17: 0 | BB17: 0 | BC17: 0 | BF17: 0.9 | BG17: 1 | BH17: 0.9 | BI17: 0.61111111 | BK17: 0.65 | BL17: 0 | BM17: 0 | BN17: 0 | BO17: 20 | BP17: 13 | BQ17: 14 | BR17: 2092.9385 | BS17: 2050.2685 | BT17: 0 | BU17: 197.67183 | BV17: 1114.1083 | BW17: 180708 | BX17: 211424 | BY17: 1 | BZ17: 54957.85 | CA17: 48848.536 | CB17: 29118.043 | CC17: 131731.98 | CD17: 131731.98 | CE17: 209698.56 | CF17: 0.86175127 | CH17: 215807.87 | CI17: 0.97968622 | CJ17: 206489.83 | CK17: 1.0238955
A18: 45779 | H18: =I18 | I18: 163228.27 | J18: 632.66773 | K18: 258 | L18: 119 | M18: 124 | N18: 116 | Q18: 84 | R18: 106 | S18: 34 | T18: 45 | U18: 171724 | V18: 222292 | W18: 1 | X18: 4939.8222 | Y18: 0.46124031 | Z18: 0.97478992 | AA18: 0.4496124 | AB18: 0.72413793 | AD18: 0.95495495 | AE18: 0.4047619 | AF18: 0.13178295 | AG18: 0.1744186 | AH18: 226867.01 | AI18: 0.97983395 | AJ18: 111 | AK18: 106 | AL18: 116 | AM18: 14627.721 | AN18: 15217.58 | AO18: 21318.363 | AP18: 2399.1923 | AQ18: 10075.88 | AR18: 6 | AS18: 5 | AT18: 6 | AU18: 5 | AX18: 3 | AY18: 6 | AZ18: 0 | BA18: 0 | BB18: 0 | BC18: 0 | BF18: 0.83333333 | BG18: 1 | BH18: 0.83333333 | BI18: 0.6 | BK18: 0.75 | BL18: 0 | BM18: 0 | BN18: 0 | BO18: 8 | BP18: 6 | BQ18: 6 | BR18: 281.4866 | BS18: 656.08636 | BT18: 0 | BU18: 55.795171 | BV18: 465.60811 | BW18: 171724 | BX18: 222292 | BY18: 1 | BZ18: 50188.505 | CA18: 42211.616 | CB18: 14909.208 | CC18: 163228.27 | CD18: 163228.27 | CE18: 220349.1 | CF18: 0.77932699 | CH18: 228325.99 | CI18: 0.97357293 | CJ18: 233216.78 | CK18: 0.95315612
A19: 45810 | H19: 154847.15 | I19: 145313.96 | J19: 758.5688 | K19: 204 | L19: 114 | M19: 124 | N19: 116 | Q19: 96 | R19: 130 | S19: 43 | T19: 53 | U19: 209284 | V19: 255664 | W19: 1 | X19: 4823.8491 | Y19: 0.55882353 | Z19: 1.0175439 | AA19: 0.56862745 | AB19: 0.82758621 | AD19: 0.92857143 | AE19: 0.44791667 | AF19: 0.21078431 | AG19: 0.25980392 | AH19: 220689.03 | AI19: 1.1584808 | AJ19: 140 | AK19: 130 | AL19: 150 | AM19: 12724.406 | AN19: 13935.795 | AO19: 24680.086 | AP19: 1647.4886 | AQ19: 12953.219 | AR19: 99 | AS19: 30 | AT19: 30 | AU19: 29 | AX19: 17 | AY19: 20 | AZ19: 1 | BA19: 1 | BB19: 3588 | BC19: 3588 | BD19: 1 | BE19: 3588 | BF19: 0.3030303 | BG19: 0.96666667 | BH19: 0.29292929 | BI19: 0.5862069 | BK19: 0.625 | BL19: 0.058823529 | BM19: 0.01010101 | BN19: 0.01010101 | BO19: 32 | BP19: 20 | BQ19: 20 | BR19: 5541.8712 | BS19: 2698.7077 | BT19: 372.89882 | BU19: 799.51651 | BV19: 1578.9348 | BW19: 212872 | BX19: 259252 | BY19: 1 | BZ19: 58843.626 | CA19: 48947.043 | CB19: 18322.256 | CC19: 154847.15 | CD19: 153067.13 | CE19: 220336.43 | CF19: 0.96612257 | CG19: 9533.1911 | CH19: 232013.03 | CI19: 1.1174028 | CJ19: 236490.77 | CK19: 1.0962457
A20: 45841 | H20: 120482.45 | I20: 114209.1 | J20: 813.40499 | K20: 148 | L20: 62 | M20: 69 | N20: 64 | Q20: 52 | R20: 77 | S20: 24 | T20: 35 | U20: 121912 | V20: 163880 | W20: 1 | X20: 4682.2857 | Y20: 0.41891892 | Z20: 1.0322581 | AA20: 0.43243243 | AB20: 0.8125 | AD20: 0.9625 | AE20: 0.46153846 | AF20: 0.16216216 | AG20: 0.23648649 | AH20: 160109.83 | AI20: 1.0235474 | AJ20: 80 | AK20: 77 | AL20: 87 | AM20: 6512.6513 | AN20: 7240.4441 | AO20: 16780.999 | AP20: 1523.4822 | AQ20: 7668.3132 | AR20: 4 | AS20: 3 | AT20: 4 | AU20: 4 | AX20: 2 | AY20: 2 | AZ20: 0 | BA20: 1 | BB20: 0 | BC20: 1880 | BD20: 1 | BE20: 1880 | BF20: 0.75 | BG20: 1.3333333 | BH20: 1 | BI20: 0.5 | BK20: 0.5 | BL20: 0 | BM20: 0 | BN20: 0.25 | BO20: 4 | BP20: 2 | BQ20: 2 | BR20: 0 | BS20: 379.4598 | BT20: 197.37392 | BU20: 41.175195 | BV20: 164.36677 | BW20: 121912 | BX20: 165760 | BY20: 1 | BZ20: 33995.614 | CA20: 26115.29 | CB20: 6512.6513 | CC20: 120482.45 | CD20: 118443.28 | CE20: 151071.22 | CF20: 0.80698364 | CG20: 6273.3514 | CH20: 160990.72 | CI20: 1.0296246 | CJ20: 165878.07 | CK20: 0.99928824
A21: 45872 | H21: 38341.074 | I21: 35865.584 | J21: 833.5016 | K21: 46 | L21: 21 | M21: 25 | N21: 21 | Q21: 16 | R21: 36 | S21: 6 | T21: 14 | U21: 24028 | V21: 57832 | W21: 1 | X21: 4130.8571 | Y21: 0.45652174 | Z21: 1 | AA21: 0.45652174 | AB21: 0.76190476 | AD21: 1 | AE21: 0.375 | AF21: 0.13043478 | AG21: 0.30434783 | AH21: 55313.157 | AI21: 1.0455379 | AJ21: 36 | AK21: 36 | AL21: 38 | AM21: 4152.8585 | AN21: 3087.9608 | AO21: 5921.8862 | AP21: 460 | AQ21: 3349.3782 | AR21: 0 | AS21: 0 | AT21: 0 | AU21: 0 | AX21: 0 | AY21: 0 | AZ21: 0 | BA21: 0 | BB21: 0 | BC21: 0 | BO21: 0 | BP21: 0 | BQ21: 0 | BR21: 0 | BS21: 0 | BT21: 0 | BU21: 0 | BV21: 0 | BW21: 24028 | BX21: 57832 | BY21: 1 | BZ21: 12819.225 | CA21: 7100.8559 | CB21: 4152.8585 | CC21: 38341.074 | CD21: 36926.508 | CE21: 48180.223 | CF21: 0.49871086 | CG21: 2475.4893 | CH21: 55313.157 | CI21: 1.0455379 | CJ21: 54610.299 | CK21: 1.0589944
A22: 45903 | H22: 23291.661 | I22: =H22-CG22 | J22: 597.22208 | K22: 39 | L22: 18 | M22: 20 | N22: 19 | Q22: 11 | R22: 21 | S22: 3 | T22: 6 | U22: 11564 | V22: 22328 | W22: 1 | X22: 3721.3333 | Y22: 0.46153846 | Z22: 1.0555556 | AA22: 0.48717949 | AB22: 0.57894737 | AD22: 1 | AE22: 0.27272727 | AF22: 0.076923077 | AG22: 0.15384615 | AH22: 33903.815 | AI22: 0.65856895 | AJ22: 21 | AK22: 21 | AL22: 22 | AM22: 2954.9847 | AN22: 2891.7842 | AO22: 2506.9331 | AP22: 390 | AQ22: 1868.452 | AR22: 0 | AS22: 0 | AT22: 1 | AU22: 0 | AX22: 0 | AY22: 0 | AZ22: 0 | BA22: 0 | BB22: 0 | BC22: 0 | BO22: 0 | BP22: 0 | BQ22: 0 | BR22: 0 | BS22: 95 | BT22: 0 | BU22: 0 | BV22: 0 | BW22: 11564 | BX22: 22328 | BY22: 1 | BZ22: 7752.1693 | CA22: 5225.2093 | CB22: 2954.9847 | CC22: 23291.661 | CD22: 22755.744 | CE22: 30935.938 | CF22: 0.37380473 | CG22: 1071.8348 | CH22: 33998.815 | CI22: 0.65672877 | CJ22: 33968.831 | CK22: 0.65730847
A23: 45931 | H23: 17359.655 | I23: =H23-CG23 | J23: 619.98769 | K23: 28 | L23: 11 | M23: 12 | N23: 10 | Q23: 9 | R23: 12 | S23: 3 | T23: 7 | U23: 16464 | V23: 38447 | W23: 1 | X23: 5492.4286 | Y23: 0.39285714 | Z23: 0.90909091 | AA23: 0.35714286 | AB23: 0.9 | AD23: 1 | AE23: 0.33333333 | AF23: 0.10714286 | AG23: 0.25 | AH23: 26596.919 | AI23: 1.4455434 | AJ23: 12 | AK23: 12 | AL23: 15 | AM23: 1749.5713 | AN23: 1706.9683 | AO23: 4229.235 | AP23: 280 | AQ23: 1271.4886 | AR23: 0 | AS23: 0 | AT23: 0 | AU23: 0 | AX23: 0 | AY23: 0 | AZ23: 0 | BA23: 0 | BB23: 0 | BC23: 0 | BO23: 0 | BP23: 0 | BQ23: 0 | BR23: 0 | BS23: 0 | BT23: 0 | BU23: 0 | BV23: 0 | BW23: 16464 | BX23: 38447 | BY23: 1 | BZ23: 7487.6919 | CA23: 4503.4478 | CB23: 1749.5713 | CC23: 17359.655 | CD23: 16645.099 | CE23: 22898.118 | CF23: 0.71901105 | CG23: 1250.474 | CH23: 26596.919 | CI23: 1.4455434 | CJ23: 26947.347 | CK23: 1.4267453
A24: 45962 | H24: 20294.266 | I24: =H24-CG24 | J24: 780.5487 | K24: 26 | L24: 9 | M24: 10 | N24: 9 | Q24: 7 | R24: 10 | S24: 2 | T24: 4 | U24: 11318 | V24: 20116 | W24: 1 | X24: 5029 | Y24: 0.34615385 | Z24: 1 | AA24: 0.34615385 | AB24: 0.77777778 | AD24: 1 | AE24: 0.28571429 | AF24: 0.076923077 | AG24: 0.15384615 | AH24: 26488.23 | AI24: 0.75943164 | AJ24: 10 | AK24: 10 | AL24: 10 | AM24: 1692.4313 | AN24: 1181.0796 | AO24: 2212.794 | AP24: 260 | AQ24: 847.65904 | AR24: 0 | AS24: 0 | AT24: 0 | AU24: 0 | AX24: 0 | AY24: 0 | AZ24: 0 | BA24: 0 | BB24: 0 | BC24: 0 | BO24: 0 | BP24: 0 | BQ24: 0 | BR24: 0 | BS24: 0 | BT24: 0 | BU24: 0 | BV24: 0 | BW24: 11318 | BX24: 20116 | BY24: 1 | BZ24: 4501.5327 | CA24: 3161.3321 | CB24: 1692.4313 | CC24: 20294.266 | CD24: 19936.821 | CE24: 24790.585 | CF24: 0.45654429 | CG24: 714.88942 | CH24: 26488.23 | CI24: 0.75943164 | CJ24: 26745.799 | CK24: 0.75211812
A25: 45992 | H25: 10835.454 | I25: =H25-CG25 | J25: 3611.8179 | K25: 3 | L25: 1 | M25: 1 | N25: 2 | O25: 2 | P25: 5 | Q25: 1 | R25: 5 | S25: 0 | T25: 0 | U25: 0 | V25: 0 | Y25: 0.33333333 | Z25: 2 | AA25: 0.66666667 | AB25: 0.5 | AC25: 0.5 | AD25: 1 | AE25: 0 | AF25: 0 | AG25: 0 | AH25: 906.06055 | AI25: 0 | AJ25: 5 | AK25: 5 | AL25: 6 | AM25: 223.84966 | AN25: 147.22787 | AO25: 0 | AP25: 30 | AQ25: 504.98302 | AR25: 0 | AS25: 0 | AT25: 0 | AU25: 0 | AV25: 0 | AW25: 0 | AX25: 0 | AY25: 0 | AZ25: 0 | BA25: 0 | BB25: 0 | BC25: 0 | BO25: 0 | BP25: 0 | BQ25: 0 | BR25: 0 | BS25: 0 | BT25: 0 | BU25: 0 | BV25: 0 | BW25: 0 | BX25: 0 | BZ25: 682.21089 | CA25: 345.55554 | CB25: 223.84966 | CC25: 10835.454 | CD25: 10835.454 | CE25: 569.40521 | CF25: 0 | CG25: 0 | CH25: 906.06055 | CI25: 0 | CJ25: 907.21089 | CK25: 0
A26: 46023 | H26: 2266.5659 | I26: =H26-CG26 | J26: 566.64146 | K26: 4 | L26: 4 | M26: 4 | N26: 3 | O26: 3 | P26: 2 | Q26: 2 | R26: 2 | S26: 1 | T26: 1 | U26: 4588 | V26: 4588 | W26: 1 | X26: 4588 | Y26: 1 | Z26: 0.75 | AA26: 0.75 | AB26: 0.66666667 | AC26: 0.66666667 | AD26: 1 | AE26: 0.5 | AF26: 0.25 | AG26: 0.25 | AH26: 4042.3411 | AI26: 1.1349859 | AJ26: 2 | AK26: 2 | AL26: 2 | AM26: 374.59392 | AN26: 625.33018 | AO26: 567.52352 | AP26: 40 | AQ26: 168.32767 | AR26: 0 | AS26: 0 | AT26: 0 | AU26: 0 | AV26: 0 | AW26: 0 | AX26: 0 | AY26: 0 | AZ26: 0 | BA26: 0 | BB26: 0 | BC26: 0 | BO26: 0 | BP26: 0 | BQ26: 0 | BR26: 0 | BS26: 0 | BT26: 0 | BU26: 0 | BV26: 0 | BW26: 4588 | BX26: 4588 | BY26: 1 | BZ26: 1401.1814 | CA26: 1401.1814 | CB26: 374.59392 | CC26: 2266.5659 | CD26: 2266.5659 | CE26: 4042.3411 | CF26: 1.1349859 | CG26: 0 | CH26: 4042.3411 | CI26: 1.1349859 | CJ26: 3967.7472 | CK26: 1.1563237
A27: 陈琪-汇总 | H27: =SUM(H13:H26) | I27: =SUM(I13:I26) | J27: =I27/K27 | K27: =SUM(K13:K26) | L27: =SUM(L13:L26) | M27: =SUM(M13:M26) | N27: =SUM(N13:N26) | O27: =SUM(O13:O26) | P27: =SUM(P13:P26) | Q27: =SUM(Q13:Q26) | R27: =SUM(R13:R26) | ... V27: =SUM(V13:V26) | X27: =V27/T27 | Y27: =L27/K27 | Z27: =N27/L27 | AA27: =N27/K27 | AB27: =Q27/N27 | AD27: =AVERAGE(AD13:AD26) | AE27: =S27/Q27 | AF27: =S27/K27 | AG27: =T27/K27 | AH27: =SUM(AH13:AH26) | AI27: =V27/AH27 | AJ27: =SUM(AJ13:AJ26) | AK27: =SUM(AK13:AK26) | AL27: =SUM(AL13:AL26) | AM27: =SUM(AM13:AM26) | AN27: =SUM(AN13:AN26) | AO27: =SUM(AO13:AO26) | AP27: =SUM(AP13:AP26) | AQ27: =SUM(AQ13:AQ26) | ... AU27: =SUM(AU13:AU26) | AX27: =SUM(AX13:AX26) | AY27: =SUM(AY13:AY26) | AZ27: =SUM(AZ13:AZ26) | BA27: =SUM(BA13:BA26) | BB27: =SUM(BB13:BB26) | BC27: =SUM(BC13:BC26) | BE27: =BC27/BA27 | BF27: =AS27/AR27 | BG27: =AU27/AS27 | BH27: =AU27/AR27 | BI27: =AX27/AU27 | BK27: =AVERAGE(BK13:BK26) | BL27: =AZ27/AX27 | BM27: =AZ27/AR27 | BN27: =BA27/AR27 | BO27: =SUM(BO13:BO26) | BP27: =SUM(BP13:BP26) | BQ27: =SUM(BQ13:BQ26) | BR27: =SUM(BR13:BR26) | BS27: =SUM(BS13:BS26) | BT27: =SUM(BT13:BT26) | BU27: =SUM(BU13:BU26) | BV27: =SUM(BV13:BV26) | ... BX27: =SUM(BX13:BX26) | BZ27: =SUM(BZ13:BZ26) | CA27: =SUM(CA13:CA26) | CB27: =SUM(CB13:CB26) | CC27: =SUM(CC13:CC26) | CD27: =SUM(CD13:CD26) | CE27: =SUM(CE13:CE26) | CF27: =BW27/CE27 | CG27: =SUM(CG13:CG26) | CH27: =SUM(CH13:CH26) | CI27: =BX27/CH27 | CJ27: =SUM(CJ13:CJ26) | CK27: =BX27/CJ27

Sheet 陈琪直播
I1: 主投 | AR1: 辅投 | BW1: 汇总
B2: 渠道组 | C2: 供应商 | D2: 渠道名称 | E2: 主投 | F2: 辅投 | G2: 结算方式 | H2: 滚动消耗 | I2: 滚动消耗(不含赠课成本) | J2: 单例子成本 | K2: 例子数 | L2: 分发数 | M2: 剔除毛例子 分发数 | N2: 约课数 | O2: 应到课数 | P2: 滚动应到课数 | Q2: 到课数 | R2: 滚动到课数 | S2: 当月成交数 | T2: 滚动成交数 | U2: 当月GMV | V2: 滚动GMV | W2: 海外GMV占比 | X2: 滚动ASP | Y2: 例子分发率 | Z2: 分发约课率 | AA2: 例子约课率 | AB2: 约课到课率 | AD2: 滚动应到课率 | AE2: 到课转化率 | AF2: 注册转化率 | AG2: 滚动转化率 | AH2: 滚动ROI2总成本 | AI2: 滚动ROI2 | AJ2: 滚动应到课人数 | AK2: 滚动到课人数 | AL2: 滚动到课人次 | AM2: 运营成本 | AN2: 销售固定成本 | AO2: 销售变动成本 | AP2: TMK费用 | AQ2: DEMO费用 | AR2: 例子数 | AS2: 分发数 | AT2: 剔除毛例子分发数 | AU2: 约课数 | AX2: 到课数 | AY2: 滚动到课数 | AZ2: 当月成交 | BA2: 滚动成交数 | BB2: 当月GMV | BC2: 滚动GMV | BD2: 海外GMV占比 | BE2: 滚动ASP | BF2: 例子分发率 | BG2: 分发约课率 | BH2: 例子约课率 | BI2: 约课到课率 | BK2: 滚动应到课率 | BL2: 到课转化率 | BM2: 注册转化率 | BN2: 滚动转化率 | BO2: 滚动应到课人数 | BP2: 滚动到课人数 | BQ2: 滚动到课人次 | BR2: 运营成本 | BS2: 销售固定成本 | BT2: 销售变动成本 | BU2: TMK费用 | BV2: DEMO费用 | BW2: 当月GMV | BX2: 滚动GMV | BY2: 海外GMV占比 | BZ2: 滚动其他成本 | CA2: 同源其他成本 | CB2: 运营成本 | CC2: 滚动消耗 | CD2: 同源消耗 | CE2: 当月ROI2总成本 | CF2: 当月ROI2 | CG2: 滚动赠课成本 | CH2: 滚动ROI2总成本 | CI2: 滚动ROI2 | CJ2: O-ROI总成本 | CK2: O-ROI
A3: 45904 | H3: 128084.36 | I3: 123439.75 | J3: 576.9566 | K3: 222 | L3: 91 | M3: 91 | N3: 90 | Q3: 69 | R3: 69 | S3: 26 | T3: 26 | U3: 151688 | V3: 151688 | W3: 1 | X3: 5834.1538 | Y3: 0.40990991 | Z3: 0.98901099 | AA3: 0.40540541 | AB3: 0.76666667 | AD3: 0.97183099 | AE3: 0.37681159 | AF3: 0.11711712 | AG3: 0.11711712 | AH3: 183768.47 | AI3: 0.82542994 | AJ3: 71 | AK3: 69 | AL3: 76 | AM3: 16820.682 | AN3: 13157.618 | AO3: 17031.157 | AP3: 2220 | AQ3: 6454.6523 | AR3: 0 | AS3: 0 | AT3: 0 | AU3: 0 | AX3: 0 | AY3: 0 | AZ3: 0 | BA3: 0 | BB3: 0 | BC3: 0 | BO3: 0 | BP3: 0 | BQ3: 0 | BR3: 0 | BS3: 0 | BT3: 0 | BU3: 0 | BV3: 0 | BW3: 151688 | BX3: 151688 | BY3: 1 | BZ3: 38863.427 | CA3: 38863.427 | CB3: 16820.682 | CC3: 128084.36 | CD3: 128084.36 | CE3: 183768.47 | CF3: 0.82542994 | CG3: 4644.6176 | CH3: 183768.47 | CI3: 0.82542994 | CJ3: 183597.79 | CK3: 0.8261973
A4: 45931 | H4: 173328.07 | I4: =H4-CG4 | J4: 509.78844 | K4: 340 | L4: 105 | M4: 107 | N4: 107 | Q4: 71 | R4: 81 | S4: 25 | T4: 28 | U4: 161397 | V4: 177161 | W4: 1 | X4: 6327.1786 | Y4: 0.30882353 | Z4: 1.0190476 | AA4: 0.31470588 | AB4: 0.6635514 | AD4: 1 | AE4: 0.35211268 | AF4: 0.073529412 | AG4: 0.082352941 | AH4: 239886.44 | AI4: 0.73852027 | AJ4: 81 | AK4: 81 | AL4: 85 | AM4: 21244.795 | AN4: 15220.468 | AO4: 19488.009 | AP4: 3400 | AQ4: 7205.1019 | AR4: 0 | AS4: 0 | AT4: 0 | AU4: 0 | AX4: 0 | AY4: 0 | AZ4: 0 | BA4: 0 | BB4: 0 | BC4: 0 | BO4: 0 | BP4: 0 | BQ4: 0 | BR4: 0 | BS4: 0 | BT4: 0 | BU4: 0 | BV4: 0 | BW4: 161397 | BX4: 177161 | BY4: 1 | BZ4: 45313.579 | CA4: 42362.593 | CB4: 21244.795 | CC4: 173328.07 | CD4: 172792.15 | CE4: 236399.54 | CF4: 0.68272976 | CG4: 5001.8958 | CH4: 239886.44 | CI4: 0.73852027 | CJ4: 244141.65 | CK4: 0.72564842
A5: 45962 | H5: 162240.1 | I5: =H5-CG5 | J5: 965.71489 | K5: 168 | L5: 74 | M5: 80 | N5: 79 | Q5: 55 | R5: 68 | S5: 22 | T5: 33 | U5: 123436 | V5: 176554 | W5: 1 | X5: 5350.1212 | Y5: 0.44047619 | Z5: 1.0675676 | AA5: 0.4702381 | AB5: 0.69620253 | AD5: 0.98550725 | AE5: 0.4 | AF5: 0.13095238 | AG5: 0.19642857 | AH5: 209744.07 | AI5: 0.84175921 | AJ5: 69 | AK5: 68 | AL5: 71 | AM5: 10935.71 | AN5: 9448.6372 | AO5: 19421.238 | AP5: 1680 | AQ5: 6018.3792 | AR5: 0 | AS5: 0 | AT5: 0 | AU5: 0 | AX5: 0 | AY5: 0 | AZ5: 0 | BA5: 0 | BB5: 0 | BC5: 0 | BO5: 0 | BP5: 0 | BQ5: 0 | BR5: 0 | BS5: 0 | BT5: 0 | BU5: 0 | BV5: 0 | BW5: 123436 | BX5: 176554 | BY5: 1 | BZ5: 36568.255 | CA5: 28660.283 | CB5: 10935.71 | CC5: 162240.1 | CD5: 160274.16 | CE5: 199870.15 | CF5: 0.61758097 | CG5: 5897.8377 | CH5: 209744.07 | CI5: 0.84175921 | CJ5: 211408.36 | CK5: 0.83513255
A6: 45992 | H6: 88525.162 | I6: =H6-CG6 | J6: 1041.4725 | K6: 85 | L6: 51 | M6: 51 | N6: 49 | O6: 48 | P6: 47 | Q6: 37 | R6: 46 | S6: 19 | T6: 22 | U6: 100699 | V6: 111196 | W6: 1 | X6: 5054.3636 | Y6: 0.6 | Z6: 0.96078431 | AA6: 0.57647059 | AB6: 0.75510204 | AC6: 0.77083333 | AD6: 0.9787234 | AE6: 0.51351351 | AF6: 0.22352941 | AG6: 0.25882353 | AH6: 121104.87 | AI6: 0.91817942 | AJ6: 47 | AK6: 46 | AL6: 49 | AM6: 6342.4071 | AN6: 7508.6214 | AO6: 13754.652 | AP6: 850 | AQ6: 4124.028 | AR6: 0 | AS6: 0 | AT6: 0 | AU6: 0 | AV6: 0 | AW6: 0 | AX6: 0 | AY6: 0 | AZ6: 0 | BA6: 0 | BB6: 0 | BC6: 0 | BO6: 0 | BP6: 0 | BQ6: 0 | BR6: 0 | BS6: 0 | BT6: 0 | BU6: 0 | BV6: 0 | BW6: 100699 | BX6: 111196 | BY6: 1 | BZ6: 26237.302 | CA6: 24097.212 | CB6: 6342.4071 | CC6: 88525.162 | CD6: 87939.744 | CE6: 118379.36 | CF6: 0.85064657 | CG6: 4293.0648 | CH6: 121104.87 | CI6: 0.91817942 | CJ6: 121137.46 | CK6: 0.91793237
A7: 46023 | H7: 47898.546 | I7: =H7-CG7 | J7: 630.24403 | K7: 76 | L7: 32 | M7: 35 | N7: 34 | O7: 31 | P7: 36 | Q7: 30 | R7: 36 | S7: 9 | T7: 12 | U7: 46392 | V7: 64056 | W7: 1 | X7: 5338 | Y7: 0.42105263 | Z7: 1.0625 | AA7: 0.44736842 | AB7: 0.88235294 | AC7: 0.96774194 | AD7: 1 | AE7: 0.3 | AF7: 0.11842105 | AG7: 0.15789474 | AH7: 75130.884 | AI7: 0.85259212 | AJ7: 36 | AK7: 36 | AL7: 37 | AM7: 8266.3079 | AN7: 6776.2569 | AO7: 8397.2231 | AP7: 760 | AQ7: 3032.5499 | AR7: 0 | AS7: 0 | AT7: 0 | AU7: 0 | AV7: 0 | AW7: 0 | AX7: 0 | AY7: 0 | AZ7: 0 | BA7: 0 | BB7: 0 | BC7: 0 | BO7: 0 | BP7: 0 | BQ7: 0 | BR7: 0 | BS7: 0 | BT7: 0 | BU7: 0 | BV7: 0 | BW7: 46392 | BX7: 64056 | BY7: 1 | BZ7: 18966.03 | CA7: 15495.875 | CB7: 8266.3079 | CC7: 47898.546 | CD7: 47898.546 | CE7: 71660.729 | CF7: 0.64738387 | CG7: 0 | CH7: 75130.884 | CI7: 0.85259212 | CJ7: 72564.576 | CK7: 0.88274477
A8: 46054 | H8: 43300.376 | I8: =H8-CG8 | J8: 849.02699 | K8: 51 | L8: 30 | M8: 33 | N8: 31 | O8: 26 | P8: 28 | Q8: 19 | R8: 27 | S8: 5 | T8: 8 | U8: 21140 | V8: 34204 | W8: 1 | X8: 4275.5 | Y8: 0.58823529 | Z8: 1.0333333 | AA8: 0.60784314 | AB8: 0.61290323 | AC8: 0.73076923 | AD8: 0.96428571 | AE8: 0.26315789 | AF8: 0.098039216 | AG8: 0.15686275 | AH8: 63873.732 | AI8: 0.535494 | AJ8: 28 | AK8: 27 | AL8: 30 | AM8: 6721.8597 | AN8: 6398.804 | AO8: 4483.8675 | AP8: 510 | AQ8: 2458.8243 | AR8: 0 | AS8: 0 | AT8: 0 | AU8: 0 | AV8: 0 | AW8: 0 | AX8: 0 | AY8: 0 | AZ8: 0 | BA8: 0 | BB8: 0 | BC8: 0 | BO8: 0 | BP8: 0 | BQ8: 0 | BR8: 0 | BS8: 0 | BT8: 0 | BU8: 0 | BV8: 0 | BW8: 21140 | BX8: 34204 | BY8: 1 | BZ8: 13851.496 | CA8: 10819.554 | CB8: 6721.8597 | CC8: 43300.376 | CD8: 43300.376 | CE8: 60841.79 | CF8: 0.34745854 | CG8: 0 | CH8: 63873.732 | CI8: 0.535494 | CJ8: 60976.872 | CK8: 0.56093399
A9: 46082 | H9: 22967.944 | I9: =H9-CG9 | J9: 637.99845 | K9: 36 | L9: 16 | M9: 17 | N9: 17 | O9: 16 | P9: 21 | Q9: 14 | R9: 21 | S9: 5 | T9: 10 | U9: 21740 | V9: 45980 | W9: 1 | X9: 4598 | Y9: 0.44444444 | Z9: 1.0625 | AA9: 0.47222222 | AB9: 0.82352941 | AC9: 0.875 | AD9: 1 | AE9: 0.35714286 | AF9: 0.13888889 | AG9: 0.27777778 | AH9: 36063.321 | AI9: 1.2749796 | AJ9: 21 | AK9: 21 | AL9: 21 | AM9: 3172.8682 | AN9: 2350.6079 | AO9: 5456.432 | AP9: 360 | AQ9: 1755.4687 | AR9: 0 | AS9: 0 | AT9: 0 | AU9: 0 | AV9: 0 | AW9: 0 | AX9: 0 | AY9: 0 | AZ9: 0 | BA9: 0 | BB9: 0 | BC9: 0 | BO9: 0 | BP9: 0 | BQ9: 0 | BR9: 0 | BS9: 0 | BT9: 0 | BU9: 0 | BV9: 0 | BW9: 21740 | BX9: 45980 | BY9: 1 | BZ9: 9922.5087 | CA9: 6322.5283 | CB9: 3172.8682 | CC9: 22967.944 | CD9: 21961.872 | CE9: 31457.269 | CF9: 0.69109623 | CG9: 2012.1437 | CH9: 36063.321 | CI9: 1.2749796 | CJ9: 35590.453 | CK9: 1.2919195
A10: 46113 | H10: 22967.944 | I10: =H10-CG10 | J10: 637.99845 | K10: 36 | L10: 16 | M10: 17 | N10: 17 | O10: 16 | P10: 21 | Q10: 14 | R10: 21 | S10: 5 | T10: 10 | U10: 21740 | V10: 45980 | W10: 1 | X10: 4598 | Y10: 0.44444444 | Z10: 1.0625 | AA10: 0.47222222 | AB10: 0.82352941 | AC10: 0.875 | AD10: 1 | AE10: 0.35714286 | AF10: 0.13888889 | AG10: 0.27777778 | AH10: 36063.321 | AI10: 1.2749796 | AJ10: 21 | AK10: 21 | AL10: 21 | AM10: 3172.8682 | AN10: 2350.6079 | AO10: 5456.432 | AP10: 360 | AQ10: 1755.4687 | AR10: 0 | AS10: 0 | AT10: 0 | AU10: 0 | AV10: 0 | AW10: 0 | AX10: 0 | AY10: 0 | AZ10: 0 | BA10: 0 | BB10: 0 | BC10: 0 | BO10: 0 | BP10: 0 | BQ10: 0 | BR10: 0 | BS10: 0 | BT10: 0 | BU10: 0 | BV10: 0 | BW10: 21740 | BX10: 45980 | BY10: 1 | BZ10: 9922.5087 | CA10: 6322.5283 | CB10: 3172.8682 | CC10: 22967.944 | CD10: 21961.872 | CE10: 31457.269 | CF10: 0.69109623 | CG10: 2012.1437 | CH10: 36063.321 | CI10: 1.2749796 | CJ10: 35590.453 | CK10: 1.2919195
A11: 陈琪直播-汇总 | H11: =SUM(H3:H10) | I11: =SUM(I3:I10) | J11: =I11/K11 | K11: =SUM(K3:K10) | L11: =SUM(L3:L10) | M11: =SUM(M3:M10) | N11: =SUM(N3:N10) | Q11: =SUM(Q3:Q10) | R11: =SUM(R3:R10) | S11: =SUM(S3:S10) | T11: =SUM(T3:T10) | U11: =SUM(U3:U10) | V11: =SUM(V3:V10) | X11: =V11/T11 | Y11: =L11/K11 | Z11: =N11/L11 | AA11: =N11/K11 | AB11: =Q11/N11 | AD11: =AVERAGE(AD3:AD10) | AE11: =S11/Q11 | AF11: =S11/K11 | AG11: =T11/K11 | AH11: =SUM(AH3:AH10) | AI11: =V11/AH11 | AJ11: =SUM(AJ3:AJ10) | AK11: =SUM(AK3:AK10) | AL11: =SUM(AL3:AL10) | AM11: =SUM(AM3:AM10) | AN11: =SUM(AN3:AN10) | AO11: =SUM(AO3:AO10) | AP11: =SUM(AP3:AP10) | AQ11: =SUM(AQ3:AQ10) | ... AS11: =SUM(AS3:AS10) | AU11: =SUM(AU3:AU10) | AX11: =SUM(AX3:AX10) | AY11: =SUM(AY3:AY10) | AZ11: =SUM(AZ3:AZ10) | BA11: =SUM(BA3:BA10) | BB11: =SUM(BB3:BB10) | BC11: =SUM(BC3:BC10) | BE11: =BC11/BA11 | BF11: =AS11/AR11 | BG11: =AU11/AS11 | BH11: =AU11/AR11 | BI11: =AX11/AU11 | BK11: =AVERAGE(BK3:BK10) | BL11: =AZ11/AX11 | BM11: =AZ11/AR11 | BN11: =BA11/AR11 | BO11: =SUM(BO3:BO10) | BP11: =SUM(BP3:BP10) | BQ11: =SUM(BQ3:BQ10) | BR11: =SUM(BR3:BR10) | BS11: =SUM(BS3:BS10) | BT11: =SUM(BT3:BT10) | BU11: =SUM(BU3:BU10) | BV11: =SUM(BV3:BV10) | ... BX11: =SUM(BX3:BX10) | BZ11: =SUM(BZ3:BZ10) | CA11: =SUM(CA3:CA10) | CB11: =SUM(CB3:CB10) | CC11: =SUM(CC3:CC10) | CD11: =SUM(CD3:CD10) | CE11: =SUM(CE3:CE10) | CF11: =BW11/CE11 | CG11: =SUM(CG3:CG10) | CH11: =SUM(CH3:CH10) | CI11: =BX11/CH11 | CJ11: =SUM(CJ3:CJ10) | CK11: =BX11/CJ11

Sheet 孙慧雪
I1: 主投 | AO1: 辅投 | BQ1: 汇总
B2: 渠道组 | C2: 供应商 | D2: 渠道名称 | E2: 主投 | F2: 辅投 | G2: 结算方式 | H2: 滚动消耗 | I2: 滚动消耗(不含赠课成本) | J2: 单例子成本 | K2: 例子数 | L2: 分发数 | M2: 剔除毛例子 分发数 | N2: 约课数 | O2: 到课数 | P2: 滚动到课数 | Q2: 当月成交数 | R2: 滚动成交数 | S2: 当月GMV | T2: 滚动GMV | U2: 海外GMV占比 | V2: 滚动ASP | W2: 例子分发率 | X2: 分发约课率 | Y2: 例子约课率 | Z2: 约课到课率 | AA2: 滚动应到课率 | AB2: 到课转化率 | AC2: 注册转化率 | AD2: 滚动转化率 | AE2: 滚动ROI2总成本 | AF2: 滚动ROI2 | AG2: 滚动应到课人数 | AH2: 滚动到课人数 | AI2: 滚动到课人次 | AJ2: 运营成本 | AK2: 销售固定成本 | AL2: 销售变动成本 | AM2: TMK费用 | AN2: DEMO费用 | AO2: 例子数 | AP2: 分发数 | AQ2: 剔除毛例子分发数 | AR2: 约课数 | AS2: 到课数 | AT2: 滚动到课数 | AU2: 当月成交 | AV2: 滚动成交数 | AW2: 当月GMV | AX2: 滚动GMV | AY2: 海外GMV占比 | AZ2: 滚动ASP | BA2: 例子分发率 | BB2: 分发约课率 | BC2: 例子约课率 | BD2: 约课到课率 | BE2: 滚动应到课率 | BF2: 到课转化率 | BG2: 注册转化率 | BH2: 滚动转化率 | BI2: 滚动应到课人数 | BJ2: 滚动到课人数 | BK2: 滚动到课人次 | BL2: 运营成本 | BM2: 销售固定成本 | BN2: 销售变动成本 | BO2: TMK费用 | BP2: DEMO费用 | BQ2: 当月GMV | BR2: 滚动GMV | BS2: 海外GMV占比 | BT2: 滚动其他成本 | BU2: 同源其他成本 | BV2: 运营成本 | BW2: 滚动消耗 | BX2: 同源消耗 | BY2: 当月ROI2总成本 | BZ2: 当月ROI2 | CA2: 滚动赠课成本 | CB2: 滚动ROI2总成本 | CC2: 滚动ROI2 | CD2: O-ROI总成本 | CE2: O-ROI
A3: 45718 | C3: 孙慧雪 | D3: KOLHK-香港-孙慧雪-Shukei-思维&无 | E3: - | F3: - | G3: - | H3: =I3 | I3: 107006.99 | J3: 442.17765 | K3: 242 | L3: 129 | M3: 129 | N3: 140 | O3: 113 | P3: 113 | Q3: 42 | R3: 42 | S3: 195996 | T3: 195996 | U3: 1 | V3: 4666.5714 | W3: 0.53305785 | X3: 1.0852713 | Y3: 0.5785124 | Z3: 0.80714286 | AA3: 0.96581197 | AB3: 0.37168142 | AC3: 0.17355372 | AD3: 0.17355372 | AE3: 171279.14 | AF3: 1.1443075 | AG3: 117 | AH3: 113 | AI3: 117 | AJ3: 21630.555 | AK3: 12752.848 | AL3: 18762.997 | AM3: 1628.5778 | AN3: 9497.1665 | AO3: 0 | AP3: 0 | AQ3: 0 | AR3: 0 | AS3: 0 | AT3: 0 | AU3: 0 | AV3: 0 | AW3: 0 | AX3: 0 | BI3: 0 | BJ3: 0 | BK3: 0 | BL3: 0 | BM3: 0 | BN3: 0 | BO3: 0 | BP3: 0 | BQ3: 195996 | BR3: 195996 | BS3: 1 | BT3: 42729.871 | BU3: 42729.871 | BV3: 21712.304 | BW3: 107006.99 | BX3: 107006.99 | BY3: 171449.17 | BZ3: 1.1431727 | CB3: 171449.17 | CC3: 1.1431727 | CD3: 167961.86 | CE3: 1.1669077
A4: 45750 | D4: KOLHK-香港-孙慧雪-Shukei-思维&无 | E4: - | F4: - | G4: - | H4: =I4 | I4: 80325.479 | J4: 892.50532 | K4: 90 | L4: 48 | M4: 50 | N4: 48 | O4: 35 | P4: 45 | Q4: 14 | R4: 20 | S4: 58432 | T4: 80360 | U4: 1 | V4: 4018 | W4: 0.53333333 | X4: 1 | Y4: 0.53333333 | Z4: 0.72916667 | AA4: 0.91836735 | AB4: 0.4 | AC4: 0.15555556 | AD4: 0.22222222 | AE4: 109746.72 | AF4: 0.73223143 | AG4: 49 | AH4: 45 | AI4: 47 | AJ4: 9968.2761 | AK4: 7405.9586 | AL4: 7204.5969 | AM4: 889.52324 | AN4: 3952.8892 | AO4: 0 | AP4: 0 | AQ4: 0 | AR4: 0 | AS4: 0 | AT4: 0 | AU4: 0 | AV4: 0 | AW4: 0 | AX4: 0 | BI4: 0 | BJ4: 0 | BK4: 0 | BL4: 0 | BM4: 0 | BN4: 0 | BO4: 0 | BP4: 0 | BQ4: 58432 | BR4: 80360 | BS4: 1 | BT4: 19555.481 | BU4: 16349.756 | BV4: 9968.2761 | BW4: 80325.479 | BX4: 80325.479 | BY4: 106643.51 | BZ4: 0.54791894 | CB4: 109849.24 | CC4: 0.7315481 | CD4: 106630.96 | CE4: 0.75362728
A5: 45780 | H5: =I5 | I5: 131098.62 | J5: 851.28974 | K5: 154 | L5: 63 | M5: 68 | N5: 68 | O5: 59 | P5: 68 | Q5: 25 | R5: 26 | S5: 120500 | T5: 124088 | U5: 1 | V5: 4772.6154 | W5: 0.40909091 | X5: 1.0793651 | Y5: 0.44155844 | Z5: 0.86764706 | AA5: 0.97142857 | AB5: 0.42372881 | AC5: 0.16233766 | AD5: 0.16883117 | AE5: 167935.16 | AF5: 0.73890421 | AG5: 70 | AH5: 68 | AI5: 74 | AJ5: 8731.2756 | AK5: 8345.1243 | AL5: 11900.352 | AM5: 1432.0761 | AN5: 6427.7168 | AO5: 0 | AP5: 0 | AQ5: 0 | AR5: 0 | AS5: 0 | AT5: 0 | AU5: 0 | AV5: 0 | AW5: 0 | AX5: 0 | BI5: 0 | BJ5: 0 | BK5: 0 | BL5: 0 | BM5: 0 | BN5: 0 | BO5: 0 | BP5: 0 | BQ5: 120500 | BR5: 124088 | BS5: 1 | BT5: 28105.269 | BU5: 26365.809 | BV5: 8731.2756 | BW5: 131098.62 | BX5: 131098.62 | BY5: 166195.7 | BZ5: 0.72504882 | CB5: 167935.16 | CC5: 0.73890421 | CD5: 170753.89 | CE5: 0.72670673
A6: 45811 | H6: 47816.49 | I6: 45304.246 | J6: 850.32616 | K6: 56 | L6: 27 | M6: 29 | N6: 29 | O6: 22 | P6: 31 | Q6: 9 | R6: 13 | S6: 50492 | T6: 67344 | U6: 1 | V6: 5180.3077 | W6: 0.48214286 | X6: 1.0740741 | Y6: 0.51785714 | Z6: 0.75862069 | AA6: 1 | AB6: 0.40909091 | AC6: 0.16071429 | AD6: 0.23214286 | AE6: 64518.734 | AF6: 1.0437899 | AG6: 31 | AH6: 31 | AI6: 37 | AJ6: 3492.9742 | AK6: 3259.1779 | AL6: 6500.9377 | AM6: 452.25177 | AN6: 3195.1273 | AO6: 20 | AP6: 9 | AQ6: 9 | AR6: 9 | AS6: 5 | AT6: 5 | AU6: 2 | AV6: 2 | AW6: 7987.2 | AX6: 7987.2 | AY6: 1 | AZ6: 3993.6 | BA6: 0.45 | BB6: 1 | BC6: 0.45 | BD6: 0.55555556 | BE6: 0.55555556 | BF6: 0.4 | BG6: 0.1 | BH6: 0.1 | BI6: 9 | BJ6: 5 | BK6: 7 | BL6: 1119.5699 | BM6: 809.61231 | BN6: 830.10519 | BO6: 161.51849 | BP6: 552.62717 | BQ6: 58479.2 | BR6: 75331.2 | BS6: 1 | BT6: 15761.358 | BU6: 12873.551 | BV6: 4612.5441 | BW6: 47816.49 | BX6: 47104.484 | BY6: 64590.578 | BZ6: 0.90538282 | CA6: 2512.2442 | CB6: 68190.392 | CC6: 1.1047187 | CD6: 69277.848 | CE6: 1.0873779
A7: 45842 | H7: 52997.374 | I7: 50605.35 | J7: 928.05021 | K7: 57 | L7: 24 | M7: 29 | N7: 26 | O7: 20 | P7: 32 | Q7: 11 | R7: 13 | S7: 56968 | T7: 64144 | U7: 1 | V7: 4934.1538 | W7: 0.42105263 | X7: 1.0833333 | Y7: 0.45614035 | Z7: 0.76923077 | AA7: 0.91428571 | AB7: 0.55 | AC7: 0.19298246 | AD7: 0.22807018 | AE7: 68601.979 | AF7: 0.93501675 | AG7: 35 | AH7: 32 | AI7: 34 | AJ7: 2508.2508 | AK7: 3043.0852 | AL7: 6568.2229 | AM7: 586.74653 | AN7: 2996.812 | AO7: 0 | AP7: 0 | AQ7: 1 | AR7: 0 | AS7: 0 | AT7: 1 | AU7: 0 | AV7: 1 | AW7: 0 | AX7: 1880 | AY7: 1 | AZ7: 1880 | BE7: 1 | BI7: 1 | BJ7: 1 | BK7: 1 | BL7: 0 | BM7: 94.86495 | BN7: 197.37392 | BO7: 0 | BP7: 82.183386 | BQ7: 56968 | BR7: 66024 | BS7: 1 | BT7: 13569.289 | BU7: 10789.548 | BV7: 2508.2508 | BW7: 52997.374 | BX7: 52546.014 | BY7: 65843.813 | BZ7: 0.86519898 | CA7: 2392.0239 | CB7: 69074.914 | CC7: 0.95583181 | CD7: 70841.663 | CE7: 0.93199393
A8: 45873 | H8: 17564.304 | I8: 16857.021 | J8: 1170.9536 | K8: 15 | L8: 6 | M8: 9 | N8: 6 | O8: 6 | P8: 14 | Q8: 2 | R8: 4 | S8: 12176 | T8: 21852 | U8: 1 | V8: 5463 | W8: 0.4 | X8: 1 | Y8: 0.4 | Z8: 1 | AA8: 1 | AB8: 0.33333333 | AC8: 0.13333333 | AD8: 0.26666667 | AE8: 23739.889 | AF8: 0.9204761 | AG8: 14 | AH8: 14 | AI8: 15 | AJ8: 1354.193 | AK8: 1111.6659 | AL8: 2237.603 | AM8: 150 | AN8: 1322.123 | AO8: 0 | AP8: 0 | AQ8: 0 | AR8: 0 | AS8: 0 | AT8: 0 | AU8: 0 | AV8: 0 | AW8: 0 | AX8: 0 | BI8: 0 | BJ8: 0 | BK8: 0 | BL8: 0 | BM8: 0 | BN8: 0 | BO8: 0 | BP8: 0 | BQ8: 12176 | BR8: 21852 | BS8: 1 | BT8: 4821.3918 | BU8: 2666.7589 | BV8: 1354.193 | BW8: 17564.304 | BX8: 17210.662 | BY8: 21231.614 | BZ8: 0.57348442 | CA8: 707.28265 | CB8: 23739.889 | CC8: 0.9204761 | CD8: 23510.696 | CE8: 0.92944932
A9: 45904 | H9: 905.74393 | I9: =H9-CA9 | J9: 226.43598 | K9: 4 | L9: 2 | M9: 2 | N9: 2 | O9: 2 | P9: 4 | Q9: 1 | R9: 2 | S9: 6088 | T9: 12176 | U9: 1 | V9: 6088 | W9: 0.5 | X9: 1 | Y9: 0.5 | Z9: 1 | AA9: 0.8 | AB9: 0.5 | AC9: 0.25 | AD9: 0.5 | AE9: 3329.7373 | AF9: 3.6567449 | AG9: 5 | AH9: 4 | AI9: 5 | AJ9: 303.07535 | AK9: 289.17842 | AL9: 1367.0914 | AM9: 40 | AN9: 424.64818 | AO9: 0 | AP9: 0 | AQ9: 0 | AR9: 0 | AS9: 0 | AT9: 0 | AU9: 0 | AV9: 0 | AW9: 0 | AX9: 0 | BI9: 0 | BJ9: 0 | BK9: 0 | BL9: 0 | BM9: 0 | BN9: 0 | BO9: 0 | BP9: 0 | BQ9: 6088 | BR9: 12176 | BS9: 1 | BT9: 2120.918 | BU9: 1267.513 | BV9: 303.07535 | BW9: 905.74393 | BX9: 727.10479 | BY9: 2297.6932 | BZ9: 2.649614 | CA9: 357.27827 | CB9: 3329.7373 | CC9: 3.6567449 | CD9: 3326.662 | CE9: 3.6601254
A10: 孙慧雪-汇总 | H10: =SUM(H3:H9) | I10: =SUM(I3:I9) | J10: =I10/K10 | K10: =SUM(K3:K9) | L10: =SUM(L3:L9) | M10: =SUM(M3:M9) | N10: =SUM(N3:N9) | O10: =SUM(O3:O9) | P10: =SUM(P3:P9) | Q10: =SUM(Q3:Q9) | R10: =SUM(R3:R9) | ... T10: =SUM(T3:T9) | V10: =T10/R10 | W10: =L10/K10 | X10: =N10/L10 | Y10: =N10/K10 | Z10: =O10/N10 | AA10: =AVERAGE(AA3:AA9) | AB10: =Q10/O10 | AC10: =Q10/K10 | AD10: =R10/K10 | AE10: =SUM(AE3:AE9) | AF10: =T10/AE10 | AG10: =SUM(AG3:AG9) | AH10: =SUM(AH3:AH9) | AI10: =SUM(AI3:AI9) | AJ10: =SUM(AJ3:AJ9) | AK10: =SUM(AK3:AK9) | AL10: =SUM(AL3:AL9) | AM10: =SUM(AM3:AM9) | AN10: =SUM(AN3:AN9) | ... AP10: =SUM(AP3:AP9) | AR10: =SUM(AR3:AR9) | AS10: =SUM(AS3:AS9) | AT10: =SUM(AT3:AT9) | AU10: =SUM(AU3:AU9) | AV10: =SUM(AV3:AV9) | AW10: =SUM(AW3:AW9) | AX10: =SUM(AX3:AX9) | AZ10: =AX10/AV10 | BA10: =AP10/AO10 | BB10: =AR10/AP10 | BC10: =AR10/AO10 | BD10: =AS10/AR10 | BE10: =AVERAGE(BE3:BE9) | BF10: =AU10/AS10 | BG10: =AU10/AO10 | BH10: =AV10/AO10 | BI10: =SUM(BI3:BI9) | BJ10: =SUM(BJ3:BJ9) | BK10: =SUM(BK3:BK9) | BL10: =SUM(BL3:BL9) | BM10: =SUM(BM3:BM9) | BN10: =SUM(BN3:BN9) | BO10: =SUM(BO3:BO9) | BP10: =SUM(BP3:BP9) | ... BR10: =SUM(BR3:BR9) | BT10: =SUM(BT3:BT9) | BU10: =SUM(BU3:BU9) | BV10: =SUM(BV3:BV9) | BW10: =SUM(BW3:BW9) | BX10: =SUM(BX3:BX9) | BY10: =SUM(BY3:BY9) | BZ10: =BQ10/BY10 | CA10: =SUM(CA3:CA9) | CB10: =SUM(CB3:CB9) | CC10: =BR10/CB10 | CD10: =SUM(CD3:CD9) | CE10: =BR10/CD10

Sheet 陈倩扬
I1: 主投 | AO1: 辅投 | BQ1: 汇总
B2: 渠道组 | C2: 供应商 | D2: 渠道名称 | E2: 主投 | F2: 辅投 | G2: 结算方式 | H2: 滚动消耗 | I2: 滚动消耗(不含赠课成本) | J2: 单例子成本 | K2: 例子数 | L2: 分发数 | M2: 剔除毛例子 分发数 | N2: 约课数 | O2: 到课数 | P2: 滚动到课数 | Q2: 当月成交数 | R2: 滚动成交数 | S2: 当月GMV | T2: 滚动GMV | U2: 海外GMV占比 | V2: 滚动ASP | W2: 例子分发率 | X2: 分发约课率 | Y2: 例子约课率 | Z2: 约课到课率 | AA2: 滚动应到课率 | AB2: 到课转化率 | AC2: 注册转化率 | AD2: 滚动转化率 | AE2: 滚动ROI2总成本 | AF2: 滚动ROI2 | AG2: 滚动应到课人数 | AH2: 滚动到课人数 | AI2: 滚动到课人次 | AJ2: 运营成本 | AK2: 销售固定成本 | AL2: 销售变动成本 | AM2: TMK费用 | AN2: DEMO费用 | AO2: 例子数 | AP2: 分发数 | AQ2: 剔除毛例子分发数 | AR2: 约课数 | AS2: 到课数 | AT2: 滚动到课数 | AU2: 当月成交 | AV2: 滚动成交数 | AW2: 当月GMV | AX2: 滚动GMV | AY2: 海外GMV占比 | AZ2: 滚动ASP | BA2: 例子分发率 | BB2: 分发约课率 | BC2: 例子约课率 | BD2: 约课到课率 | BE2: 滚动应到课率 | BF2: 到课转化率 | BG2: 注册转化率 | BH2: 滚动转化率 | BI2: 滚动应到课人数 | BJ2: 滚动到课人数 | BK2: 滚动到课人次 | BL2: 运营成本 | BM2: 销售固定成本 | BN2: 销售变动成本 | BO2: TMK费用 | BP2: DEMO费用 | BQ2: 当月GMV | BR2: 滚动GMV | BS2: 海外GMV占比 | BT2: 滚动其他成本 | BU2: 同源其他成本 | BV2: 运营成本 | BW2: 滚动消耗 | BX2: 同源消耗 | BY2: 当月ROI2总成本 | BZ2: 当月ROI2 | CA2: 滚动赠课成本 | CB2: 滚动ROI2总成本 | CC2: 滚动ROI2 | CD2: O-ROI总成本 | CE2: O-ROI
A3: 45718 | C3: 陈倩扬 | D3: KOLHK-香港-陈倩扬Skye-Shukei-思维&无 | E3: - | F3: - | G3: - | H3: =I3 | I3: 92998.238 | J3: 522.46201 | K3: 178 | L3: 84 | M3: 84 | N3: 97 | O3: 79 | P3: 79 | Q3: 33 | R3: 33 | S3: 156665.2 | T3: 156665.2 | U3: 1 | V3: 4747.4303 | W3: 0.47191011 | X3: 1.1547619 | Y3: 0.54494382 | Z3: 0.81443299 | AA3: 0.97530864 | AB3: 0.41772152 | AC3: 0.18539326 | AD3: 0.18539326 | AE3: 140389 | AF3: 1.1159365 | AG3: 81 | AH3: 79 | AI3: 86 | AJ3: 15910.078 | AK3: 8304.1801 | AL3: 14997.799 | AM3: 1197.8795 | AN3: 6980.8232 | AO3: 0 | AP3: 0 | AQ3: 0 | AR3: 0 | AS3: 0 | AT3: 0 | AU3: 0 | AV3: 0 | AW3: 0 | AX3: 0 | BI3: 0 | BJ3: 0 | BK3: 0 | BL3: 0 | BM3: 0 | BN3: 0 | BO3: 0 | BP3: 0 | BQ3: 156665.2 | BR3: 156665.2 | BS3: 1 | BT3: 31568.964 | BU3: 31568.964 | BV3: 15991.826 | BW3: 92998.238 | BX3: 92998.238 | BY3: 140559.03 | BZ3: 1.1145865 | CB3: 140559.03 | CC3: 1.1145865 | CD3: 137992.2 | CE3: 1.1353192
A4: 45750 | D4: KOLHK-香港-陈倩扬Skye-Shukei-思维&无 | E4: 思维 | F4: - | G4: CPT | H4: =I4 | I4: 48781.331 | J4: 1084.0296 | K4: 45 | L4: 28 | M4: 31 | N4: 29 | O4: 21 | P4: 28 | Q4: 5 | R4: 11 | S4: 23940 | T4: 45568 | U4: 1 | V4: 4142.5455 | W4: 0.62222222 | X4: 1.0357143 | Y4: 0.64444444 | Z4: 0.72413793 | AA4: 0.93333333 | AB4: 0.23809524 | AC4: 0.11111111 | AD4: 0.24444444 | AE4: 65326.296 | AF4: 0.69754453 | AG4: 30 | AH4: 28 | AI4: 29 | AJ4: 4984.1381 | AK4: 4591.6944 | AL4: 4085.3543 | AM4: 444.76162 | AN4: 2439.0168 | AO4: 0 | AP4: 0 | AQ4: 0 | AR4: 0 | AS4: 0 | AT4: 0 | AU4: 0 | AV4: 0 | AW4: 0 | AX4: 0 | BI4: 0 | BJ4: 0 | BK4: 0 | BL4: 0 | BM4: 0 | BN4: 0 | BO4: 0 | BP4: 0 | BQ4: 23940 | BR4: 45568 | BS4: 1 | BT4: 12047.293 | BU4: 8888.5526 | BV4: 5193.4319 | BW4: 48781.331 | BX4: 48781.331 | BY4: 62863.315 | BZ4: 0.38082624 | CB4: 66022.055 | CC4: 0.6901936 | CD4: 64353.623 | CE4: 0.70808756
A5: 45780 | H5: =I5 | I5: 69042.51 | J5: 793.59207 | K5: 87 | L5: 44 | M5: 45 | N5: 44 | O5: 34 | P5: 42 | Q5: 11 | R5: 15 | S5: 47868 | T5: 69111.2 | U5: 1 | V5: 4607.4133 | W5: 0.50574713 | X5: 1 | Y5: 0.50574713 | Z5: 0.77272727 | AA5: 0.91304348 | AB5: 0.32352941 | AC5: 0.12643678 | AD5: 0.17241379 | AE5: 91364.504 | AF5: 0.75643381 | AG5: 46 | AH5: 42 | AI5: 51 | AJ5: 4932.6037 | AK5: 5522.5087 | AL5: 6627.9381 | AM5: 809.02998 | AN5: 4429.9129 | AO5: 0 | AP5: 0 | AQ5: 0 | AR5: 0 | AS5: 0 | AT5: 0 | AU5: 0 | AV5: 0 | AW5: 0 | AX5: 0 | BI5: 0 | BJ5: 0 | BK5: 0 | BL5: 0 | BM5: 0 | BN5: 0 | BO5: 0 | BP5: 0 | BQ5: 47868 | BR5: 69111.2 | BS5: 1 | BT5: 17389.39 | BU5: 14187.059 | BV5: 4932.6037 | BW5: 69042.51 | BX5: 69042.51 | BY5: 88162.172 | BZ5: 0.54295395 | CB5: 91364.504 | CC5: 0.75643381 | CD5: 92956.9 | CE5: 0.74347574
A6: 45811 | H6: 5499.1814 | I6: 4609.174 | J6: 549.91814 | K6: 10 | L6: 3 | M6: 3 | N6: 3 | O6: 3 | P6: 8 | Q6: 2 | R6: 5 | S6: 9776 | T6: 21340 | U6: 1 | V6: 4268 | W6: 0.3 | X6: 1 | Y6: 0.3 | Z6: 1 | AA6: 1 | AB6: 0.66666667 | AC6: 0.2 | AD6: 0.5 | AE6: 9378.0558 | AF6: 2.2755249 | AG6: 8 | AH6: 8 | AI6: 9 | AJ6: 623.7454 | AK6: 337.15634 | AL6: 2060.0203 | AM6: 80.759244 | AN6: 777.19314 | AO6: 0 | AP6: 0 | AQ6: 0 | AR6: 0 | AS6: 0 | AT6: 0 | AU6: 0 | AV6: 0 | AW6: 0 | AX6: 0 | BI6: 0 | BJ6: 0 | BK6: 0 | BL6: 0 | BM6: 0 | BN6: 0 | BO6: 0 | BP6: 0 | BQ6: 9776 | BR6: 21340 | BS6: 1 | BT6: 3530.1415 | BU6: 1895.7018 | BV6: 735.70239 | BW6: 5499.1814 | BX6: 4965.1769 | BY6: 7596.5811 | BZ6: 1.2868947 | CA6: 890.00741 | CB6: 9765.0253 | CC6: 2.1853502 | CD6: 9929.3229 | CE6: 2.1491899
A8: 陈倩扬-汇总 | H8: =SUM(H3:H7) | I8: =SUM(I3:I7) | J8: =I8/K8 | K8: =SUM(K3:K7) | L8: =SUM(L3:L7) | M8: =SUM(M3:M7) | N8: =SUM(N3:N7) | O8: =SUM(O3:O7) | P8: =SUM(P3:P7) | Q8: =SUM(Q3:Q7) | R8: =SUM(R3:R7) | ... T8: =SUM(T3:T7) | V8: =T8/R8 | W8: =L8/K8 | X8: =N8/L8 | Y8: =N8/K8 | Z8: =O8/N8 | AA8: =AVERAGE(AA3:AA7) | AB8: =Q8/O8 | AC8: =Q8/K8 | AD8: =R8/K8 | AE8: =SUM(AE3:AE7) | AF8: =T8/AE8 | AG8: =SUM(AG3:AG7) | AH8: =SUM(AH3:AH7) | AI8: =SUM(AI3:AI7) | AJ8: =SUM(AJ3:AJ7) | AK8: =SUM(AK3:AK7) | AL8: =SUM(AL3:AL7) | AM8: =SUM(AM3:AM7) | AN8: =SUM(AN3:AN7) | ... AP8: =SUM(AP3:AP7) | AR8: =SUM(AR3:AR7) | AS8: =SUM(AS3:AS7) | AT8: =SUM(AT3:AT7) | AU8: =SUM(AU3:AU7) | AV8: =SUM(AV3:AV7) | AW8: =SUM(AW3:AW7) | AX8: =SUM(AX3:AX7) | AZ8: =AX8/AV8 | BA8: =AP8/AO8 | BB8: =AR8/AP8 | BC8: =AR8/AO8 | BD8: =AS8/AR8 | BE8: =AVERAGE(BE3:BE7) | BF8: =AU8/AS8 | BG8: =AU8/AO8 | BH8: =AV8/AO8 | BI8: =SUM(BI3:BI7) | BJ8: =SUM(BJ3:BJ7) | BK8: =SUM(BK3:BK7) | BL8: =SUM(BL3:BL7) | BM8: =SUM(BM3:BM7) | BN8: =SUM(BN3:BN7) | BO8: =SUM(BO3:BO7) | BP8: =SUM(BP3:BP7) | ... BR8: =SUM(BR3:BR7) | BT8: =SUM(BT3:BT7) | BU8: =SUM(BU3:BU7) | BV8: =SUM(BV3:BV7) | BW8: =SUM(BW3:BW7) | BX8: =SUM(BX3:BX7) | BY8: =SUM(BY3:BY7) | BZ8: =BQ8/BY8 | CA8: =SUM(CA3:CA7) | CB8: =SUM(CB3:CB7) | CC8: =BR8/CB8 | CD8: =SUM(CD3:CD7) | CE8: =BR8/CD8

Sheet Bob
I1: 主投 | AR1: 辅投 | BW1: 汇总
B2: 渠道组 | C2: 供应商 | D2: 渠道名称 | E2: 主投 | F2: 辅投 | G2: 结算方式 | H2: 滚动消耗 | I2: 滚动消耗(不含赠课成本) | J2: 单例子成本 | K2: 例子数 | L2: 分发数 | M2: 剔除毛例子 分发数 | N2: 约课数 | Q2: 到课数 | R2: 滚动到课数 | S2: 当月成交数 | T2: 滚动成交数 | U2: 当月GMV | V2: 滚动GMV | W2: 海外GMV占比 | X2: 滚动ASP | Y2: 例子分发率 | Z2: 分发约课率 | AA2: 例子约课率 | AB2: 约课到课率 | AD2: 滚动应到课率 | AE2: 到课转化率 | AF2: 注册转化率 | AG2: 滚动转化率 | AH2: 滚动ROI2总成本 | AI2: 滚动ROI2 | AJ2: 滚动应到课人数 | AK2: 滚动到课人数 | AL2: 滚动到课人次 | AM2: 运营成本 | AN2: 销售固定成本 | AO2: 销售变动成本 | AP2: TMK费用 | AQ2: DEMO费用 | AR2: 例子数 | AS2: 分发数 | AT2: 剔除毛例子分发数 | AU2: 约课数 | AX2: 到课数 | AY2: 滚动到课数 | AZ2: 当月成交 | BA2: 滚动成交数 | BB2: 当月GMV | BC2: 滚动GMV | BD2: 海外GMV占比 | BE2: 滚动ASP | BF2: 例子分发率 | BG2: 分发约课率 | BH2: 例子约课率 | BI2: 约课到课率 | BK2: 滚动应到课率 | BL2: 到课转化率 | BM2: 注册转化率 | BN2: 滚动转化率 | BO2: 滚动应到课人数 | BP2: 滚动到课人数 | BQ2: 滚动到课人次 | BR2: 运营成本 | BS2: 销售固定成本 | BT2: 销售变动成本 | BU2: TMK费用 | BV2: DEMO费用 | BW2: 当月GMV | BX2: 滚动GMV | BY2: 海外GMV占比 | BZ2: 滚动其他成本 | CA2: 同源其他成本 | CB2: 运营成本 | CC2: 滚动消耗 | CD2: 同源消耗 | CE2: 当月ROI2总成本 | CF2: 当月ROI2 | CG2: 滚动赠课成本 | CH2: 滚动ROI2总成本 | CI2: 滚动ROI2 | CJ2: O-ROI总成本 | CK2: O-ROI
A4: 45750 | D4: KOLHK-香港-Bob林盛斌-Shukei-思维&无01 | E4: - | F4: - | G4: - | H4: =I4 | I4: 46341.657 | J4: 311.01783 | K4: 149 | L4: 82 | M4: 82 | N4: 79 | Q4: 57 | R4: 57 | S4: 22 | T4: 22 | U4: 96736 | V4: 96736 | W4: 1 | X4: 4397.0909 | Y4: 0.55033557 | Z4: 0.96341463 | AA4: 0.53020134 | AB4: 0.72151899 | AD4: 0.96610169 | AE4: 0.38596491 | AF4: 0.14765101 | AG4: 0.14765101 | AH4: 90013.923 | AI4: 1.0746782 | AJ4: 59 | AK4: 57 | AL4: 58 | AM4: 16503.035 | AN4: 12145.772 | AO4: 8672.7711 | AP4: 1472.6551 | AQ4: 4878.0335 | AR4: 0 | AS4: 0 | AT4: 0 | AU4: 0 | AX4: 0 | AY4: 0 | AZ4: 0 | BA4: 0 | BB4: 0 | BC4: 0 | BO4: 0 | BP4: 0 | BQ4: 0 | BR4: 0 | BS4: 0 | BT4: 0 | BU4: 0 | BV4: 0 | BW4: 96736 | BX4: 96736 | BY4: 1 | BZ4: 27169.232 | CA4: 27169.232 | CB4: 16503.035 | CC4: 46341.657 | CD4: 46341.657 | CE4: 90013.923 | CF4: 1.0746782 | CH4: 90013.923 | CI4: 1.0746782 | CJ4: 84685.889 | CK4: 1.1422918
A5: 45780 | H5: =I5 | I5: 164736.25 | J5: 752.22034 | K5: 219 | L5: 85 | M5: 92 | N5: 89 | Q5: 68 | R5: 86 | S5: 23 | T5: 27 | U5: 131124 | V5: 145576 | W5: 1 | X5: 5391.7037 | Y5: 0.38812785 | Z5: 1.0470588 | AA5: 0.40639269 | AB5: 0.76404494 | AD5: 0.97727273 | AE5: 0.33823529 | AF5: 0.10502283 | AG5: 0.12328767 | AH5: 212258.39 | AI5: 0.68584332 | AJ5: 88 | AK5: 86 | AL5: 90 | AM5: 12416.554 | AN5: 11290.462 | AO5: 13961.105 | AP5: 2036.5237 | AQ5: 7817.4934 | AR5: 0 | AS5: 0 | AT5: 0 | AU5: 0 | AX5: 0 | AY5: 0 | AZ5: 0 | BA5: 0 | BB5: 0 | BC5: 0 | BO5: 0 | BP5: 0 | BQ5: 0 | BR5: 0 | BS5: 0 | BT5: 0 | BU5: 0 | BV5: 0 | BW5: 131124 | BX5: 145576 | BY5: 1 | BZ5: 35105.584 | CA5: 31210.185 | CB5: 12416.554 | CC5: 164736.25 | CD5: 164736.25 | CE5: 208362.99 | CF5: 0.62930561 | CH5: 212258.39 | CI5: 0.68584332 | CJ5: 216266.84 | CK5: 0.6731314
A6: 45811 | H6: 105682.87 | I6: 100124.38 | J6: 974.87429 | K6: 108 | L6: 66 | M6: 70 | N6: 69 | Q6: 54 | R6: 63 | S6: 23 | T6: 29 | U6: 124424 | V6: 155552 | W6: 1 | X6: 5363.8621 | Y6: 0.61111111 | Z6: 1.0454545 | AA6: 0.63888889 | AB6: 0.7826087 | AD6: 0.92647059 | AE6: 0.42592593 | AF6: 0.21296296 | AG6: 0.26851852 | AH6: 141650.13 | AI6: 1.0981423 | AJ6: 68 | AK6: 63 | AL6: 68 | AM6: 6736.4503 | AN6: 7866.9813 | AO6: 15015.946 | AP6: 872.19983 | AQ6: 5872.1259 | AR6: 72 | AS6: 32 | AT6: 32 | AU6: 32 | AX6: 24 | AY6: 24 | AZ6: 4 | BA6: 4 | BB6: 13404.4 | BC6: 13404.4 | BD6: 1 | BE6: 3351.1 | BF6: 0.44444444 | BG6: 1 | BH6: 0.44444444 | BI6: 0.75 | BK6: 0.75 | BL6: 0.16666667 | BM6: 0.055555556 | BN6: 0.055555556 | BO6: 32 | BP6: 24 | BQ6: 28 | BR6: 4030.4518 | BS6: 2878.6215 | BT6: 1393.1117 | BU6: 581.46656 | BV6: 2210.5087 | BW6: 137828.4 | BX6: 168956.4 | BY6: 1 | BZ6: 36690.961 | CA6: 32372.983 | CB6: 10766.902 | CC6: 105682.87 | CD6: 104614.86 | CE6: 147754.75 | CF6: 0.93281875 | CG6: 5558.4929 | CH6: 153140.74 | CI6: 1.1032754 | CJ6: 155873.83 | CK6: 1.0839305
A7: 45842 | H7: 53515.038 | I7: 52280.07 | J7: 1274.1676 | K7: 42 | L7: 21 | M7: 28 | N7: 21 | Q7: 18 | R7: 25 | S7: 4 | T7: 7 | U7: 26852 | V7: 44916 | W7: 1 | X7: 6416.5714 | Y7: 0.5 | Z7: 1 | AA7: 0.5 | AB7: 0.85714286 | AD7: 0.96153846 | AE7: 0.22222222 | AF7: 0.095238095 | AG7: 0.16666667 | AH7: 65977.272 | AI7: 0.68077989 | AJ7: 26 | AK7: 25 | AL7: 30 | AM7: 1848.1848 | AN7: 2938.1512 | AO7: 4599.3125 | AP7: 432.33955 | AQ7: 2644.2459 | AR7: 0 | AS7: 0 | AT7: 0 | AU7: 0 | AX7: 0 | AY7: 1 | AZ7: 0 | BA7: 0 | BB7: 0 | BC7: 0 | BK7: 1 | BO7: 1 | BP7: 1 | BQ7: 1 | BR7: 0 | BS7: 0 | BT7: 0 | BU7: 0 | BV7: 82.183386 | BW7: 26852 | BX7: 44916 | BY7: 1 | BZ7: 10696.233 | CA7: 7236.5186 | CB7: 1848.1848 | CC7: 53515.038 | CD7: 52985.766 | CE7: 62070.469 | CF7: 0.43260507 | CG7: 1234.9678 | CH7: 66059.455 | CI7: 0.67993295 | CJ7: 67361.27 | CK7: 0.66679265
A8: 45962 | H8: 21854.973 | I8: =H8-CG8 | J8: 1986.8157 | K8: 11 | L8: 4 | M8: 4 | N8: 4 | Q8: 2 | R8: 2 | S8: 2 | T8: 2 | U8: 10598 | V8: 10598 | W8: 1 | X8: 5299 | Y8: 0.36363636 | Z8: 1 | AA8: 0.36363636 | AB8: 0.5 | AD8: 1 | AE8: 1 | AF8: 0.18181818 | AG8: 0.18181818 | AH8: 24573.529 | AI8: 0.43127709 | AJ8: 2 | AK8: 2 | AL8: 3 | AM8: 716.02863 | AN8: 472.43186 | AO8: 1165.7979 | AP8: 110 | AQ8: 254.29771 | AR8: 0 | AS8: 0 | AT8: 0 | AU8: 0 | AX8: 0 | AY8: 0 | AZ8: 0 | BA8: 0 | BB8: 0 | BC8: 0 | BO8: 0 | BP8: 0 | BQ8: 0 | BR8: 0 | BS8: 0 | BT8: 0 | BU8: 0 | BV8: 0 | BW8: 10598 | BX8: 10598 | BY8: 1 | BZ8: 2002.5275 | CA8: 2002.5275 | CB8: 716.02863 | CC8: 21854.973 | CD8: 21854.973 | CE8: 24573.529 | CF8: 0.43127709 | CG8: 357.44471 | CH8: 24573.529 | CI8: 0.43127709 | CJ8: 24682.5 | CK8: 0.42937303
A9: 45992 | H9: 7697.7969 | I9: =H9-CG9 | J9: 2565.9323 | K9: 3 | L9: 1 | M9: 1 | N9: 1 | O9: 1 | P9: 1 | Q9: 1 | R9: 1 | S9: 1 | T9: 1 | U9: 5299 | V9: 5299 | W9: 1 | X9: 5299 | Y9: 0.33333333 | Z9: 1 | AA9: 0.33333333 | AB9: 1 | AC9: 1 | AD9: 1 | AE9: 1 | AF9: 0.33333333 | AG9: 0.33333333 | AH9: 8759.6463 | AI9: 0.6049331 | AJ9: 1 | AK9: 1 | AL9: 1 | AM9: 209.56949 | AN9: 130.28899 | AO9: 609.73789 | AP9: 30 | AQ9: 82.25303 | AR9: 0 | AS9: 0 | AT9: 0 | AU9: 0 | AV9: 0 | AW9: 0 | AX9: 0 | AY9: 0 | AZ9: 0 | BA9: 0 | BB9: 0 | BC9: 0 | BO9: 0 | BP9: 0 | BQ9: 0 | BR9: 0 | BS9: 0 | BT9: 0 | BU9: 0 | BV9: 0 | BW9: 5299 | BX9: 5299 | BY9: 1 | BZ9: 852.27991 | CA9: 852.27991 | CB9: 209.56949 | CC9: 7697.7969 | CD9: 7697.7969 | CE9: 8759.6463 | CF9: 0.6049331 | CG9: 195.13931 | CH9: 8759.6463 | CI9: 0.6049331 | CJ9: 8775.0768 | CK9: 0.60386936
A10: bob-汇总 | H10: =SUM(H3:H9) | I10: =SUM(I3:I9) | J10: =I10/K10 | K10: =SUM(K3:K9) | L10: =SUM(L3:L9) | M10: =SUM(M3:M9) | N10: =SUM(N3:N9) | Q10: =SUM(Q3:Q9) | R10: =SUM(R3:R9) | S10: =SUM(S3:S9) | T10: =SUM(T3:T9) | U10: =SUM(U3:U9) | V10: =SUM(V3:V9) | X10: =V10/T10 | Y10: =L10/K10 | Z10: =N10/L10 | AA10: =N10/K10 | AB10: =Q10/N10 | AD10: =AVERAGE(AD3:AD9) | AE10: =S10/Q10 | AF10: =S10/K10 | AG10: =T10/K10 | AH10: =SUM(AH3:AH9) | AI10: =V10/AH10 | AJ10: =SUM(AJ3:AJ9) | AK10: =SUM(AK3:AK9) | AL10: =SUM(AL3:AL9) | AM10: =SUM(AM3:AM9) | AN10: =SUM(AN3:AN9) | AO10: =SUM(AO3:AO9) | AP10: =SUM(AP3:AP9) | AQ10: =SUM(AQ3:AQ9) | ... AS10: =SUM(AS3:AS9) | AU10: =SUM(AU3:AU9) | AX10: =SUM(AX3:AX9) | AY10: =SUM(AY3:AY9) | AZ10: =SUM(AZ3:AZ9) | BA10: =SUM(BA3:BA9) | BB10: =SUM(BB3:BB9) | BC10: =SUM(BC3:BC9) | BE10: =BC10/BA10 | BF10: =AS10/AR10 | BG10: =AU10/AS10 | BH10: =AU10/AR10 | BI10: =AX10/AU10 | BK10: =AVERAGE(BK3:BK9) | BL10: =AZ10/AX10 | BM10: =AZ10/AR10 | BN10: =BA10/AR10 | BO10: =SUM(BO3:BO9) | BP10: =SUM(BP3:BP9) | BQ10: =SUM(BQ3:BQ9) | BR10: =SUM(BR3:BR9) | BS10: =SUM(BS3:BS9) | BT10: =SUM(BT3:BT9) | BU10: =SUM(BU3:BU9) | BV10: =SUM(BV3:BV9) | ... BX10: =SUM(BX3:BX9) | BZ10: =SUM(BZ3:BZ9) | CA10: =SUM(CA3:CA9) | CB10: =SUM(CB3:CB9) | CC10: =SUM(CC3:CC9) | CD10: =SUM(CD3:CD9) | CE10: =SUM(CE3:CE9) | CF10: =BW10/CE10 | CG10: =SUM(CG3:CG9) | CH10: =SUM(CH3:CH9) | CI10: =BX10/CH10 | CJ10: =SUM(CJ3:CJ9) | CK10: =BX10/CJ10

Sheet 叶翠翠
I1: 主投 | AO1: 辅投 | BQ1: 汇总
B2: 渠道组 | C2: 供应商 | D2: 渠道名称 | E2: 主投 | F2: 辅投 | G2: 结算方式 | H2: 滚动消耗 | I2: 滚动消耗(不含赠课成本) | J2: 单例子成本 | K2: 例子数 | L2: 分发数 | M2: 剔除毛例子 分发数 | N2: 约课数 | O2: 到课数 | P2: 滚动到课数 | Q2: 当月成交数 | R2: 滚动成交数 | S2: 当月GMV | T2: 滚动GMV | U2: 海外GMV占比 | V2: 滚动ASP | W2: 例子分发率 | X2: 分发约课率 | Y2: 例子约课率 | Z2: 约课到课率 | AA2: 滚动应到课率 | AB2: 到课转化率 | AC2: 注册转化率 | AD2: 滚动转化率 | AE2: 滚动ROI2总成本 | AF2: 滚动ROI2 | AG2: 滚动应到课人数 | AH2: 滚动到课人数 | AI2: 滚动到课人次 | AJ2: 运营成本 | AK2: 销售固定成本 | AL2: 销售变动成本 | AM2: TMK费用 | AN2: DEMO费用 | AO2: 例子数 | AP2: 分发数 | AQ2: 剔除毛例子分发数 | AR2: 约课数 | AS2: 到课数 | AT2: 滚动到课数 | AU2: 当月成交 | AV2: 滚动成交数 | AW2: 当月GMV | AX2: 滚动GMV | AY2: 海外GMV占比 | AZ2: 滚动ASP | BA2: 例子分发率 | BB2: 分发约课率 | BC2: 例子约课率 | BD2: 约课到课率 | BE2: 滚动应到课率 | BF2: 到课转化率 | BG2: 注册转化率 | BH2: 滚动转化率 | BI2: 滚动应到课人数 | BJ2: 滚动到课人数 | BK2: 滚动到课人次 | BL2: 运营成本 | BM2: 销售固定成本 | BN2: 销售变动成本 | BO2: TMK费用 | BP2: DEMO费用 | BQ2: 当月GMV | BR2: 滚动GMV | BS2: 海外GMV占比 | BT2: 滚动其他成本 | BU2: 同源其他成本 | BV2: 运营成本 | BW2: 滚动消耗 | BX2: 同源消耗 | BY2: 当月ROI2总成本 | BZ2: 当月ROI2 | CA2: 滚动赠课成本 | CB2: 滚动ROI2总成本 | CC2: 滚动ROI2 | CD2: O-ROI总成本 | CE2: O-ROI
A4: 45750 | D4: KOLHK-香港-Tracy葉翠翠-Shukei-思维&无 | E4: - | F4: - | G4: - | H4: =I4 | I4: 15480.518 | J4: 418.39239 | K4: 37 | L4: 15 | M4: 15 | N4: 15 | O4: 9 | P4: 9 | Q4: 4 | R4: 4 | S4: 16752 | T4: 16752 | U4: 1 | V4: 4188 | W4: 0.40540541 | X4: 1 | Y4: 0.40540541 | Z4: 0.6 | AA4: 1 | AB4: 0.44444444 | AC4: 0.10810811 | AD4: 0.10810811 | AE4: 24424.888 | AF4: 0.6858578 | AG4: 9 | AH4: 9 | AI4: 9 | AJ4: 4098.0691 | AK4: 2221.7876 | AL4: 1501.8841 | AM4: 365.69289 | AN4: 756.93623 | AO4: 0 | AP4: 0 | AQ4: 0 | AR4: 0 | AS4: 0 | AT4: 0 | AU4: 0 | AV4: 0 | AW4: 0 | AX4: 0 | BI4: 0 | BJ4: 0 | BK4: 0 | BL4: 0 | BM4: 0 | BN4: 0 | BO4: 0 | BP4: 0 | BQ4: 16752 | BR4: 16752 | BS4: 1 | BT4: 4846.3008 | BU4: 4846.3008 | BV4: 4098.0691 | BW4: 15480.518 | BX4: 15480.518 | BY4: 24424.888 | BZ4: 0.6858578 | CB4: 24424.888 | CC4: 0.6858578 | CD4: 23101.819 | CE4: 0.7251377
A5: 45780 | H5: =I5 | I5: 73876.847 | J5: 1191.562 | K5: 62 | L5: 29 | M5: 32 | N5: 28 | O5: 18 | P5: 24 | Q5: 5 | R5: 5 | S5: 18140 | T5: 18140 | U5: 1 | V5: 3628 | W5: 0.46774194 | X5: 0.96551724 | Y5: 0.4516129 | Z5: 0.64285714 | AA5: 0.88888889 | AB5: 0.27777778 | AC5: 0.080645161 | AD5: 0.080645161 | AE5: 85893.762 | AF5: 0.21119112 | AG5: 27 | AH5: 24 | AI5: 26 | AJ5: 3515.1889 | AK5: 3927.1173 | AL5: 1739.6717 | AM5: 576.5501 | AN5: 2258.387 | AO5: 0 | AP5: 0 | AQ5: 0 | AR5: 0 | AS5: 0 | AT5: 0 | AU5: 0 | AV5: 0 | AW5: 0 | AX5: 0 | BI5: 0 | BJ5: 0 | BK5: 0 | BL5: 0 | BM5: 0 | BN5: 0 | BO5: 0 | BP5: 0 | BQ5: 18140 | BR5: 18140 | BS5: 1 | BT5: 8501.7261 | BU5: 7438.6705 | BV5: 3515.1889 | BW5: 73876.847 | BX5: 73876.847 | BY5: 84830.706 | BZ5: 0.21383766 | CB5: 85893.762 | CC5: 0.21119112 | CD5: 87028.573 | CE5: 0.20843729
A6: 45811 | H6: 27427.561 | I6: 26537.554 | J6: 2285.6301 | K6: 12 | L6: 7 | M6: 7 | N6: 7 | O6: 7 | P6: 8 | Q6: 4 | R6: 5 | S6: 14252 | T6: 17840 | U6: 1 | V6: 3568 | W6: 0.58333333 | X6: 1 | Y6: 0.58333333 | Z6: 1 | AA6: 0.88888889 | AB6: 0.57142857 | AC6: 0.33333333 | AD6: 0.41666667 | AE6: 31472.657 | AF6: 0.56684124 | AG6: 9 | AH6: 8 | AI6: 8 | AJ6: 748.49447 | AK6: 786.69813 | AL6: 1722.1538 | AM6: 96.911093 | AN6: 690.83835 | AO6: 0 | AP6: 0 | AQ6: 0 | AR6: 0 | AS6: 0 | AT6: 0 | AU6: 0 | AV6: 0 | AW6: 0 | AX6: 0 | BI6: 0 | BJ6: 0 | BK6: 0 | BL6: 0 | BM6: 0 | BN6: 0 | BO6: 0 | BP6: 0 | BQ6: 14252 | BR6: 17840 | BS6: 1 | BT6: 3296.6014 | BU6: 2863.8852 | BV6: 748.49447 | BW6: 27427.561 | BX6: 27249.56 | BY6: 30861.939 | BZ6: 0.46179859 | CA6: 890.00741 | CB6: 31472.657 | CC6: 0.56684124 | CD6: 31624.162 | CE6: 0.56412561
